debug.log[2020-08-14 14:19:24 +0300] [17892] [INFO] Starting gunicorn 20.0.4
[2020-08-14 14:19:24 +0300] [17892] [INFO] Listening at: http://127.0.0.1:8000 (17892)
[2020-08-14 14:19:24 +0300] [17892] [INFO] Using worker: sync
[2020-08-14 14:19:24 +0300] [17895] [INFO] Booting worker with pid: 17895
[2020-08-14 14:19:24 +0300] [17896] [INFO] Booting worker with pid: 17896
Not Found: /favicon.ico
[2020-08-14 11:19:52,444] log: WARNING - Not Found: /favicon.ico
Not Found: /favicon.ico
[2020-08-14 11:20:15,769] log: WARNING - Not Found: /favicon.ico
Not Found: /favicon.ico
[2020-08-14 11:21:24,613] log: WARNING - Not Found: /favicon.ico
Not Found: /favicon.ico
[2020-08-14 11:23:01,613] log: WARNING - Not Found: /favicon.ico
Not Found: /favicon.ico
[2020-08-14 11:25:42,137] log: WARNING - Not Found: /favicon.ico
Not Found: /favicon.ico
[2020-08-14 11:26:46,891] log: WARNING - Not Found: /favicon.ico
Not Found: /boaform/admin/formLogin
[2020-08-14 11:39:46,882] log: WARNING - Not Found: /boaform/admin/formLogin
Not Found: /favicon.ico
[2020-08-14 11:49:28,535] log: WARNING - Not Found: /favicon.ico
Not Found: /favicon.ico
[2020-08-14 11:49:31,972] log: WARNING - Not Found: /favicon.ico
Not Found: /favicon.ico
[2020-08-14 11:49:36,336] log: WARNING - Not Found: /favicon.ico
Not Found: /favicon.ico
[2020-08-14 11:49:43,795] log: WARNING - Not Found: /favicon.ico
Not Found: /favicon.ico
[2020-08-14 11:49:52,681] log: WARNING - Not Found: /favicon.ico
Not Found: /favicon.ico
[2020-08-14 11:50:05,527] log: WARNING - Not Found: /favicon.ico
Not Found: /favicon.ico
[2020-08-14 11:50:06,182] log: WARNING - Not Found: /favicon.ico
Not Found: /favicon.ico
[2020-08-14 11:50:42,966] log: WARNING - Not Found: /favicon.ico
Not Found: /favicon.ico
[2020-08-14 11:51:52,203] log: WARNING - Not Found: /favicon.ico
Not Found: /favicon.ico
[2020-08-14 12:14:29,142] log: WARNING - Not Found: /favicon.ico
Not Found: /favicon.ico
[2020-08-14 12:18:55,681] log: WARNING - Not Found: /favicon.ico
Not Found: /favicon.ico
[2020-08-14 12:23:13,035] log: WARNING - Not Found: /favicon.ico
Not Found: /boaform/admin/formLogin
[2020-08-14 13:13:40,524] log: WARNING - Not Found: /boaform/admin/formLogin
[2020-08-18 15:19:54 +0300] [15254] [INFO] Starting gunicorn 20.0.4
[2020-08-18 15:19:54 +0300] [15254] [INFO] Listening at: http://127.0.0.1:8000 (15254)
[2020-08-18 15:19:54 +0300] [15254] [INFO] Using worker: sync
[2020-08-18 15:19:54 +0300] [15257] [INFO] Booting worker with pid: 15257
[2020-08-18 15:19:54 +0300] [15258] [INFO] Booting worker with pid: 15258
[2020-08-18 12:19:54 +0000] [15257] [ERROR] Exception in worker process
Traceback (most recent call last):
  File "/home/piekuser/venv/lib/python3.7/site-packages/gunicorn/arbiter.py", line 583, in spawn_worker
    worker.init_process()
  File "/home/piekuser/venv/lib/python3.7/site-packages/gunicorn/workers/base.py", line 119, in init_process
    self.load_wsgi()
  File "/home/piekuser/venv/lib/python3.7/site-packages/gunicorn/workers/base.py", line 144, in load_wsgi
    self.wsgi = self.app.wsgi()
  File "/home/piekuser/venv/lib/python3.7/site-packages/gunicorn/app/base.py", line 67, in wsgi
    self.callable = self.load()
  File "/home/piekuser/venv/lib/python3.7/site-packages/gunicorn/app/wsgiapp.py", line 49, in load
    return self.load_wsgiapp()
  File "/home/piekuser/venv/lib/python3.7/site-packages/gunicorn/app/wsgiapp.py", line 39, in load_wsgiapp
    return util.import_app(self.app_uri)
  File "/home/piekuser/venv/lib/python3.7/site-packages/gunicorn/util.py", line 358, in import_app
    mod = importlib.import_module(module)
  File "/usr/lib/python3.7/importlib/__init__.py", line 127, in import_module
    return _bootstrap._gcd_import(name[level:], package, level)
  File "<frozen importlib._bootstrap>", line 1006, in _gcd_import
  File "<frozen importlib._bootstrap>", line 983, in _find_and_load
  File "<frozen importlib._bootstrap>", line 967, in _find_and_load_unlocked
  File "<frozen importlib._bootstrap>", line 677, in _load_unlocked
  File "<frozen importlib._bootstrap_external>", line 728, in exec_module
  File "<frozen importlib._bootstrap>", line 219, in _call_with_frames_removed
  File "/home/piekuser/piek/jrl/wsgi.py", line 16, in <module>
    application = get_wsgi_application()
  File "/home/piekuser/venv/lib/python3.7/site-packages/django/core/wsgi.py", line 12, in get_wsgi_application
    django.setup(set_prefix=False)
  File "/home/piekuser/venv/lib/python3.7/site-packages/django/__init__.py", line 24, in setup
    apps.populate(settings.INSTALLED_APPS)
  File "/home/piekuser/venv/lib/python3.7/site-packages/django/apps/registry.py", line 114, in populate
    app_config.import_models()
  File "/home/piekuser/venv/lib/python3.7/site-packages/django/apps/config.py", line 211, in import_models
    self.models_module = import_module(models_module_name)
  File "/usr/lib/python3.7/importlib/__init__.py", line 127, in import_module
    return _bootstrap._gcd_import(name[level:], package, level)
  File "<frozen importlib._bootstrap>", line 1006, in _gcd_import
  File "<frozen importlib._bootstrap>", line 983, in _find_and_load
  File "<frozen importlib._bootstrap>", line 967, in _find_and_load_unlocked
  File "<frozen importlib._bootstrap>", line 677, in _load_unlocked
  File "<frozen importlib._bootstrap_external>", line 728, in exec_module
  File "<frozen importlib._bootstrap>", line 219, in _call_with_frames_removed
  File "/home/piekuser/piek/mainapp/models.py", line 3, in <module>
    from tinymce import HTMLField
ImportError: cannot import name 'HTMLField' from 'tinymce' (/home/piekuser/venv/lib/python3.7/site-packages/tinymce/__init__.py)
[2020-08-18 12:19:54 +0000] [15257] [INFO] Worker exiting (pid: 15257)
[2020-08-18 12:19:55 +0000] [15258] [ERROR] Exception in worker process
Traceback (most recent call last):
  File "/home/piekuser/venv/lib/python3.7/site-packages/gunicorn/arbiter.py", line 583, in spawn_worker
    worker.init_process()
  File "/home/piekuser/venv/lib/python3.7/site-packages/gunicorn/workers/base.py", line 119, in init_process
    self.load_wsgi()
  File "/home/piekuser/venv/lib/python3.7/site-packages/gunicorn/workers/base.py", line 144, in load_wsgi
    self.wsgi = self.app.wsgi()
  File "/home/piekuser/venv/lib/python3.7/site-packages/gunicorn/app/base.py", line 67, in wsgi
    self.callable = self.load()
  File "/home/piekuser/venv/lib/python3.7/site-packages/gunicorn/app/wsgiapp.py", line 49, in load
    return self.load_wsgiapp()
  File "/home/piekuser/venv/lib/python3.7/site-packages/gunicorn/app/wsgiapp.py", line 39, in load_wsgiapp
    return util.import_app(self.app_uri)
  File "/home/piekuser/venv/lib/python3.7/site-packages/gunicorn/util.py", line 358, in import_app
    mod = importlib.import_module(module)
  File "/usr/lib/python3.7/importlib/__init__.py", line 127, in import_module
    return _bootstrap._gcd_import(name[level:], package, level)
  File "<frozen importlib._bootstrap>", line 1006, in _gcd_import
  File "<frozen importlib._bootstrap>", line 983, in _find_and_load
  File "<frozen importlib._bootstrap>", line 967, in _find_and_load_unlocked
  File "<frozen importlib._bootstrap>", line 677, in _load_unlocked
  File "<frozen importlib._bootstrap_external>", line 728, in exec_module
  File "<frozen importlib._bootstrap>", line 219, in _call_with_frames_removed
  File "/home/piekuser/piek/jrl/wsgi.py", line 16, in <module>
    application = get_wsgi_application()
  File "/home/piekuser/venv/lib/python3.7/site-packages/django/core/wsgi.py", line 12, in get_wsgi_application
    django.setup(set_prefix=False)
  File "/home/piekuser/venv/lib/python3.7/site-packages/django/__init__.py", line 24, in setup
    apps.populate(settings.INSTALLED_APPS)
  File "/home/piekuser/venv/lib/python3.7/site-packages/django/apps/registry.py", line 114, in populate
    app_config.import_models()
  File "/home/piekuser/venv/lib/python3.7/site-packages/django/apps/config.py", line 211, in import_models
    self.models_module = import_module(models_module_name)
  File "/usr/lib/python3.7/importlib/__init__.py", line 127, in import_module
    return _bootstrap._gcd_import(name[level:], package, level)
  File "<frozen importlib._bootstrap>", line 1006, in _gcd_import
  File "<frozen importlib._bootstrap>", line 983, in _find_and_load
  File "<frozen importlib._bootstrap>", line 967, in _find_and_load_unlocked
  File "<frozen importlib._bootstrap>", line 677, in _load_unlocked
  File "<frozen importlib._bootstrap_external>", line 728, in exec_module
  File "<frozen importlib._bootstrap>", line 219, in _call_with_frames_removed
  File "/home/piekuser/piek/mainapp/models.py", line 3, in <module>
    from tinymce import HTMLField
ImportError: cannot import name 'HTMLField' from 'tinymce' (/home/piekuser/venv/lib/python3.7/site-packages/tinymce/__init__.py)
[2020-08-18 12:19:55 +0000] [15258] [INFO] Worker exiting (pid: 15258)
[2020-08-18 15:19:55 +0300] [15254] [INFO] Shutting down: Master
[2020-08-18 15:19:55 +0300] [15254] [INFO] Reason: Worker failed to boot.
[2020-08-18 15:19:56 +0300] [15263] [INFO] Starting gunicorn 20.0.4
[2020-08-18 15:19:56 +0300] [15263] [INFO] Listening at: http://127.0.0.1:8000 (15263)
[2020-08-18 15:19:56 +0300] [15263] [INFO] Using worker: sync
[2020-08-18 15:19:56 +0300] [15266] [INFO] Booting worker with pid: 15266
[2020-08-18 15:19:56 +0300] [15267] [INFO] Booting worker with pid: 15267
[2020-08-18 12:19:56 +0000] [15266] [ERROR] Exception in worker process
Traceback (most recent call last):
  File "/home/piekuser/venv/lib/python3.7/site-packages/gunicorn/arbiter.py", line 583, in spawn_worker
    worker.init_process()
  File "/home/piekuser/venv/lib/python3.7/site-packages/gunicorn/workers/base.py", line 119, in init_process
    self.load_wsgi()
  File "/home/piekuser/venv/lib/python3.7/site-packages/gunicorn/workers/base.py", line 144, in load_wsgi
    self.wsgi = self.app.wsgi()
  File "/home/piekuser/venv/lib/python3.7/site-packages/gunicorn/app/base.py", line 67, in wsgi
    self.callable = self.load()
  File "/home/piekuser/venv/lib/python3.7/site-packages/gunicorn/app/wsgiapp.py", line 49, in load
    return self.load_wsgiapp()
  File "/home/piekuser/venv/lib/python3.7/site-packages/gunicorn/app/wsgiapp.py", line 39, in load_wsgiapp
    return util.import_app(self.app_uri)
  File "/home/piekuser/venv/lib/python3.7/site-packages/gunicorn/util.py", line 358, in import_app
    mod = importlib.import_module(module)
  File "/usr/lib/python3.7/importlib/__init__.py", line 127, in import_module
    return _bootstrap._gcd_import(name[level:], package, level)
  File "<frozen importlib._bootstrap>", line 1006, in _gcd_import
  File "<frozen importlib._bootstrap>", line 983, in _find_and_load
  File "<frozen importlib._bootstrap>", line 967, in _find_and_load_unlocked
  File "<frozen importlib._bootstrap>", line 677, in _load_unlocked
  File "<frozen importlib._bootstrap_external>", line 728, in exec_module
  File "<frozen importlib._bootstrap>", line 219, in _call_with_frames_removed
  File "/home/piekuser/piek/jrl/wsgi.py", line 16, in <module>
    application = get_wsgi_application()
  File "/home/piekuser/venv/lib/python3.7/site-packages/django/core/wsgi.py", line 12, in get_wsgi_application
    django.setup(set_prefix=False)
  File "/home/piekuser/venv/lib/python3.7/site-packages/django/__init__.py", line 24, in setup
    apps.populate(settings.INSTALLED_APPS)
  File "/home/piekuser/venv/lib/python3.7/site-packages/django/apps/registry.py", line 114, in populate
    app_config.import_models()
  File "/home/piekuser/venv/lib/python3.7/site-packages/django/apps/config.py", line 211, in import_models
    self.models_module = import_module(models_module_name)
  File "/usr/lib/python3.7/importlib/__init__.py", line 127, in import_module
    return _bootstrap._gcd_import(name[level:], package, level)
  File "<frozen importlib._bootstrap>", line 1006, in _gcd_import
  File "<frozen importlib._bootstrap>", line 983, in _find_and_load
  File "<frozen importlib._bootstrap>", line 967, in _find_and_load_unlocked
  File "<frozen importlib._bootstrap>", line 677, in _load_unlocked
  File "<frozen importlib._bootstrap_external>", line 728, in exec_module
  File "<frozen importlib._bootstrap>", line 219, in _call_with_frames_removed
  File "/home/piekuser/piek/mainapp/models.py", line 3, in <module>
    from tinymce import HTMLField
ImportError: cannot import name 'HTMLField' from 'tinymce' (/home/piekuser/venv/lib/python3.7/site-packages/tinymce/__init__.py)
[2020-08-18 12:19:56 +0000] [15266] [INFO] Worker exiting (pid: 15266)
[2020-08-18 12:19:56 +0000] [15267] [ERROR] Exception in worker process
Traceback (most recent call last):
  File "/home/piekuser/venv/lib/python3.7/site-packages/gunicorn/arbiter.py", line 583, in spawn_worker
    worker.init_process()
  File "/home/piekuser/venv/lib/python3.7/site-packages/gunicorn/workers/base.py", line 119, in init_process
    self.load_wsgi()
  File "/home/piekuser/venv/lib/python3.7/site-packages/gunicorn/workers/base.py", line 144, in load_wsgi
    self.wsgi = self.app.wsgi()
  File "/home/piekuser/venv/lib/python3.7/site-packages/gunicorn/app/base.py", line 67, in wsgi
    self.callable = self.load()
  File "/home/piekuser/venv/lib/python3.7/site-packages/gunicorn/app/wsgiapp.py", line 49, in load
    return self.load_wsgiapp()
  File "/home/piekuser/venv/lib/python3.7/site-packages/gunicorn/app/wsgiapp.py", line 39, in load_wsgiapp
    return util.import_app(self.app_uri)
  File "/home/piekuser/venv/lib/python3.7/site-packages/gunicorn/util.py", line 358, in import_app
    mod = importlib.import_module(module)
  File "/usr/lib/python3.7/importlib/__init__.py", line 127, in import_module
    return _bootstrap._gcd_import(name[level:], package, level)
  File "<frozen importlib._bootstrap>", line 1006, in _gcd_import
  File "<frozen importlib._bootstrap>", line 983, in _find_and_load
  File "<frozen importlib._bootstrap>", line 967, in _find_and_load_unlocked
  File "<frozen importlib._bootstrap>", line 677, in _load_unlocked
  File "<frozen importlib._bootstrap_external>", line 728, in exec_module
  File "<frozen importlib._bootstrap>", line 219, in _call_with_frames_removed
  File "/home/piekuser/piek/jrl/wsgi.py", line 16, in <module>
    application = get_wsgi_application()
  File "/home/piekuser/venv/lib/python3.7/site-packages/django/core/wsgi.py", line 12, in get_wsgi_application
    django.setup(set_prefix=False)
  File "/home/piekuser/venv/lib/python3.7/site-packages/django/__init__.py", line 24, in setup
    apps.populate(settings.INSTALLED_APPS)
  File "/home/piekuser/venv/lib/python3.7/site-packages/django/apps/registry.py", line 114, in populate
    app_config.import_models()
  File "/home/piekuser/venv/lib/python3.7/site-packages/django/apps/config.py", line 211, in import_models
    self.models_module = import_module(models_module_name)
  File "/usr/lib/python3.7/importlib/__init__.py", line 127, in import_module
    return _bootstrap._gcd_import(name[level:], package, level)
  File "<frozen importlib._bootstrap>", line 1006, in _gcd_import
  File "<frozen importlib._bootstrap>", line 983, in _find_and_load
  File "<frozen importlib._bootstrap>", line 967, in _find_and_load_unlocked
  File "<frozen importlib._bootstrap>", line 677, in _load_unlocked
  File "<frozen importlib._bootstrap_external>", line 728, in exec_module
  File "<frozen importlib._bootstrap>", line 219, in _call_with_frames_removed
  File "/home/piekuser/piek/mainapp/models.py", line 3, in <module>
    from tinymce import HTMLField
ImportError: cannot import name 'HTMLField' from 'tinymce' (/home/piekuser/venv/lib/python3.7/site-packages/tinymce/__init__.py)
[2020-08-18 12:19:56 +0000] [15267] [INFO] Worker exiting (pid: 15267)
Traceback (most recent call last):
  File "/home/piekuser/venv/lib/python3.7/site-packages/gunicorn/arbiter.py", line 209, in run
    self.sleep()
  File "/home/piekuser/venv/lib/python3.7/site-packages/gunicorn/arbiter.py", line 357, in sleep
    ready = select.select([self.PIPE[0]], [], [], 1.0)
  File "/home/piekuser/venv/lib/python3.7/site-packages/gunicorn/arbiter.py", line 242, in handle_chld
    self.reap_workers()
  File "/home/piekuser/venv/lib/python3.7/site-packages/gunicorn/arbiter.py", line 525, in reap_workers
    raise HaltServer(reason, self.WORKER_BOOT_ERROR)
gunicorn.errors.HaltServer: <HaltServer 'Worker failed to boot.' 3>

During handling of the above exception, another exception occurred:

Traceback (most recent call last):
  File "/home/piekuser/venv/bin/gunicorn", line 10, in <module>
    sys.exit(run())
  File "/home/piekuser/venv/lib/python3.7/site-packages/gunicorn/app/wsgiapp.py", line 58, in run
    WSGIApplication("%(prog)s [OPTIONS] [APP_MODULE]").run()
  File "/home/piekuser/venv/lib/python3.7/site-packages/gunicorn/app/base.py", line 228, in run
    super().run()
  File "/home/piekuser/venv/lib/python3.7/site-packages/gunicorn/app/base.py", line 72, in run
    Arbiter(self).run()
  File "/home/piekuser/venv/lib/python3.7/site-packages/gunicorn/arbiter.py", line 229, in run
    self.halt(reason=inst.reason, exit_status=inst.exit_status)
  File "/home/piekuser/venv/lib/python3.7/site-packages/gunicorn/arbiter.py", line 342, in halt
    self.stop()
  File "/home/piekuser/venv/lib/python3.7/site-packages/gunicorn/arbiter.py", line 393, in stop
    time.sleep(0.1)
  File "/home/piekuser/venv/lib/python3.7/site-packages/gunicorn/arbiter.py", line 242, in handle_chld
    self.reap_workers()
  File "/home/piekuser/venv/lib/python3.7/site-packages/gunicorn/arbiter.py", line 525, in reap_workers
    raise HaltServer(reason, self.WORKER_BOOT_ERROR)
gunicorn.errors.HaltServer: <HaltServer 'Worker failed to boot.' 3>
[2020-08-18 15:19:59 +0300] [15268] [INFO] Starting gunicorn 20.0.4
[2020-08-18 15:19:59 +0300] [15268] [INFO] Listening at: http://127.0.0.1:8000 (15268)
[2020-08-18 15:19:59 +0300] [15268] [INFO] Using worker: sync
[2020-08-18 15:19:59 +0300] [15271] [INFO] Booting worker with pid: 15271
[2020-08-18 15:19:59 +0300] [15272] [INFO] Booting worker with pid: 15272
[2020-08-18 12:19:59 +0000] [15271] [ERROR] Exception in worker process
Traceback (most recent call last):
  File "/home/piekuser/venv/lib/python3.7/site-packages/gunicorn/arbiter.py", line 583, in spawn_worker
    worker.init_process()
  File "/home/piekuser/venv/lib/python3.7/site-packages/gunicorn/workers/base.py", line 119, in init_process
    self.load_wsgi()
  File "/home/piekuser/venv/lib/python3.7/site-packages/gunicorn/workers/base.py", line 144, in load_wsgi
    self.wsgi = self.app.wsgi()
  File "/home/piekuser/venv/lib/python3.7/site-packages/gunicorn/app/base.py", line 67, in wsgi
    self.callable = self.load()
  File "/home/piekuser/venv/lib/python3.7/site-packages/gunicorn/app/wsgiapp.py", line 49, in load
    return self.load_wsgiapp()
  File "/home/piekuser/venv/lib/python3.7/site-packages/gunicorn/app/wsgiapp.py", line 39, in load_wsgiapp
    return util.import_app(self.app_uri)
  File "/home/piekuser/venv/lib/python3.7/site-packages/gunicorn/util.py", line 358, in import_app
    mod = importlib.import_module(module)
  File "/usr/lib/python3.7/importlib/__init__.py", line 127, in import_module
    return _bootstrap._gcd_import(name[level:], package, level)
  File "<frozen importlib._bootstrap>", line 1006, in _gcd_import
  File "<frozen importlib._bootstrap>", line 983, in _find_and_load
  File "<frozen importlib._bootstrap>", line 967, in _find_and_load_unlocked
  File "<frozen importlib._bootstrap>", line 677, in _load_unlocked
  File "<frozen importlib._bootstrap_external>", line 728, in exec_module
  File "<frozen importlib._bootstrap>", line 219, in _call_with_frames_removed
  File "/home/piekuser/piek/jrl/wsgi.py", line 16, in <module>
    application = get_wsgi_application()
  File "/home/piekuser/venv/lib/python3.7/site-packages/django/core/wsgi.py", line 12, in get_wsgi_application
    django.setup(set_prefix=False)
  File "/home/piekuser/venv/lib/python3.7/site-packages/django/__init__.py", line 24, in setup
    apps.populate(settings.INSTALLED_APPS)
  File "/home/piekuser/venv/lib/python3.7/site-packages/django/apps/registry.py", line 114, in populate
    app_config.import_models()
  File "/home/piekuser/venv/lib/python3.7/site-packages/django/apps/config.py", line 211, in import_models
    self.models_module = import_module(models_module_name)
  File "/usr/lib/python3.7/importlib/__init__.py", line 127, in import_module
    return _bootstrap._gcd_import(name[level:], package, level)
  File "<frozen importlib._bootstrap>", line 1006, in _gcd_import
  File "<frozen importlib._bootstrap>", line 983, in _find_and_load
  File "<frozen importlib._bootstrap>", line 967, in _find_and_load_unlocked
  File "<frozen importlib._bootstrap>", line 677, in _load_unlocked
  File "<frozen importlib._bootstrap_external>", line 728, in exec_module
  File "<frozen importlib._bootstrap>", line 219, in _call_with_frames_removed
  File "/home/piekuser/piek/mainapp/models.py", line 3, in <module>
    from tinymce import HTMLField
ImportError: cannot import name 'HTMLField' from 'tinymce' (/home/piekuser/venv/lib/python3.7/site-packages/tinymce/__init__.py)
[2020-08-18 12:19:59 +0000] [15271] [INFO] Worker exiting (pid: 15271)
[2020-08-18 12:19:59 +0000] [15272] [ERROR] Exception in worker process
Traceback (most recent call last):
  File "/home/piekuser/venv/lib/python3.7/site-packages/gunicorn/arbiter.py", line 583, in spawn_worker
    worker.init_process()
  File "/home/piekuser/venv/lib/python3.7/site-packages/gunicorn/workers/base.py", line 119, in init_process
    self.load_wsgi()
  File "/home/piekuser/venv/lib/python3.7/site-packages/gunicorn/workers/base.py", line 144, in load_wsgi
    self.wsgi = self.app.wsgi()
  File "/home/piekuser/venv/lib/python3.7/site-packages/gunicorn/app/base.py", line 67, in wsgi
    self.callable = self.load()
  File "/home/piekuser/venv/lib/python3.7/site-packages/gunicorn/app/wsgiapp.py", line 49, in load
    return self.load_wsgiapp()
  File "/home/piekuser/venv/lib/python3.7/site-packages/gunicorn/app/wsgiapp.py", line 39, in load_wsgiapp
    return util.import_app(self.app_uri)
  File "/home/piekuser/venv/lib/python3.7/site-packages/gunicorn/util.py", line 358, in import_app
    mod = importlib.import_module(module)
  File "/usr/lib/python3.7/importlib/__init__.py", line 127, in import_module
    return _bootstrap._gcd_import(name[level:], package, level)
  File "<frozen importlib._bootstrap>", line 1006, in _gcd_import
  File "<frozen importlib._bootstrap>", line 983, in _find_and_load
  File "<frozen importlib._bootstrap>", line 967, in _find_and_load_unlocked
  File "<frozen importlib._bootstrap>", line 677, in _load_unlocked
  File "<frozen importlib._bootstrap_external>", line 728, in exec_module
  File "<frozen importlib._bootstrap>", line 219, in _call_with_frames_removed
  File "/home/piekuser/piek/jrl/wsgi.py", line 16, in <module>
    application = get_wsgi_application()
  File "/home/piekuser/venv/lib/python3.7/site-packages/django/core/wsgi.py", line 12, in get_wsgi_application
    django.setup(set_prefix=False)
  File "/home/piekuser/venv/lib/python3.7/site-packages/django/__init__.py", line 24, in setup
    apps.populate(settings.INSTALLED_APPS)
  File "/home/piekuser/venv/lib/python3.7/site-packages/django/apps/registry.py", line 114, in populate
    app_config.import_models()
  File "/home/piekuser/venv/lib/python3.7/site-packages/django/apps/config.py", line 211, in import_models
    self.models_module = import_module(models_module_name)
  File "/usr/lib/python3.7/importlib/__init__.py", line 127, in import_module
    return _bootstrap._gcd_import(name[level:], package, level)
  File "<frozen importlib._bootstrap>", line 1006, in _gcd_import
  File "<frozen importlib._bootstrap>", line 983, in _find_and_load
  File "<frozen importlib._bootstrap>", line 967, in _find_and_load_unlocked
  File "<frozen importlib._bootstrap>", line 677, in _load_unlocked
  File "<frozen importlib._bootstrap_external>", line 728, in exec_module
  File "<frozen importlib._bootstrap>", line 219, in _call_with_frames_removed
  File "/home/piekuser/piek/mainapp/models.py", line 3, in <module>
    from tinymce import HTMLField
ImportError: cannot import name 'HTMLField' from 'tinymce' (/home/piekuser/venv/lib/python3.7/site-packages/tinymce/__init__.py)
[2020-08-18 12:19:59 +0000] [15272] [INFO] Worker exiting (pid: 15272)
Traceback (most recent call last):
  File "/home/piekuser/venv/lib/python3.7/site-packages/gunicorn/arbiter.py", line 209, in run
    self.sleep()
  File "/home/piekuser/venv/lib/python3.7/site-packages/gunicorn/arbiter.py", line 357, in sleep
    ready = select.select([self.PIPE[0]], [], [], 1.0)
  File "/home/piekuser/venv/lib/python3.7/site-packages/gunicorn/arbiter.py", line 242, in handle_chld
    self.reap_workers()
  File "/home/piekuser/venv/lib/python3.7/site-packages/gunicorn/arbiter.py", line 525, in reap_workers
    raise HaltServer(reason, self.WORKER_BOOT_ERROR)
gunicorn.errors.HaltServer: <HaltServer 'Worker failed to boot.' 3>

During handling of the above exception, another exception occurred:

Traceback (most recent call last):
  File "/home/piekuser/venv/bin/gunicorn", line 10, in <module>
    sys.exit(run())
  File "/home/piekuser/venv/lib/python3.7/site-packages/gunicorn/app/wsgiapp.py", line 58, in run
    WSGIApplication("%(prog)s [OPTIONS] [APP_MODULE]").run()
  File "/home/piekuser/venv/lib/python3.7/site-packages/gunicorn/app/base.py", line 228, in run
    super().run()
  File "/home/piekuser/venv/lib/python3.7/site-packages/gunicorn/app/base.py", line 72, in run
    Arbiter(self).run()
  File "/home/piekuser/venv/lib/python3.7/site-packages/gunicorn/arbiter.py", line 229, in run
    self.halt(reason=inst.reason, exit_status=inst.exit_status)
  File "/home/piekuser/venv/lib/python3.7/site-packages/gunicorn/arbiter.py", line 342, in halt
    self.stop()
  File "/home/piekuser/venv/lib/python3.7/site-packages/gunicorn/arbiter.py", line 393, in stop
    time.sleep(0.1)
  File "/home/piekuser/venv/lib/python3.7/site-packages/gunicorn/arbiter.py", line 242, in handle_chld
    self.reap_workers()
  File "/home/piekuser/venv/lib/python3.7/site-packages/gunicorn/arbiter.py", line 525, in reap_workers
    raise HaltServer(reason, self.WORKER_BOOT_ERROR)
gunicorn.errors.HaltServer: <HaltServer 'Worker failed to boot.' 3>
[2020-08-18 15:20:02 +0300] [15275] [INFO] Starting gunicorn 20.0.4
[2020-08-18 15:20:02 +0300] [15275] [INFO] Listening at: http://127.0.0.1:8000 (15275)
[2020-08-18 15:20:02 +0300] [15275] [INFO] Using worker: sync
[2020-08-18 15:20:02 +0300] [15278] [INFO] Booting worker with pid: 15278
[2020-08-18 15:20:02 +0300] [15279] [INFO] Booting worker with pid: 15279
[2020-08-18 12:20:03 +0000] [15278] [ERROR] Exception in worker process
Traceback (most recent call last):
  File "/home/piekuser/venv/lib/python3.7/site-packages/gunicorn/arbiter.py", line 583, in spawn_worker
    worker.init_process()
  File "/home/piekuser/venv/lib/python3.7/site-packages/gunicorn/workers/base.py", line 119, in init_process
    self.load_wsgi()
  File "/home/piekuser/venv/lib/python3.7/site-packages/gunicorn/workers/base.py", line 144, in load_wsgi
    self.wsgi = self.app.wsgi()
  File "/home/piekuser/venv/lib/python3.7/site-packages/gunicorn/app/base.py", line 67, in wsgi
    self.callable = self.load()
  File "/home/piekuser/venv/lib/python3.7/site-packages/gunicorn/app/wsgiapp.py", line 49, in load
    return self.load_wsgiapp()
  File "/home/piekuser/venv/lib/python3.7/site-packages/gunicorn/app/wsgiapp.py", line 39, in load_wsgiapp
    return util.import_app(self.app_uri)
  File "/home/piekuser/venv/lib/python3.7/site-packages/gunicorn/util.py", line 358, in import_app
    mod = importlib.import_module(module)
  File "/usr/lib/python3.7/importlib/__init__.py", line 127, in import_module
    return _bootstrap._gcd_import(name[level:], package, level)
  File "<frozen importlib._bootstrap>", line 1006, in _gcd_import
  File "<frozen importlib._bootstrap>", line 983, in _find_and_load
  File "<frozen importlib._bootstrap>", line 967, in _find_and_load_unlocked
  File "<frozen importlib._bootstrap>", line 677, in _load_unlocked
  File "<frozen importlib._bootstrap_external>", line 728, in exec_module
  File "<frozen importlib._bootstrap>", line 219, in _call_with_frames_removed
  File "/home/piekuser/piek/jrl/wsgi.py", line 16, in <module>
    application = get_wsgi_application()
  File "/home/piekuser/venv/lib/python3.7/site-packages/django/core/wsgi.py", line 12, in get_wsgi_application
    django.setup(set_prefix=False)
  File "/home/piekuser/venv/lib/python3.7/site-packages/django/__init__.py", line 24, in setup
    apps.populate(settings.INSTALLED_APPS)
  File "/home/piekuser/venv/lib/python3.7/site-packages/django/apps/registry.py", line 114, in populate
    app_config.import_models()
  File "/home/piekuser/venv/lib/python3.7/site-packages/django/apps/config.py", line 211, in import_models
    self.models_module = import_module(models_module_name)
  File "/usr/lib/python3.7/importlib/__init__.py", line 127, in import_module
    return _bootstrap._gcd_import(name[level:], package, level)
  File "<frozen importlib._bootstrap>", line 1006, in _gcd_import
  File "<frozen importlib._bootstrap>", line 983, in _find_and_load
  File "<frozen importlib._bootstrap>", line 967, in _find_and_load_unlocked
  File "<frozen importlib._bootstrap>", line 677, in _load_unlocked
  File "<frozen importlib._bootstrap_external>", line 728, in exec_module
  File "<frozen importlib._bootstrap>", line 219, in _call_with_frames_removed
  File "/home/piekuser/piek/mainapp/models.py", line 3, in <module>
    from tinymce import HTMLField
ImportError: cannot import name 'HTMLField' from 'tinymce' (/home/piekuser/venv/lib/python3.7/site-packages/tinymce/__init__.py)
[2020-08-18 12:20:03 +0000] [15278] [INFO] Worker exiting (pid: 15278)
[2020-08-18 12:20:03 +0000] [15279] [ERROR] Exception in worker process
Traceback (most recent call last):
  File "/home/piekuser/venv/lib/python3.7/site-packages/gunicorn/arbiter.py", line 583, in spawn_worker
    worker.init_process()
  File "/home/piekuser/venv/lib/python3.7/site-packages/gunicorn/workers/base.py", line 119, in init_process
    self.load_wsgi()
  File "/home/piekuser/venv/lib/python3.7/site-packages/gunicorn/workers/base.py", line 144, in load_wsgi
    self.wsgi = self.app.wsgi()
  File "/home/piekuser/venv/lib/python3.7/site-packages/gunicorn/app/base.py", line 67, in wsgi
    self.callable = self.load()
  File "/home/piekuser/venv/lib/python3.7/site-packages/gunicorn/app/wsgiapp.py", line 49, in load
    return self.load_wsgiapp()
  File "/home/piekuser/venv/lib/python3.7/site-packages/gunicorn/app/wsgiapp.py", line 39, in load_wsgiapp
    return util.import_app(self.app_uri)
  File "/home/piekuser/venv/lib/python3.7/site-packages/gunicorn/util.py", line 358, in import_app
    mod = importlib.import_module(module)
  File "/usr/lib/python3.7/importlib/__init__.py", line 127, in import_module
    return _bootstrap._gcd_import(name[level:], package, level)
  File "<frozen importlib._bootstrap>", line 1006, in _gcd_import
  File "<frozen importlib._bootstrap>", line 983, in _find_and_load
  File "<frozen importlib._bootstrap>", line 967, in _find_and_load_unlocked
  File "<frozen importlib._bootstrap>", line 677, in _load_unlocked
  File "<frozen importlib._bootstrap_external>", line 728, in exec_module
  File "<frozen importlib._bootstrap>", line 219, in _call_with_frames_removed
  File "/home/piekuser/piek/jrl/wsgi.py", line 16, in <module>
    application = get_wsgi_application()
  File "/home/piekuser/venv/lib/python3.7/site-packages/django/core/wsgi.py", line 12, in get_wsgi_application
    django.setup(set_prefix=False)
  File "/home/piekuser/venv/lib/python3.7/site-packages/django/__init__.py", line 24, in setup
    apps.populate(settings.INSTALLED_APPS)
  File "/home/piekuser/venv/lib/python3.7/site-packages/django/apps/registry.py", line 114, in populate
    app_config.import_models()
  File "/home/piekuser/venv/lib/python3.7/site-packages/django/apps/config.py", line 211, in import_models
    self.models_module = import_module(models_module_name)
  File "/usr/lib/python3.7/importlib/__init__.py", line 127, in import_module
    return _bootstrap._gcd_import(name[level:], package, level)
  File "<frozen importlib._bootstrap>", line 1006, in _gcd_import
  File "<frozen importlib._bootstrap>", line 983, in _find_and_load
  File "<frozen importlib._bootstrap>", line 967, in _find_and_load_unlocked
  File "<frozen importlib._bootstrap>", line 677, in _load_unlocked
  File "<frozen importlib._bootstrap_external>", line 728, in exec_module
  File "<frozen importlib._bootstrap>", line 219, in _call_with_frames_removed
  File "/home/piekuser/piek/mainapp/models.py", line 3, in <module>
    from tinymce import HTMLField
ImportError: cannot import name 'HTMLField' from 'tinymce' (/home/piekuser/venv/lib/python3.7/site-packages/tinymce/__init__.py)
[2020-08-18 12:20:03 +0000] [15279] [INFO] Worker exiting (pid: 15279)
Traceback (most recent call last):
  File "/home/piekuser/venv/lib/python3.7/site-packages/gunicorn/arbiter.py", line 209, in run
    self.sleep()
  File "/home/piekuser/venv/lib/python3.7/site-packages/gunicorn/arbiter.py", line 357, in sleep
    ready = select.select([self.PIPE[0]], [], [], 1.0)
  File "/home/piekuser/venv/lib/python3.7/site-packages/gunicorn/arbiter.py", line 242, in handle_chld
    self.reap_workers()
  File "/home/piekuser/venv/lib/python3.7/site-packages/gunicorn/arbiter.py", line 525, in reap_workers
    raise HaltServer(reason, self.WORKER_BOOT_ERROR)
gunicorn.errors.HaltServer: <HaltServer 'Worker failed to boot.' 3>

During handling of the above exception, another exception occurred:

Traceback (most recent call last):
  File "/home/piekuser/venv/bin/gunicorn", line 10, in <module>
    sys.exit(run())
  File "/home/piekuser/venv/lib/python3.7/site-packages/gunicorn/app/wsgiapp.py", line 58, in run
    WSGIApplication("%(prog)s [OPTIONS] [APP_MODULE]").run()
  File "/home/piekuser/venv/lib/python3.7/site-packages/gunicorn/app/base.py", line 228, in run
    super().run()
  File "/home/piekuser/venv/lib/python3.7/site-packages/gunicorn/app/base.py", line 72, in run
    Arbiter(self).run()
  File "/home/piekuser/venv/lib/python3.7/site-packages/gunicorn/arbiter.py", line 229, in run
    self.halt(reason=inst.reason, exit_status=inst.exit_status)
  File "/home/piekuser/venv/lib/python3.7/site-packages/gunicorn/arbiter.py", line 342, in halt
    self.stop()
  File "/home/piekuser/venv/lib/python3.7/site-packages/gunicorn/arbiter.py", line 393, in stop
    time.sleep(0.1)
  File "/home/piekuser/venv/lib/python3.7/site-packages/gunicorn/arbiter.py", line 242, in handle_chld
    self.reap_workers()
  File "/home/piekuser/venv/lib/python3.7/site-packages/gunicorn/arbiter.py", line 525, in reap_workers
    raise HaltServer(reason, self.WORKER_BOOT_ERROR)
gunicorn.errors.HaltServer: <HaltServer 'Worker failed to boot.' 3>
[2020-08-18 15:20:52 +0300] [15295] [INFO] Starting gunicorn 20.0.4
[2020-08-18 15:20:52 +0300] [15295] [INFO] Listening at: http://127.0.0.1:8000 (15295)
[2020-08-18 15:20:52 +0300] [15295] [INFO] Using worker: sync
[2020-08-18 15:20:52 +0300] [15298] [INFO] Booting worker with pid: 15298
[2020-08-18 15:20:53 +0300] [15299] [INFO] Booting worker with pid: 15299
[2020-08-18 12:20:53 +0000] [15298] [ERROR] Exception in worker process
Traceback (most recent call last):
  File "/home/piekuser/venv/lib/python3.7/site-packages/gunicorn/arbiter.py", line 583, in spawn_worker
    worker.init_process()
  File "/home/piekuser/venv/lib/python3.7/site-packages/gunicorn/workers/base.py", line 119, in init_process
    self.load_wsgi()
  File "/home/piekuser/venv/lib/python3.7/site-packages/gunicorn/workers/base.py", line 144, in load_wsgi
    self.wsgi = self.app.wsgi()
  File "/home/piekuser/venv/lib/python3.7/site-packages/gunicorn/app/base.py", line 67, in wsgi
    self.callable = self.load()
  File "/home/piekuser/venv/lib/python3.7/site-packages/gunicorn/app/wsgiapp.py", line 49, in load
    return self.load_wsgiapp()
  File "/home/piekuser/venv/lib/python3.7/site-packages/gunicorn/app/wsgiapp.py", line 39, in load_wsgiapp
    return util.import_app(self.app_uri)
  File "/home/piekuser/venv/lib/python3.7/site-packages/gunicorn/util.py", line 358, in import_app
    mod = importlib.import_module(module)
  File "/usr/lib/python3.7/importlib/__init__.py", line 127, in import_module
    return _bootstrap._gcd_import(name[level:], package, level)
  File "<frozen importlib._bootstrap>", line 1006, in _gcd_import
  File "<frozen importlib._bootstrap>", line 983, in _find_and_load
  File "<frozen importlib._bootstrap>", line 967, in _find_and_load_unlocked
  File "<frozen importlib._bootstrap>", line 677, in _load_unlocked
  File "<frozen importlib._bootstrap_external>", line 728, in exec_module
  File "<frozen importlib._bootstrap>", line 219, in _call_with_frames_removed
  File "/home/piekuser/piek/jrl/wsgi.py", line 16, in <module>
    application = get_wsgi_application()
  File "/home/piekuser/venv/lib/python3.7/site-packages/django/core/wsgi.py", line 12, in get_wsgi_application
    django.setup(set_prefix=False)
  File "/home/piekuser/venv/lib/python3.7/site-packages/django/__init__.py", line 24, in setup
    apps.populate(settings.INSTALLED_APPS)
  File "/home/piekuser/venv/lib/python3.7/site-packages/django/apps/registry.py", line 114, in populate
    app_config.import_models()
  File "/home/piekuser/venv/lib/python3.7/site-packages/django/apps/config.py", line 211, in import_models
    self.models_module = import_module(models_module_name)
  File "/usr/lib/python3.7/importlib/__init__.py", line 127, in import_module
    return _bootstrap._gcd_import(name[level:], package, level)
  File "<frozen importlib._bootstrap>", line 1006, in _gcd_import
  File "<frozen importlib._bootstrap>", line 983, in _find_and_load
  File "<frozen importlib._bootstrap>", line 967, in _find_and_load_unlocked
  File "<frozen importlib._bootstrap>", line 677, in _load_unlocked
  File "<frozen importlib._bootstrap_external>", line 728, in exec_module
  File "<frozen importlib._bootstrap>", line 219, in _call_with_frames_removed
  File "/home/piekuser/piek/mainapp/models.py", line 3, in <module>
    from tinymce import HTMLField
ImportError: cannot import name 'HTMLField' from 'tinymce' (/home/piekuser/venv/lib/python3.7/site-packages/tinymce/__init__.py)
[2020-08-18 12:20:53 +0000] [15298] [INFO] Worker exiting (pid: 15298)
[2020-08-18 12:20:53 +0000] [15299] [ERROR] Exception in worker process
Traceback (most recent call last):
  File "/home/piekuser/venv/lib/python3.7/site-packages/gunicorn/arbiter.py", line 583, in spawn_worker
    worker.init_process()
  File "/home/piekuser/venv/lib/python3.7/site-packages/gunicorn/workers/base.py", line 119, in init_process
    self.load_wsgi()
  File "/home/piekuser/venv/lib/python3.7/site-packages/gunicorn/workers/base.py", line 144, in load_wsgi
    self.wsgi = self.app.wsgi()
  File "/home/piekuser/venv/lib/python3.7/site-packages/gunicorn/app/base.py", line 67, in wsgi
    self.callable = self.load()
  File "/home/piekuser/venv/lib/python3.7/site-packages/gunicorn/app/wsgiapp.py", line 49, in load
    return self.load_wsgiapp()
  File "/home/piekuser/venv/lib/python3.7/site-packages/gunicorn/app/wsgiapp.py", line 39, in load_wsgiapp
    return util.import_app(self.app_uri)
  File "/home/piekuser/venv/lib/python3.7/site-packages/gunicorn/util.py", line 358, in import_app
    mod = importlib.import_module(module)
  File "/usr/lib/python3.7/importlib/__init__.py", line 127, in import_module
    return _bootstrap._gcd_import(name[level:], package, level)
  File "<frozen importlib._bootstrap>", line 1006, in _gcd_import
  File "<frozen importlib._bootstrap>", line 983, in _find_and_load
  File "<frozen importlib._bootstrap>", line 967, in _find_and_load_unlocked
  File "<frozen importlib._bootstrap>", line 677, in _load_unlocked
  File "<frozen importlib._bootstrap_external>", line 728, in exec_module
  File "<frozen importlib._bootstrap>", line 219, in _call_with_frames_removed
  File "/home/piekuser/piek/jrl/wsgi.py", line 16, in <module>
    application = get_wsgi_application()
  File "/home/piekuser/venv/lib/python3.7/site-packages/django/core/wsgi.py", line 12, in get_wsgi_application
    django.setup(set_prefix=False)
  File "/home/piekuser/venv/lib/python3.7/site-packages/django/__init__.py", line 24, in setup
    apps.populate(settings.INSTALLED_APPS)
  File "/home/piekuser/venv/lib/python3.7/site-packages/django/apps/registry.py", line 114, in populate
    app_config.import_models()
  File "/home/piekuser/venv/lib/python3.7/site-packages/django/apps/config.py", line 211, in import_models
    self.models_module = import_module(models_module_name)
  File "/usr/lib/python3.7/importlib/__init__.py", line 127, in import_module
    return _bootstrap._gcd_import(name[level:], package, level)
  File "<frozen importlib._bootstrap>", line 1006, in _gcd_import
  File "<frozen importlib._bootstrap>", line 983, in _find_and_load
  File "<frozen importlib._bootstrap>", line 967, in _find_and_load_unlocked
  File "<frozen importlib._bootstrap>", line 677, in _load_unlocked
  File "<frozen importlib._bootstrap_external>", line 728, in exec_module
  File "<frozen importlib._bootstrap>", line 219, in _call_with_frames_removed
  File "/home/piekuser/piek/mainapp/models.py", line 3, in <module>
    from tinymce import HTMLField
ImportError: cannot import name 'HTMLField' from 'tinymce' (/home/piekuser/venv/lib/python3.7/site-packages/tinymce/__init__.py)
[2020-08-18 12:20:53 +0000] [15299] [INFO] Worker exiting (pid: 15299)
Traceback (most recent call last):
  File "/home/piekuser/venv/lib/python3.7/site-packages/gunicorn/arbiter.py", line 209, in run
    self.sleep()
  File "/home/piekuser/venv/lib/python3.7/site-packages/gunicorn/arbiter.py", line 357, in sleep
    ready = select.select([self.PIPE[0]], [], [], 1.0)
  File "/home/piekuser/venv/lib/python3.7/site-packages/gunicorn/arbiter.py", line 242, in handle_chld
    self.reap_workers()
  File "/home/piekuser/venv/lib/python3.7/site-packages/gunicorn/arbiter.py", line 525, in reap_workers
    raise HaltServer(reason, self.WORKER_BOOT_ERROR)
gunicorn.errors.HaltServer: <HaltServer 'Worker failed to boot.' 3>

During handling of the above exception, another exception occurred:

Traceback (most recent call last):
  File "/home/piekuser/venv/bin/gunicorn", line 10, in <module>
    sys.exit(run())
  File "/home/piekuser/venv/lib/python3.7/site-packages/gunicorn/app/wsgiapp.py", line 58, in run
    WSGIApplication("%(prog)s [OPTIONS] [APP_MODULE]").run()
  File "/home/piekuser/venv/lib/python3.7/site-packages/gunicorn/app/base.py", line 228, in run
    super().run()
  File "/home/piekuser/venv/lib/python3.7/site-packages/gunicorn/app/base.py", line 72, in run
    Arbiter(self).run()
  File "/home/piekuser/venv/lib/python3.7/site-packages/gunicorn/arbiter.py", line 229, in run
    self.halt(reason=inst.reason, exit_status=inst.exit_status)
  File "/home/piekuser/venv/lib/python3.7/site-packages/gunicorn/arbiter.py", line 342, in halt
    self.stop()
  File "/home/piekuser/venv/lib/python3.7/site-packages/gunicorn/arbiter.py", line 393, in stop
    time.sleep(0.1)
  File "/home/piekuser/venv/lib/python3.7/site-packages/gunicorn/arbiter.py", line 242, in handle_chld
    self.reap_workers()
  File "/home/piekuser/venv/lib/python3.7/site-packages/gunicorn/arbiter.py", line 525, in reap_workers
    raise HaltServer(reason, self.WORKER_BOOT_ERROR)
gunicorn.errors.HaltServer: <HaltServer 'Worker failed to boot.' 3>
[2020-08-18 15:20:54 +0300] [15300] [INFO] Starting gunicorn 20.0.4
[2020-08-18 15:20:54 +0300] [15300] [INFO] Listening at: http://127.0.0.1:8000 (15300)
[2020-08-18 15:20:54 +0300] [15300] [INFO] Using worker: sync
[2020-08-18 15:20:54 +0300] [15303] [INFO] Booting worker with pid: 15303
[2020-08-18 15:20:54 +0300] [15304] [INFO] Booting worker with pid: 15304
[2020-08-18 12:20:55 +0000] [15303] [ERROR] Exception in worker process
Traceback (most recent call last):
  File "/home/piekuser/venv/lib/python3.7/site-packages/gunicorn/arbiter.py", line 583, in spawn_worker
    worker.init_process()
  File "/home/piekuser/venv/lib/python3.7/site-packages/gunicorn/workers/base.py", line 119, in init_process
    self.load_wsgi()
  File "/home/piekuser/venv/lib/python3.7/site-packages/gunicorn/workers/base.py", line 144, in load_wsgi
    self.wsgi = self.app.wsgi()
  File "/home/piekuser/venv/lib/python3.7/site-packages/gunicorn/app/base.py", line 67, in wsgi
    self.callable = self.load()
  File "/home/piekuser/venv/lib/python3.7/site-packages/gunicorn/app/wsgiapp.py", line 49, in load
    return self.load_wsgiapp()
  File "/home/piekuser/venv/lib/python3.7/site-packages/gunicorn/app/wsgiapp.py", line 39, in load_wsgiapp
    return util.import_app(self.app_uri)
  File "/home/piekuser/venv/lib/python3.7/site-packages/gunicorn/util.py", line 358, in import_app
    mod = importlib.import_module(module)
  File "/usr/lib/python3.7/importlib/__init__.py", line 127, in import_module
    return _bootstrap._gcd_import(name[level:], package, level)
  File "<frozen importlib._bootstrap>", line 1006, in _gcd_import
  File "<frozen importlib._bootstrap>", line 983, in _find_and_load
  File "<frozen importlib._bootstrap>", line 967, in _find_and_load_unlocked
  File "<frozen importlib._bootstrap>", line 677, in _load_unlocked
  File "<frozen importlib._bootstrap_external>", line 728, in exec_module
  File "<frozen importlib._bootstrap>", line 219, in _call_with_frames_removed
  File "/home/piekuser/piek/jrl/wsgi.py", line 16, in <module>
    application = get_wsgi_application()
  File "/home/piekuser/venv/lib/python3.7/site-packages/django/core/wsgi.py", line 12, in get_wsgi_application
    django.setup(set_prefix=False)
  File "/home/piekuser/venv/lib/python3.7/site-packages/django/__init__.py", line 24, in setup
    apps.populate(settings.INSTALLED_APPS)
  File "/home/piekuser/venv/lib/python3.7/site-packages/django/apps/registry.py", line 114, in populate
    app_config.import_models()
  File "/home/piekuser/venv/lib/python3.7/site-packages/django/apps/config.py", line 211, in import_models
    self.models_module = import_module(models_module_name)
  File "/usr/lib/python3.7/importlib/__init__.py", line 127, in import_module
    return _bootstrap._gcd_import(name[level:], package, level)
  File "<frozen importlib._bootstrap>", line 1006, in _gcd_import
  File "<frozen importlib._bootstrap>", line 983, in _find_and_load
  File "<frozen importlib._bootstrap>", line 967, in _find_and_load_unlocked
  File "<frozen importlib._bootstrap>", line 677, in _load_unlocked
  File "<frozen importlib._bootstrap_external>", line 728, in exec_module
  File "<frozen importlib._bootstrap>", line 219, in _call_with_frames_removed
  File "/home/piekuser/piek/mainapp/models.py", line 3, in <module>
    from tinymce import HTMLField
ImportError: cannot import name 'HTMLField' from 'tinymce' (/home/piekuser/venv/lib/python3.7/site-packages/tinymce/__init__.py)
[2020-08-18 12:20:55 +0000] [15303] [INFO] Worker exiting (pid: 15303)
[2020-08-18 12:20:55 +0000] [15304] [ERROR] Exception in worker process
Traceback (most recent call last):
  File "/home/piekuser/venv/lib/python3.7/site-packages/gunicorn/arbiter.py", line 583, in spawn_worker
    worker.init_process()
  File "/home/piekuser/venv/lib/python3.7/site-packages/gunicorn/workers/base.py", line 119, in init_process
    self.load_wsgi()
  File "/home/piekuser/venv/lib/python3.7/site-packages/gunicorn/workers/base.py", line 144, in load_wsgi
    self.wsgi = self.app.wsgi()
  File "/home/piekuser/venv/lib/python3.7/site-packages/gunicorn/app/base.py", line 67, in wsgi
    self.callable = self.load()
  File "/home/piekuser/venv/lib/python3.7/site-packages/gunicorn/app/wsgiapp.py", line 49, in load
    return self.load_wsgiapp()
  File "/home/piekuser/venv/lib/python3.7/site-packages/gunicorn/app/wsgiapp.py", line 39, in load_wsgiapp
    return util.import_app(self.app_uri)
  File "/home/piekuser/venv/lib/python3.7/site-packages/gunicorn/util.py", line 358, in import_app
    mod = importlib.import_module(module)
  File "/usr/lib/python3.7/importlib/__init__.py", line 127, in import_module
    return _bootstrap._gcd_import(name[level:], package, level)
  File "<frozen importlib._bootstrap>", line 1006, in _gcd_import
  File "<frozen importlib._bootstrap>", line 983, in _find_and_load
  File "<frozen importlib._bootstrap>", line 967, in _find_and_load_unlocked
  File "<frozen importlib._bootstrap>", line 677, in _load_unlocked
  File "<frozen importlib._bootstrap_external>", line 728, in exec_module
  File "<frozen importlib._bootstrap>", line 219, in _call_with_frames_removed
  File "/home/piekuser/piek/jrl/wsgi.py", line 16, in <module>
    application = get_wsgi_application()
  File "/home/piekuser/venv/lib/python3.7/site-packages/django/core/wsgi.py", line 12, in get_wsgi_application
    django.setup(set_prefix=False)
  File "/home/piekuser/venv/lib/python3.7/site-packages/django/__init__.py", line 24, in setup
    apps.populate(settings.INSTALLED_APPS)
  File "/home/piekuser/venv/lib/python3.7/site-packages/django/apps/registry.py", line 114, in populate
    app_config.import_models()
  File "/home/piekuser/venv/lib/python3.7/site-packages/django/apps/config.py", line 211, in import_models
    self.models_module = import_module(models_module_name)
  File "/usr/lib/python3.7/importlib/__init__.py", line 127, in import_module
    return _bootstrap._gcd_import(name[level:], package, level)
  File "<frozen importlib._bootstrap>", line 1006, in _gcd_import
  File "<frozen importlib._bootstrap>", line 983, in _find_and_load
  File "<frozen importlib._bootstrap>", line 967, in _find_and_load_unlocked
  File "<frozen importlib._bootstrap>", line 677, in _load_unlocked
  File "<frozen importlib._bootstrap_external>", line 728, in exec_module
  File "<frozen importlib._bootstrap>", line 219, in _call_with_frames_removed
  File "/home/piekuser/piek/mainapp/models.py", line 3, in <module>
    from tinymce import HTMLField
ImportError: cannot import name 'HTMLField' from 'tinymce' (/home/piekuser/venv/lib/python3.7/site-packages/tinymce/__init__.py)
[2020-08-18 12:20:55 +0000] [15304] [INFO] Worker exiting (pid: 15304)
[2020-08-18 15:20:55 +0300] [15300] [INFO] Shutting down: Master
[2020-08-18 15:20:55 +0300] [15300] [INFO] Reason: Worker failed to boot.
[2020-08-18 15:20:57 +0300] [15305] [INFO] Starting gunicorn 20.0.4
[2020-08-18 15:20:57 +0300] [15305] [INFO] Listening at: http://127.0.0.1:8000 (15305)
[2020-08-18 15:20:57 +0300] [15305] [INFO] Using worker: sync
[2020-08-18 15:20:57 +0300] [15308] [INFO] Booting worker with pid: 15308
[2020-08-18 15:20:57 +0300] [15309] [INFO] Booting worker with pid: 15309
[2020-08-18 12:20:57 +0000] [15308] [ERROR] Exception in worker process
Traceback (most recent call last):
  File "/home/piekuser/venv/lib/python3.7/site-packages/gunicorn/arbiter.py", line 583, in spawn_worker
    worker.init_process()
  File "/home/piekuser/venv/lib/python3.7/site-packages/gunicorn/workers/base.py", line 119, in init_process
    self.load_wsgi()
  File "/home/piekuser/venv/lib/python3.7/site-packages/gunicorn/workers/base.py", line 144, in load_wsgi
    self.wsgi = self.app.wsgi()
  File "/home/piekuser/venv/lib/python3.7/site-packages/gunicorn/app/base.py", line 67, in wsgi
    self.callable = self.load()
  File "/home/piekuser/venv/lib/python3.7/site-packages/gunicorn/app/wsgiapp.py", line 49, in load
    return self.load_wsgiapp()
  File "/home/piekuser/venv/lib/python3.7/site-packages/gunicorn/app/wsgiapp.py", line 39, in load_wsgiapp
    return util.import_app(self.app_uri)
  File "/home/piekuser/venv/lib/python3.7/site-packages/gunicorn/util.py", line 358, in import_app
    mod = importlib.import_module(module)
  File "/usr/lib/python3.7/importlib/__init__.py", line 127, in import_module
    return _bootstrap._gcd_import(name[level:], package, level)
  File "<frozen importlib._bootstrap>", line 1006, in _gcd_import
  File "<frozen importlib._bootstrap>", line 983, in _find_and_load
  File "<frozen importlib._bootstrap>", line 967, in _find_and_load_unlocked
  File "<frozen importlib._bootstrap>", line 677, in _load_unlocked
  File "<frozen importlib._bootstrap_external>", line 728, in exec_module
  File "<frozen importlib._bootstrap>", line 219, in _call_with_frames_removed
  File "/home/piekuser/piek/jrl/wsgi.py", line 16, in <module>
    application = get_wsgi_application()
  File "/home/piekuser/venv/lib/python3.7/site-packages/django/core/wsgi.py", line 12, in get_wsgi_application
    django.setup(set_prefix=False)
  File "/home/piekuser/venv/lib/python3.7/site-packages/django/__init__.py", line 24, in setup
    apps.populate(settings.INSTALLED_APPS)
  File "/home/piekuser/venv/lib/python3.7/site-packages/django/apps/registry.py", line 114, in populate
    app_config.import_models()
  File "/home/piekuser/venv/lib/python3.7/site-packages/django/apps/config.py", line 211, in import_models
    self.models_module = import_module(models_module_name)
  File "/usr/lib/python3.7/importlib/__init__.py", line 127, in import_module
    return _bootstrap._gcd_import(name[level:], package, level)
  File "<frozen importlib._bootstrap>", line 1006, in _gcd_import
  File "<frozen importlib._bootstrap>", line 983, in _find_and_load
  File "<frozen importlib._bootstrap>", line 967, in _find_and_load_unlocked
  File "<frozen importlib._bootstrap>", line 677, in _load_unlocked
  File "<frozen importlib._bootstrap_external>", line 728, in exec_module
  File "<frozen importlib._bootstrap>", line 219, in _call_with_frames_removed
  File "/home/piekuser/piek/mainapp/models.py", line 3, in <module>
    from tinymce import HTMLField
ImportError: cannot import name 'HTMLField' from 'tinymce' (/home/piekuser/venv/lib/python3.7/site-packages/tinymce/__init__.py)
[2020-08-18 12:20:57 +0000] [15308] [INFO] Worker exiting (pid: 15308)
[2020-08-18 12:20:57 +0000] [15309] [ERROR] Exception in worker process
Traceback (most recent call last):
  File "/home/piekuser/venv/lib/python3.7/site-packages/gunicorn/arbiter.py", line 583, in spawn_worker
    worker.init_process()
  File "/home/piekuser/venv/lib/python3.7/site-packages/gunicorn/workers/base.py", line 119, in init_process
    self.load_wsgi()
  File "/home/piekuser/venv/lib/python3.7/site-packages/gunicorn/workers/base.py", line 144, in load_wsgi
    self.wsgi = self.app.wsgi()
  File "/home/piekuser/venv/lib/python3.7/site-packages/gunicorn/app/base.py", line 67, in wsgi
    self.callable = self.load()
  File "/home/piekuser/venv/lib/python3.7/site-packages/gunicorn/app/wsgiapp.py", line 49, in load
    return self.load_wsgiapp()
  File "/home/piekuser/venv/lib/python3.7/site-packages/gunicorn/app/wsgiapp.py", line 39, in load_wsgiapp
    return util.import_app(self.app_uri)
  File "/home/piekuser/venv/lib/python3.7/site-packages/gunicorn/util.py", line 358, in import_app
    mod = importlib.import_module(module)
  File "/usr/lib/python3.7/importlib/__init__.py", line 127, in import_module
    return _bootstrap._gcd_import(name[level:], package, level)
  File "<frozen importlib._bootstrap>", line 1006, in _gcd_import
  File "<frozen importlib._bootstrap>", line 983, in _find_and_load
  File "<frozen importlib._bootstrap>", line 967, in _find_and_load_unlocked
  File "<frozen importlib._bootstrap>", line 677, in _load_unlocked
  File "<frozen importlib._bootstrap_external>", line 728, in exec_module
  File "<frozen importlib._bootstrap>", line 219, in _call_with_frames_removed
  File "/home/piekuser/piek/jrl/wsgi.py", line 16, in <module>
    application = get_wsgi_application()
  File "/home/piekuser/venv/lib/python3.7/site-packages/django/core/wsgi.py", line 12, in get_wsgi_application
    django.setup(set_prefix=False)
  File "/home/piekuser/venv/lib/python3.7/site-packages/django/__init__.py", line 24, in setup
    apps.populate(settings.INSTALLED_APPS)
  File "/home/piekuser/venv/lib/python3.7/site-packages/django/apps/registry.py", line 114, in populate
    app_config.import_models()
  File "/home/piekuser/venv/lib/python3.7/site-packages/django/apps/config.py", line 211, in import_models
    self.models_module = import_module(models_module_name)
  File "/usr/lib/python3.7/importlib/__init__.py", line 127, in import_module
    return _bootstrap._gcd_import(name[level:], package, level)
  File "<frozen importlib._bootstrap>", line 1006, in _gcd_import
  File "<frozen importlib._bootstrap>", line 983, in _find_and_load
  File "<frozen importlib._bootstrap>", line 967, in _find_and_load_unlocked
  File "<frozen importlib._bootstrap>", line 677, in _load_unlocked
  File "<frozen importlib._bootstrap_external>", line 728, in exec_module
  File "<frozen importlib._bootstrap>", line 219, in _call_with_frames_removed
  File "/home/piekuser/piek/mainapp/models.py", line 3, in <module>
    from tinymce import HTMLField
ImportError: cannot import name 'HTMLField' from 'tinymce' (/home/piekuser/venv/lib/python3.7/site-packages/tinymce/__init__.py)
[2020-08-18 12:20:57 +0000] [15309] [INFO] Worker exiting (pid: 15309)
Traceback (most recent call last):
  File "/home/piekuser/venv/lib/python3.7/site-packages/gunicorn/arbiter.py", line 209, in run
    self.sleep()
  File "/home/piekuser/venv/lib/python3.7/site-packages/gunicorn/arbiter.py", line 357, in sleep
    ready = select.select([self.PIPE[0]], [], [], 1.0)
  File "/home/piekuser/venv/lib/python3.7/site-packages/gunicorn/arbiter.py", line 242, in handle_chld
    self.reap_workers()
  File "/home/piekuser/venv/lib/python3.7/site-packages/gunicorn/arbiter.py", line 525, in reap_workers
    raise HaltServer(reason, self.WORKER_BOOT_ERROR)
gunicorn.errors.HaltServer: <HaltServer 'Worker failed to boot.' 3>

During handling of the above exception, another exception occurred:

Traceback (most recent call last):
  File "/home/piekuser/venv/bin/gunicorn", line 10, in <module>
    sys.exit(run())
  File "/home/piekuser/venv/lib/python3.7/site-packages/gunicorn/app/wsgiapp.py", line 58, in run
    WSGIApplication("%(prog)s [OPTIONS] [APP_MODULE]").run()
  File "/home/piekuser/venv/lib/python3.7/site-packages/gunicorn/app/base.py", line 228, in run
    super().run()
  File "/home/piekuser/venv/lib/python3.7/site-packages/gunicorn/app/base.py", line 72, in run
    Arbiter(self).run()
  File "/home/piekuser/venv/lib/python3.7/site-packages/gunicorn/arbiter.py", line 229, in run
    self.halt(reason=inst.reason, exit_status=inst.exit_status)
  File "/home/piekuser/venv/lib/python3.7/site-packages/gunicorn/arbiter.py", line 342, in halt
    self.stop()
  File "/home/piekuser/venv/lib/python3.7/site-packages/gunicorn/arbiter.py", line 393, in stop
    time.sleep(0.1)
  File "/home/piekuser/venv/lib/python3.7/site-packages/gunicorn/arbiter.py", line 242, in handle_chld
    self.reap_workers()
  File "/home/piekuser/venv/lib/python3.7/site-packages/gunicorn/arbiter.py", line 525, in reap_workers
    raise HaltServer(reason, self.WORKER_BOOT_ERROR)
gunicorn.errors.HaltServer: <HaltServer 'Worker failed to boot.' 3>
[2020-08-18 15:21:01 +0300] [15310] [INFO] Starting gunicorn 20.0.4
[2020-08-18 15:21:01 +0300] [15310] [INFO] Listening at: http://127.0.0.1:8000 (15310)
[2020-08-18 15:21:01 +0300] [15310] [INFO] Using worker: sync
[2020-08-18 15:21:01 +0300] [15313] [INFO] Booting worker with pid: 15313
[2020-08-18 15:21:01 +0300] [15314] [INFO] Booting worker with pid: 15314
[2020-08-18 12:21:01 +0000] [15313] [ERROR] Exception in worker process
Traceback (most recent call last):
  File "/home/piekuser/venv/lib/python3.7/site-packages/gunicorn/arbiter.py", line 583, in spawn_worker
    worker.init_process()
  File "/home/piekuser/venv/lib/python3.7/site-packages/gunicorn/workers/base.py", line 119, in init_process
    self.load_wsgi()
  File "/home/piekuser/venv/lib/python3.7/site-packages/gunicorn/workers/base.py", line 144, in load_wsgi
    self.wsgi = self.app.wsgi()
  File "/home/piekuser/venv/lib/python3.7/site-packages/gunicorn/app/base.py", line 67, in wsgi
    self.callable = self.load()
  File "/home/piekuser/venv/lib/python3.7/site-packages/gunicorn/app/wsgiapp.py", line 49, in load
    return self.load_wsgiapp()
  File "/home/piekuser/venv/lib/python3.7/site-packages/gunicorn/app/wsgiapp.py", line 39, in load_wsgiapp
    return util.import_app(self.app_uri)
  File "/home/piekuser/venv/lib/python3.7/site-packages/gunicorn/util.py", line 358, in import_app
    mod = importlib.import_module(module)
  File "/usr/lib/python3.7/importlib/__init__.py", line 127, in import_module
    return _bootstrap._gcd_import(name[level:], package, level)
  File "<frozen importlib._bootstrap>", line 1006, in _gcd_import
  File "<frozen importlib._bootstrap>", line 983, in _find_and_load
  File "<frozen importlib._bootstrap>", line 967, in _find_and_load_unlocked
  File "<frozen importlib._bootstrap>", line 677, in _load_unlocked
  File "<frozen importlib._bootstrap_external>", line 728, in exec_module
  File "<frozen importlib._bootstrap>", line 219, in _call_with_frames_removed
  File "/home/piekuser/piek/jrl/wsgi.py", line 16, in <module>
    application = get_wsgi_application()
  File "/home/piekuser/venv/lib/python3.7/site-packages/django/core/wsgi.py", line 12, in get_wsgi_application
    django.setup(set_prefix=False)
  File "/home/piekuser/venv/lib/python3.7/site-packages/django/__init__.py", line 24, in setup
    apps.populate(settings.INSTALLED_APPS)
  File "/home/piekuser/venv/lib/python3.7/site-packages/django/apps/registry.py", line 114, in populate
    app_config.import_models()
  File "/home/piekuser/venv/lib/python3.7/site-packages/django/apps/config.py", line 211, in import_models
    self.models_module = import_module(models_module_name)
  File "/usr/lib/python3.7/importlib/__init__.py", line 127, in import_module
    return _bootstrap._gcd_import(name[level:], package, level)
  File "<frozen importlib._bootstrap>", line 1006, in _gcd_import
  File "<frozen importlib._bootstrap>", line 983, in _find_and_load
  File "<frozen importlib._bootstrap>", line 967, in _find_and_load_unlocked
  File "<frozen importlib._bootstrap>", line 677, in _load_unlocked
  File "<frozen importlib._bootstrap_external>", line 728, in exec_module
  File "<frozen importlib._bootstrap>", line 219, in _call_with_frames_removed
  File "/home/piekuser/piek/mainapp/models.py", line 3, in <module>
    from tinymce import HTMLField
ImportError: cannot import name 'HTMLField' from 'tinymce' (/home/piekuser/venv/lib/python3.7/site-packages/tinymce/__init__.py)
[2020-08-18 12:21:01 +0000] [15313] [INFO] Worker exiting (pid: 15313)
[2020-08-18 12:21:01 +0000] [15314] [ERROR] Exception in worker process
Traceback (most recent call last):
  File "/home/piekuser/venv/lib/python3.7/site-packages/gunicorn/arbiter.py", line 583, in spawn_worker
    worker.init_process()
  File "/home/piekuser/venv/lib/python3.7/site-packages/gunicorn/workers/base.py", line 119, in init_process
    self.load_wsgi()
  File "/home/piekuser/venv/lib/python3.7/site-packages/gunicorn/workers/base.py", line 144, in load_wsgi
    self.wsgi = self.app.wsgi()
  File "/home/piekuser/venv/lib/python3.7/site-packages/gunicorn/app/base.py", line 67, in wsgi
    self.callable = self.load()
  File "/home/piekuser/venv/lib/python3.7/site-packages/gunicorn/app/wsgiapp.py", line 49, in load
    return self.load_wsgiapp()
  File "/home/piekuser/venv/lib/python3.7/site-packages/gunicorn/app/wsgiapp.py", line 39, in load_wsgiapp
    return util.import_app(self.app_uri)
  File "/home/piekuser/venv/lib/python3.7/site-packages/gunicorn/util.py", line 358, in import_app
    mod = importlib.import_module(module)
  File "/usr/lib/python3.7/importlib/__init__.py", line 127, in import_module
    return _bootstrap._gcd_import(name[level:], package, level)
  File "<frozen importlib._bootstrap>", line 1006, in _gcd_import
  File "<frozen importlib._bootstrap>", line 983, in _find_and_load
  File "<frozen importlib._bootstrap>", line 967, in _find_and_load_unlocked
  File "<frozen importlib._bootstrap>", line 677, in _load_unlocked
  File "<frozen importlib._bootstrap_external>", line 728, in exec_module
  File "<frozen importlib._bootstrap>", line 219, in _call_with_frames_removed
  File "/home/piekuser/piek/jrl/wsgi.py", line 16, in <module>
    application = get_wsgi_application()
  File "/home/piekuser/venv/lib/python3.7/site-packages/django/core/wsgi.py", line 12, in get_wsgi_application
    django.setup(set_prefix=False)
  File "/home/piekuser/venv/lib/python3.7/site-packages/django/__init__.py", line 24, in setup
    apps.populate(settings.INSTALLED_APPS)
  File "/home/piekuser/venv/lib/python3.7/site-packages/django/apps/registry.py", line 114, in populate
    app_config.import_models()
  File "/home/piekuser/venv/lib/python3.7/site-packages/django/apps/config.py", line 211, in import_models
    self.models_module = import_module(models_module_name)
  File "/usr/lib/python3.7/importlib/__init__.py", line 127, in import_module
    return _bootstrap._gcd_import(name[level:], package, level)
  File "<frozen importlib._bootstrap>", line 1006, in _gcd_import
  File "<frozen importlib._bootstrap>", line 983, in _find_and_load
  File "<frozen importlib._bootstrap>", line 967, in _find_and_load_unlocked
  File "<frozen importlib._bootstrap>", line 677, in _load_unlocked
  File "<frozen importlib._bootstrap_external>", line 728, in exec_module
  File "<frozen importlib._bootstrap>", line 219, in _call_with_frames_removed
  File "/home/piekuser/piek/mainapp/models.py", line 3, in <module>
    from tinymce import HTMLField
ImportError: cannot import name 'HTMLField' from 'tinymce' (/home/piekuser/venv/lib/python3.7/site-packages/tinymce/__init__.py)
[2020-08-18 12:21:01 +0000] [15314] [INFO] Worker exiting (pid: 15314)
Traceback (most recent call last):
  File "/home/piekuser/venv/lib/python3.7/site-packages/gunicorn/arbiter.py", line 209, in run
    self.sleep()
  File "/home/piekuser/venv/lib/python3.7/site-packages/gunicorn/arbiter.py", line 357, in sleep
    ready = select.select([self.PIPE[0]], [], [], 1.0)
  File "/home/piekuser/venv/lib/python3.7/site-packages/gunicorn/arbiter.py", line 242, in handle_chld
    self.reap_workers()
  File "/home/piekuser/venv/lib/python3.7/site-packages/gunicorn/arbiter.py", line 525, in reap_workers
    raise HaltServer(reason, self.WORKER_BOOT_ERROR)
gunicorn.errors.HaltServer: <HaltServer 'Worker failed to boot.' 3>

During handling of the above exception, another exception occurred:

Traceback (most recent call last):
  File "/home/piekuser/venv/bin/gunicorn", line 10, in <module>
    sys.exit(run())
  File "/home/piekuser/venv/lib/python3.7/site-packages/gunicorn/app/wsgiapp.py", line 58, in run
    WSGIApplication("%(prog)s [OPTIONS] [APP_MODULE]").run()
  File "/home/piekuser/venv/lib/python3.7/site-packages/gunicorn/app/base.py", line 228, in run
    super().run()
  File "/home/piekuser/venv/lib/python3.7/site-packages/gunicorn/app/base.py", line 72, in run
    Arbiter(self).run()
  File "/home/piekuser/venv/lib/python3.7/site-packages/gunicorn/arbiter.py", line 229, in run
    self.halt(reason=inst.reason, exit_status=inst.exit_status)
  File "/home/piekuser/venv/lib/python3.7/site-packages/gunicorn/arbiter.py", line 342, in halt
    self.stop()
  File "/home/piekuser/venv/lib/python3.7/site-packages/gunicorn/arbiter.py", line 393, in stop
    time.sleep(0.1)
  File "/home/piekuser/venv/lib/python3.7/site-packages/gunicorn/arbiter.py", line 242, in handle_chld
    self.reap_workers()
  File "/home/piekuser/venv/lib/python3.7/site-packages/gunicorn/arbiter.py", line 525, in reap_workers
    raise HaltServer(reason, self.WORKER_BOOT_ERROR)
gunicorn.errors.HaltServer: <HaltServer 'Worker failed to boot.' 3>
[2020-08-18 15:22:43 +0300] [15397] [INFO] Starting gunicorn 20.0.4
[2020-08-18 15:22:43 +0300] [15397] [INFO] Listening at: http://127.0.0.1:8000 (15397)
[2020-08-18 15:22:43 +0300] [15397] [INFO] Using worker: sync
[2020-08-18 15:22:43 +0300] [15400] [INFO] Booting worker with pid: 15400
[2020-08-18 15:22:43 +0300] [15401] [INFO] Booting worker with pid: 15401
[2020-08-18 12:22:43 +0000] [15400] [ERROR] Exception in worker process
Traceback (most recent call last):
  File "/home/piekuser/venv/lib/python3.7/site-packages/gunicorn/arbiter.py", line 583, in spawn_worker
    worker.init_process()
  File "/home/piekuser/venv/lib/python3.7/site-packages/gunicorn/workers/base.py", line 119, in init_process
    self.load_wsgi()
  File "/home/piekuser/venv/lib/python3.7/site-packages/gunicorn/workers/base.py", line 144, in load_wsgi
    self.wsgi = self.app.wsgi()
  File "/home/piekuser/venv/lib/python3.7/site-packages/gunicorn/app/base.py", line 67, in wsgi
    self.callable = self.load()
  File "/home/piekuser/venv/lib/python3.7/site-packages/gunicorn/app/wsgiapp.py", line 49, in load
    return self.load_wsgiapp()
  File "/home/piekuser/venv/lib/python3.7/site-packages/gunicorn/app/wsgiapp.py", line 39, in load_wsgiapp
    return util.import_app(self.app_uri)
  File "/home/piekuser/venv/lib/python3.7/site-packages/gunicorn/util.py", line 358, in import_app
    mod = importlib.import_module(module)
  File "/usr/lib/python3.7/importlib/__init__.py", line 127, in import_module
    return _bootstrap._gcd_import(name[level:], package, level)
  File "<frozen importlib._bootstrap>", line 1006, in _gcd_import
  File "<frozen importlib._bootstrap>", line 983, in _find_and_load
  File "<frozen importlib._bootstrap>", line 967, in _find_and_load_unlocked
  File "<frozen importlib._bootstrap>", line 677, in _load_unlocked
  File "<frozen importlib._bootstrap_external>", line 728, in exec_module
  File "<frozen importlib._bootstrap>", line 219, in _call_with_frames_removed
  File "/home/piekuser/piek/jrl/wsgi.py", line 16, in <module>
    application = get_wsgi_application()
  File "/home/piekuser/venv/lib/python3.7/site-packages/django/core/wsgi.py", line 12, in get_wsgi_application
    django.setup(set_prefix=False)
  File "/home/piekuser/venv/lib/python3.7/site-packages/django/__init__.py", line 24, in setup
    apps.populate(settings.INSTALLED_APPS)
  File "/home/piekuser/venv/lib/python3.7/site-packages/django/apps/registry.py", line 114, in populate
    app_config.import_models()
  File "/home/piekuser/venv/lib/python3.7/site-packages/django/apps/config.py", line 211, in import_models
    self.models_module = import_module(models_module_name)
  File "/usr/lib/python3.7/importlib/__init__.py", line 127, in import_module
    return _bootstrap._gcd_import(name[level:], package, level)
  File "<frozen importlib._bootstrap>", line 1006, in _gcd_import
  File "<frozen importlib._bootstrap>", line 983, in _find_and_load
  File "<frozen importlib._bootstrap>", line 967, in _find_and_load_unlocked
  File "<frozen importlib._bootstrap>", line 677, in _load_unlocked
  File "<frozen importlib._bootstrap_external>", line 728, in exec_module
  File "<frozen importlib._bootstrap>", line 219, in _call_with_frames_removed
  File "/home/piekuser/piek/mainapp/models.py", line 3, in <module>
    from tinymce import HTMLField
ImportError: cannot import name 'HTMLField' from 'tinymce' (/home/piekuser/venv/lib/python3.7/site-packages/tinymce/__init__.py)
[2020-08-18 12:22:43 +0000] [15400] [INFO] Worker exiting (pid: 15400)
[2020-08-18 12:22:43 +0000] [15401] [ERROR] Exception in worker process
Traceback (most recent call last):
  File "/home/piekuser/venv/lib/python3.7/site-packages/gunicorn/arbiter.py", line 583, in spawn_worker
    worker.init_process()
  File "/home/piekuser/venv/lib/python3.7/site-packages/gunicorn/workers/base.py", line 119, in init_process
    self.load_wsgi()
  File "/home/piekuser/venv/lib/python3.7/site-packages/gunicorn/workers/base.py", line 144, in load_wsgi
    self.wsgi = self.app.wsgi()
  File "/home/piekuser/venv/lib/python3.7/site-packages/gunicorn/app/base.py", line 67, in wsgi
    self.callable = self.load()
  File "/home/piekuser/venv/lib/python3.7/site-packages/gunicorn/app/wsgiapp.py", line 49, in load
    return self.load_wsgiapp()
  File "/home/piekuser/venv/lib/python3.7/site-packages/gunicorn/app/wsgiapp.py", line 39, in load_wsgiapp
    return util.import_app(self.app_uri)
  File "/home/piekuser/venv/lib/python3.7/site-packages/gunicorn/util.py", line 358, in import_app
    mod = importlib.import_module(module)
  File "/usr/lib/python3.7/importlib/__init__.py", line 127, in import_module
    return _bootstrap._gcd_import(name[level:], package, level)
  File "<frozen importlib._bootstrap>", line 1006, in _gcd_import
  File "<frozen importlib._bootstrap>", line 983, in _find_and_load
  File "<frozen importlib._bootstrap>", line 967, in _find_and_load_unlocked
  File "<frozen importlib._bootstrap>", line 677, in _load_unlocked
  File "<frozen importlib._bootstrap_external>", line 728, in exec_module
  File "<frozen importlib._bootstrap>", line 219, in _call_with_frames_removed
  File "/home/piekuser/piek/jrl/wsgi.py", line 16, in <module>
    application = get_wsgi_application()
  File "/home/piekuser/venv/lib/python3.7/site-packages/django/core/wsgi.py", line 12, in get_wsgi_application
    django.setup(set_prefix=False)
  File "/home/piekuser/venv/lib/python3.7/site-packages/django/__init__.py", line 24, in setup
    apps.populate(settings.INSTALLED_APPS)
  File "/home/piekuser/venv/lib/python3.7/site-packages/django/apps/registry.py", line 114, in populate
    app_config.import_models()
  File "/home/piekuser/venv/lib/python3.7/site-packages/django/apps/config.py", line 211, in import_models
    self.models_module = import_module(models_module_name)
  File "/usr/lib/python3.7/importlib/__init__.py", line 127, in import_module
    return _bootstrap._gcd_import(name[level:], package, level)
  File "<frozen importlib._bootstrap>", line 1006, in _gcd_import
  File "<frozen importlib._bootstrap>", line 983, in _find_and_load
  File "<frozen importlib._bootstrap>", line 967, in _find_and_load_unlocked
  File "<frozen importlib._bootstrap>", line 677, in _load_unlocked
  File "<frozen importlib._bootstrap_external>", line 728, in exec_module
  File "<frozen importlib._bootstrap>", line 219, in _call_with_frames_removed
  File "/home/piekuser/piek/mainapp/models.py", line 3, in <module>
    from tinymce import HTMLField
ImportError: cannot import name 'HTMLField' from 'tinymce' (/home/piekuser/venv/lib/python3.7/site-packages/tinymce/__init__.py)
[2020-08-18 12:22:43 +0000] [15401] [INFO] Worker exiting (pid: 15401)
[2020-08-18 15:22:44 +0300] [15397] [INFO] Shutting down: Master
[2020-08-18 15:22:44 +0300] [15397] [INFO] Reason: Worker failed to boot.
[2020-08-18 15:22:45 +0300] [15402] [INFO] Starting gunicorn 20.0.4
[2020-08-18 15:22:45 +0300] [15402] [INFO] Listening at: http://127.0.0.1:8000 (15402)
[2020-08-18 15:22:45 +0300] [15402] [INFO] Using worker: sync
[2020-08-18 15:22:45 +0300] [15405] [INFO] Booting worker with pid: 15405
[2020-08-18 15:22:45 +0300] [15406] [INFO] Booting worker with pid: 15406
[2020-08-18 12:22:45 +0000] [15405] [ERROR] Exception in worker process
Traceback (most recent call last):
  File "/home/piekuser/venv/lib/python3.7/site-packages/gunicorn/arbiter.py", line 583, in spawn_worker
    worker.init_process()
  File "/home/piekuser/venv/lib/python3.7/site-packages/gunicorn/workers/base.py", line 119, in init_process
    self.load_wsgi()
  File "/home/piekuser/venv/lib/python3.7/site-packages/gunicorn/workers/base.py", line 144, in load_wsgi
    self.wsgi = self.app.wsgi()
  File "/home/piekuser/venv/lib/python3.7/site-packages/gunicorn/app/base.py", line 67, in wsgi
    self.callable = self.load()
  File "/home/piekuser/venv/lib/python3.7/site-packages/gunicorn/app/wsgiapp.py", line 49, in load
    return self.load_wsgiapp()
  File "/home/piekuser/venv/lib/python3.7/site-packages/gunicorn/app/wsgiapp.py", line 39, in load_wsgiapp
    return util.import_app(self.app_uri)
  File "/home/piekuser/venv/lib/python3.7/site-packages/gunicorn/util.py", line 358, in import_app
    mod = importlib.import_module(module)
  File "/usr/lib/python3.7/importlib/__init__.py", line 127, in import_module
    return _bootstrap._gcd_import(name[level:], package, level)
  File "<frozen importlib._bootstrap>", line 1006, in _gcd_import
  File "<frozen importlib._bootstrap>", line 983, in _find_and_load
  File "<frozen importlib._bootstrap>", line 967, in _find_and_load_unlocked
  File "<frozen importlib._bootstrap>", line 677, in _load_unlocked
  File "<frozen importlib._bootstrap_external>", line 728, in exec_module
  File "<frozen importlib._bootstrap>", line 219, in _call_with_frames_removed
  File "/home/piekuser/piek/jrl/wsgi.py", line 16, in <module>
    application = get_wsgi_application()
  File "/home/piekuser/venv/lib/python3.7/site-packages/django/core/wsgi.py", line 12, in get_wsgi_application
    django.setup(set_prefix=False)
  File "/home/piekuser/venv/lib/python3.7/site-packages/django/__init__.py", line 24, in setup
    apps.populate(settings.INSTALLED_APPS)
  File "/home/piekuser/venv/lib/python3.7/site-packages/django/apps/registry.py", line 114, in populate
    app_config.import_models()
  File "/home/piekuser/venv/lib/python3.7/site-packages/django/apps/config.py", line 211, in import_models
    self.models_module = import_module(models_module_name)
  File "/usr/lib/python3.7/importlib/__init__.py", line 127, in import_module
    return _bootstrap._gcd_import(name[level:], package, level)
  File "<frozen importlib._bootstrap>", line 1006, in _gcd_import
  File "<frozen importlib._bootstrap>", line 983, in _find_and_load
  File "<frozen importlib._bootstrap>", line 967, in _find_and_load_unlocked
  File "<frozen importlib._bootstrap>", line 677, in _load_unlocked
  File "<frozen importlib._bootstrap_external>", line 728, in exec_module
  File "<frozen importlib._bootstrap>", line 219, in _call_with_frames_removed
  File "/home/piekuser/piek/mainapp/models.py", line 3, in <module>
    from tinymce import HTMLField
ImportError: cannot import name 'HTMLField' from 'tinymce' (/home/piekuser/venv/lib/python3.7/site-packages/tinymce/__init__.py)
[2020-08-18 12:22:45 +0000] [15405] [INFO] Worker exiting (pid: 15405)
[2020-08-18 12:22:45 +0000] [15406] [ERROR] Exception in worker process
Traceback (most recent call last):
  File "/home/piekuser/venv/lib/python3.7/site-packages/gunicorn/arbiter.py", line 583, in spawn_worker
    worker.init_process()
  File "/home/piekuser/venv/lib/python3.7/site-packages/gunicorn/workers/base.py", line 119, in init_process
    self.load_wsgi()
  File "/home/piekuser/venv/lib/python3.7/site-packages/gunicorn/workers/base.py", line 144, in load_wsgi
    self.wsgi = self.app.wsgi()
  File "/home/piekuser/venv/lib/python3.7/site-packages/gunicorn/app/base.py", line 67, in wsgi
    self.callable = self.load()
  File "/home/piekuser/venv/lib/python3.7/site-packages/gunicorn/app/wsgiapp.py", line 49, in load
    return self.load_wsgiapp()
  File "/home/piekuser/venv/lib/python3.7/site-packages/gunicorn/app/wsgiapp.py", line 39, in load_wsgiapp
    return util.import_app(self.app_uri)
  File "/home/piekuser/venv/lib/python3.7/site-packages/gunicorn/util.py", line 358, in import_app
    mod = importlib.import_module(module)
  File "/usr/lib/python3.7/importlib/__init__.py", line 127, in import_module
    return _bootstrap._gcd_import(name[level:], package, level)
  File "<frozen importlib._bootstrap>", line 1006, in _gcd_import
  File "<frozen importlib._bootstrap>", line 983, in _find_and_load
  File "<frozen importlib._bootstrap>", line 967, in _find_and_load_unlocked
  File "<frozen importlib._bootstrap>", line 677, in _load_unlocked
  File "<frozen importlib._bootstrap_external>", line 728, in exec_module
  File "<frozen importlib._bootstrap>", line 219, in _call_with_frames_removed
  File "/home/piekuser/piek/jrl/wsgi.py", line 16, in <module>
    application = get_wsgi_application()
  File "/home/piekuser/venv/lib/python3.7/site-packages/django/core/wsgi.py", line 12, in get_wsgi_application
    django.setup(set_prefix=False)
  File "/home/piekuser/venv/lib/python3.7/site-packages/django/__init__.py", line 24, in setup
    apps.populate(settings.INSTALLED_APPS)
  File "/home/piekuser/venv/lib/python3.7/site-packages/django/apps/registry.py", line 114, in populate
    app_config.import_models()
  File "/home/piekuser/venv/lib/python3.7/site-packages/django/apps/config.py", line 211, in import_models
    self.models_module = import_module(models_module_name)
  File "/usr/lib/python3.7/importlib/__init__.py", line 127, in import_module
    return _bootstrap._gcd_import(name[level:], package, level)
  File "<frozen importlib._bootstrap>", line 1006, in _gcd_import
  File "<frozen importlib._bootstrap>", line 983, in _find_and_load
  File "<frozen importlib._bootstrap>", line 967, in _find_and_load_unlocked
  File "<frozen importlib._bootstrap>", line 677, in _load_unlocked
  File "<frozen importlib._bootstrap_external>", line 728, in exec_module
  File "<frozen importlib._bootstrap>", line 219, in _call_with_frames_removed
  File "/home/piekuser/piek/mainapp/models.py", line 3, in <module>
    from tinymce import HTMLField
ImportError: cannot import name 'HTMLField' from 'tinymce' (/home/piekuser/venv/lib/python3.7/site-packages/tinymce/__init__.py)
[2020-08-18 12:22:45 +0000] [15406] [INFO] Worker exiting (pid: 15406)
[2020-08-18 15:22:45 +0300] [15402] [INFO] Shutting down: Master
[2020-08-18 15:22:45 +0300] [15402] [INFO] Reason: Worker failed to boot.
[2020-08-18 15:22:48 +0300] [15407] [INFO] Starting gunicorn 20.0.4
[2020-08-18 15:22:48 +0300] [15407] [INFO] Listening at: http://127.0.0.1:8000 (15407)
[2020-08-18 15:22:48 +0300] [15407] [INFO] Using worker: sync
[2020-08-18 15:22:48 +0300] [15410] [INFO] Booting worker with pid: 15410
[2020-08-18 15:22:48 +0300] [15411] [INFO] Booting worker with pid: 15411
[2020-08-18 12:22:48 +0000] [15410] [ERROR] Exception in worker process
Traceback (most recent call last):
  File "/home/piekuser/venv/lib/python3.7/site-packages/gunicorn/arbiter.py", line 583, in spawn_worker
    worker.init_process()
  File "/home/piekuser/venv/lib/python3.7/site-packages/gunicorn/workers/base.py", line 119, in init_process
    self.load_wsgi()
  File "/home/piekuser/venv/lib/python3.7/site-packages/gunicorn/workers/base.py", line 144, in load_wsgi
    self.wsgi = self.app.wsgi()
  File "/home/piekuser/venv/lib/python3.7/site-packages/gunicorn/app/base.py", line 67, in wsgi
    self.callable = self.load()
  File "/home/piekuser/venv/lib/python3.7/site-packages/gunicorn/app/wsgiapp.py", line 49, in load
    return self.load_wsgiapp()
  File "/home/piekuser/venv/lib/python3.7/site-packages/gunicorn/app/wsgiapp.py", line 39, in load_wsgiapp
    return util.import_app(self.app_uri)
  File "/home/piekuser/venv/lib/python3.7/site-packages/gunicorn/util.py", line 358, in import_app
    mod = importlib.import_module(module)
  File "/usr/lib/python3.7/importlib/__init__.py", line 127, in import_module
    return _bootstrap._gcd_import(name[level:], package, level)
  File "<frozen importlib._bootstrap>", line 1006, in _gcd_import
  File "<frozen importlib._bootstrap>", line 983, in _find_and_load
  File "<frozen importlib._bootstrap>", line 967, in _find_and_load_unlocked
  File "<frozen importlib._bootstrap>", line 677, in _load_unlocked
  File "<frozen importlib._bootstrap_external>", line 728, in exec_module
  File "<frozen importlib._bootstrap>", line 219, in _call_with_frames_removed
  File "/home/piekuser/piek/jrl/wsgi.py", line 16, in <module>
    application = get_wsgi_application()
  File "/home/piekuser/venv/lib/python3.7/site-packages/django/core/wsgi.py", line 12, in get_wsgi_application
    django.setup(set_prefix=False)
  File "/home/piekuser/venv/lib/python3.7/site-packages/django/__init__.py", line 24, in setup
    apps.populate(settings.INSTALLED_APPS)
  File "/home/piekuser/venv/lib/python3.7/site-packages/django/apps/registry.py", line 114, in populate
    app_config.import_models()
  File "/home/piekuser/venv/lib/python3.7/site-packages/django/apps/config.py", line 211, in import_models
    self.models_module = import_module(models_module_name)
  File "/usr/lib/python3.7/importlib/__init__.py", line 127, in import_module
    return _bootstrap._gcd_import(name[level:], package, level)
  File "<frozen importlib._bootstrap>", line 1006, in _gcd_import
  File "<frozen importlib._bootstrap>", line 983, in _find_and_load
  File "<frozen importlib._bootstrap>", line 967, in _find_and_load_unlocked
  File "<frozen importlib._bootstrap>", line 677, in _load_unlocked
  File "<frozen importlib._bootstrap_external>", line 728, in exec_module
  File "<frozen importlib._bootstrap>", line 219, in _call_with_frames_removed
  File "/home/piekuser/piek/mainapp/models.py", line 3, in <module>
    from tinymce import HTMLField
ImportError: cannot import name 'HTMLField' from 'tinymce' (/home/piekuser/venv/lib/python3.7/site-packages/tinymce/__init__.py)
[2020-08-18 12:22:48 +0000] [15410] [INFO] Worker exiting (pid: 15410)
[2020-08-18 12:22:48 +0000] [15411] [ERROR] Exception in worker process
Traceback (most recent call last):
  File "/home/piekuser/venv/lib/python3.7/site-packages/gunicorn/arbiter.py", line 583, in spawn_worker
    worker.init_process()
  File "/home/piekuser/venv/lib/python3.7/site-packages/gunicorn/workers/base.py", line 119, in init_process
    self.load_wsgi()
  File "/home/piekuser/venv/lib/python3.7/site-packages/gunicorn/workers/base.py", line 144, in load_wsgi
    self.wsgi = self.app.wsgi()
  File "/home/piekuser/venv/lib/python3.7/site-packages/gunicorn/app/base.py", line 67, in wsgi
    self.callable = self.load()
  File "/home/piekuser/venv/lib/python3.7/site-packages/gunicorn/app/wsgiapp.py", line 49, in load
    return self.load_wsgiapp()
  File "/home/piekuser/venv/lib/python3.7/site-packages/gunicorn/app/wsgiapp.py", line 39, in load_wsgiapp
    return util.import_app(self.app_uri)
  File "/home/piekuser/venv/lib/python3.7/site-packages/gunicorn/util.py", line 358, in import_app
    mod = importlib.import_module(module)
  File "/usr/lib/python3.7/importlib/__init__.py", line 127, in import_module
    return _bootstrap._gcd_import(name[level:], package, level)
  File "<frozen importlib._bootstrap>", line 1006, in _gcd_import
  File "<frozen importlib._bootstrap>", line 983, in _find_and_load
  File "<frozen importlib._bootstrap>", line 967, in _find_and_load_unlocked
  File "<frozen importlib._bootstrap>", line 677, in _load_unlocked
  File "<frozen importlib._bootstrap_external>", line 728, in exec_module
  File "<frozen importlib._bootstrap>", line 219, in _call_with_frames_removed
  File "/home/piekuser/piek/jrl/wsgi.py", line 16, in <module>
    application = get_wsgi_application()
  File "/home/piekuser/venv/lib/python3.7/site-packages/django/core/wsgi.py", line 12, in get_wsgi_application
    django.setup(set_prefix=False)
  File "/home/piekuser/venv/lib/python3.7/site-packages/django/__init__.py", line 24, in setup
    apps.populate(settings.INSTALLED_APPS)
  File "/home/piekuser/venv/lib/python3.7/site-packages/django/apps/registry.py", line 114, in populate
    app_config.import_models()
  File "/home/piekuser/venv/lib/python3.7/site-packages/django/apps/config.py", line 211, in import_models
    self.models_module = import_module(models_module_name)
  File "/usr/lib/python3.7/importlib/__init__.py", line 127, in import_module
    return _bootstrap._gcd_import(name[level:], package, level)
  File "<frozen importlib._bootstrap>", line 1006, in _gcd_import
  File "<frozen importlib._bootstrap>", line 983, in _find_and_load
  File "<frozen importlib._bootstrap>", line 967, in _find_and_load_unlocked
  File "<frozen importlib._bootstrap>", line 677, in _load_unlocked
  File "<frozen importlib._bootstrap_external>", line 728, in exec_module
  File "<frozen importlib._bootstrap>", line 219, in _call_with_frames_removed
  File "/home/piekuser/piek/mainapp/models.py", line 3, in <module>
    from tinymce import HTMLField
ImportError: cannot import name 'HTMLField' from 'tinymce' (/home/piekuser/venv/lib/python3.7/site-packages/tinymce/__init__.py)
[2020-08-18 12:22:48 +0000] [15411] [INFO] Worker exiting (pid: 15411)
Traceback (most recent call last):
  File "/home/piekuser/venv/lib/python3.7/site-packages/gunicorn/arbiter.py", line 209, in run
    self.sleep()
  File "/home/piekuser/venv/lib/python3.7/site-packages/gunicorn/arbiter.py", line 357, in sleep
    ready = select.select([self.PIPE[0]], [], [], 1.0)
  File "/home/piekuser/venv/lib/python3.7/site-packages/gunicorn/arbiter.py", line 242, in handle_chld
    self.reap_workers()
  File "/home/piekuser/venv/lib/python3.7/site-packages/gunicorn/arbiter.py", line 525, in reap_workers
    raise HaltServer(reason, self.WORKER_BOOT_ERROR)
gunicorn.errors.HaltServer: <HaltServer 'Worker failed to boot.' 3>

During handling of the above exception, another exception occurred:

Traceback (most recent call last):
  File "/home/piekuser/venv/bin/gunicorn", line 10, in <module>
    sys.exit(run())
  File "/home/piekuser/venv/lib/python3.7/site-packages/gunicorn/app/wsgiapp.py", line 58, in run
    WSGIApplication("%(prog)s [OPTIONS] [APP_MODULE]").run()
  File "/home/piekuser/venv/lib/python3.7/site-packages/gunicorn/app/base.py", line 228, in run
    super().run()
  File "/home/piekuser/venv/lib/python3.7/site-packages/gunicorn/app/base.py", line 72, in run
    Arbiter(self).run()
  File "/home/piekuser/venv/lib/python3.7/site-packages/gunicorn/arbiter.py", line 229, in run
    self.halt(reason=inst.reason, exit_status=inst.exit_status)
  File "/home/piekuser/venv/lib/python3.7/site-packages/gunicorn/arbiter.py", line 342, in halt
    self.stop()
  File "/home/piekuser/venv/lib/python3.7/site-packages/gunicorn/arbiter.py", line 393, in stop
    time.sleep(0.1)
  File "/home/piekuser/venv/lib/python3.7/site-packages/gunicorn/arbiter.py", line 242, in handle_chld
    self.reap_workers()
  File "/home/piekuser/venv/lib/python3.7/site-packages/gunicorn/arbiter.py", line 525, in reap_workers
    raise HaltServer(reason, self.WORKER_BOOT_ERROR)
gunicorn.errors.HaltServer: <HaltServer 'Worker failed to boot.' 3>
[2020-08-18 15:22:51 +0300] [15413] [INFO] Starting gunicorn 20.0.4
[2020-08-18 15:22:51 +0300] [15413] [INFO] Listening at: http://127.0.0.1:8000 (15413)
[2020-08-18 15:22:51 +0300] [15413] [INFO] Using worker: sync
[2020-08-18 15:22:51 +0300] [15416] [INFO] Booting worker with pid: 15416
[2020-08-18 15:22:51 +0300] [15417] [INFO] Booting worker with pid: 15417
[2020-08-18 12:22:52 +0000] [15416] [ERROR] Exception in worker process
Traceback (most recent call last):
  File "/home/piekuser/venv/lib/python3.7/site-packages/gunicorn/arbiter.py", line 583, in spawn_worker
    worker.init_process()
  File "/home/piekuser/venv/lib/python3.7/site-packages/gunicorn/workers/base.py", line 119, in init_process
    self.load_wsgi()
  File "/home/piekuser/venv/lib/python3.7/site-packages/gunicorn/workers/base.py", line 144, in load_wsgi
    self.wsgi = self.app.wsgi()
  File "/home/piekuser/venv/lib/python3.7/site-packages/gunicorn/app/base.py", line 67, in wsgi
    self.callable = self.load()
  File "/home/piekuser/venv/lib/python3.7/site-packages/gunicorn/app/wsgiapp.py", line 49, in load
    return self.load_wsgiapp()
  File "/home/piekuser/venv/lib/python3.7/site-packages/gunicorn/app/wsgiapp.py", line 39, in load_wsgiapp
    return util.import_app(self.app_uri)
  File "/home/piekuser/venv/lib/python3.7/site-packages/gunicorn/util.py", line 358, in import_app
    mod = importlib.import_module(module)
  File "/usr/lib/python3.7/importlib/__init__.py", line 127, in import_module
    return _bootstrap._gcd_import(name[level:], package, level)
  File "<frozen importlib._bootstrap>", line 1006, in _gcd_import
  File "<frozen importlib._bootstrap>", line 983, in _find_and_load
  File "<frozen importlib._bootstrap>", line 967, in _find_and_load_unlocked
  File "<frozen importlib._bootstrap>", line 677, in _load_unlocked
  File "<frozen importlib._bootstrap_external>", line 728, in exec_module
  File "<frozen importlib._bootstrap>", line 219, in _call_with_frames_removed
  File "/home/piekuser/piek/jrl/wsgi.py", line 16, in <module>
    application = get_wsgi_application()
  File "/home/piekuser/venv/lib/python3.7/site-packages/django/core/wsgi.py", line 12, in get_wsgi_application
    django.setup(set_prefix=False)
  File "/home/piekuser/venv/lib/python3.7/site-packages/django/__init__.py", line 24, in setup
    apps.populate(settings.INSTALLED_APPS)
  File "/home/piekuser/venv/lib/python3.7/site-packages/django/apps/registry.py", line 114, in populate
    app_config.import_models()
  File "/home/piekuser/venv/lib/python3.7/site-packages/django/apps/config.py", line 211, in import_models
    self.models_module = import_module(models_module_name)
  File "/usr/lib/python3.7/importlib/__init__.py", line 127, in import_module
    return _bootstrap._gcd_import(name[level:], package, level)
  File "<frozen importlib._bootstrap>", line 1006, in _gcd_import
  File "<frozen importlib._bootstrap>", line 983, in _find_and_load
  File "<frozen importlib._bootstrap>", line 967, in _find_and_load_unlocked
  File "<frozen importlib._bootstrap>", line 677, in _load_unlocked
  File "<frozen importlib._bootstrap_external>", line 728, in exec_module
  File "<frozen importlib._bootstrap>", line 219, in _call_with_frames_removed
  File "/home/piekuser/piek/mainapp/models.py", line 3, in <module>
    from tinymce import HTMLField
ImportError: cannot import name 'HTMLField' from 'tinymce' (/home/piekuser/venv/lib/python3.7/site-packages/tinymce/__init__.py)
[2020-08-18 12:22:52 +0000] [15416] [INFO] Worker exiting (pid: 15416)
[2020-08-18 12:22:52 +0000] [15417] [ERROR] Exception in worker process
Traceback (most recent call last):
  File "/home/piekuser/venv/lib/python3.7/site-packages/gunicorn/arbiter.py", line 583, in spawn_worker
    worker.init_process()
  File "/home/piekuser/venv/lib/python3.7/site-packages/gunicorn/workers/base.py", line 119, in init_process
    self.load_wsgi()
  File "/home/piekuser/venv/lib/python3.7/site-packages/gunicorn/workers/base.py", line 144, in load_wsgi
    self.wsgi = self.app.wsgi()
  File "/home/piekuser/venv/lib/python3.7/site-packages/gunicorn/app/base.py", line 67, in wsgi
    self.callable = self.load()
  File "/home/piekuser/venv/lib/python3.7/site-packages/gunicorn/app/wsgiapp.py", line 49, in load
    return self.load_wsgiapp()
  File "/home/piekuser/venv/lib/python3.7/site-packages/gunicorn/app/wsgiapp.py", line 39, in load_wsgiapp
    return util.import_app(self.app_uri)
  File "/home/piekuser/venv/lib/python3.7/site-packages/gunicorn/util.py", line 358, in import_app
    mod = importlib.import_module(module)
  File "/usr/lib/python3.7/importlib/__init__.py", line 127, in import_module
    return _bootstrap._gcd_import(name[level:], package, level)
  File "<frozen importlib._bootstrap>", line 1006, in _gcd_import
  File "<frozen importlib._bootstrap>", line 983, in _find_and_load
  File "<frozen importlib._bootstrap>", line 967, in _find_and_load_unlocked
  File "<frozen importlib._bootstrap>", line 677, in _load_unlocked
  File "<frozen importlib._bootstrap_external>", line 728, in exec_module
  File "<frozen importlib._bootstrap>", line 219, in _call_with_frames_removed
  File "/home/piekuser/piek/jrl/wsgi.py", line 16, in <module>
    application = get_wsgi_application()
  File "/home/piekuser/venv/lib/python3.7/site-packages/django/core/wsgi.py", line 12, in get_wsgi_application
    django.setup(set_prefix=False)
  File "/home/piekuser/venv/lib/python3.7/site-packages/django/__init__.py", line 24, in setup
    apps.populate(settings.INSTALLED_APPS)
  File "/home/piekuser/venv/lib/python3.7/site-packages/django/apps/registry.py", line 114, in populate
    app_config.import_models()
  File "/home/piekuser/venv/lib/python3.7/site-packages/django/apps/config.py", line 211, in import_models
    self.models_module = import_module(models_module_name)
  File "/usr/lib/python3.7/importlib/__init__.py", line 127, in import_module
    return _bootstrap._gcd_import(name[level:], package, level)
  File "<frozen importlib._bootstrap>", line 1006, in _gcd_import
  File "<frozen importlib._bootstrap>", line 983, in _find_and_load
  File "<frozen importlib._bootstrap>", line 967, in _find_and_load_unlocked
  File "<frozen importlib._bootstrap>", line 677, in _load_unlocked
  File "<frozen importlib._bootstrap_external>", line 728, in exec_module
  File "<frozen importlib._bootstrap>", line 219, in _call_with_frames_removed
  File "/home/piekuser/piek/mainapp/models.py", line 3, in <module>
    from tinymce import HTMLField
ImportError: cannot import name 'HTMLField' from 'tinymce' (/home/piekuser/venv/lib/python3.7/site-packages/tinymce/__init__.py)
[2020-08-18 12:22:52 +0000] [15417] [INFO] Worker exiting (pid: 15417)
[2020-08-18 15:22:52 +0300] [15413] [INFO] Shutting down: Master
[2020-08-18 15:22:52 +0300] [15413] [INFO] Reason: Worker failed to boot.
[2020-08-18 15:29:40 +0300] [15567] [INFO] Starting gunicorn 20.0.4
[2020-08-18 15:29:40 +0300] [15567] [INFO] Listening at: http://127.0.0.1:8000 (15567)
[2020-08-18 15:29:40 +0300] [15567] [INFO] Using worker: sync
[2020-08-18 15:29:40 +0300] [15570] [INFO] Booting worker with pid: 15570
[2020-08-18 15:29:40 +0300] [15571] [INFO] Booting worker with pid: 15571
[2020-08-18 12:29:40 +0000] [15570] [ERROR] Exception in worker process
Traceback (most recent call last):
  File "/home/piekuser/venv/lib/python3.7/site-packages/gunicorn/arbiter.py", line 583, in spawn_worker
    worker.init_process()
  File "/home/piekuser/venv/lib/python3.7/site-packages/gunicorn/workers/base.py", line 119, in init_process
    self.load_wsgi()
  File "/home/piekuser/venv/lib/python3.7/site-packages/gunicorn/workers/base.py", line 144, in load_wsgi
    self.wsgi = self.app.wsgi()
  File "/home/piekuser/venv/lib/python3.7/site-packages/gunicorn/app/base.py", line 67, in wsgi
    self.callable = self.load()
  File "/home/piekuser/venv/lib/python3.7/site-packages/gunicorn/app/wsgiapp.py", line 49, in load
    return self.load_wsgiapp()
  File "/home/piekuser/venv/lib/python3.7/site-packages/gunicorn/app/wsgiapp.py", line 39, in load_wsgiapp
    return util.import_app(self.app_uri)
  File "/home/piekuser/venv/lib/python3.7/site-packages/gunicorn/util.py", line 358, in import_app
    mod = importlib.import_module(module)
  File "/usr/lib/python3.7/importlib/__init__.py", line 127, in import_module
    return _bootstrap._gcd_import(name[level:], package, level)
  File "<frozen importlib._bootstrap>", line 1006, in _gcd_import
  File "<frozen importlib._bootstrap>", line 983, in _find_and_load
  File "<frozen importlib._bootstrap>", line 967, in _find_and_load_unlocked
  File "<frozen importlib._bootstrap>", line 677, in _load_unlocked
  File "<frozen importlib._bootstrap_external>", line 728, in exec_module
  File "<frozen importlib._bootstrap>", line 219, in _call_with_frames_removed
  File "/home/piekuser/piek/jrl/wsgi.py", line 16, in <module>
    application = get_wsgi_application()
  File "/home/piekuser/venv/lib/python3.7/site-packages/django/core/wsgi.py", line 12, in get_wsgi_application
    django.setup(set_prefix=False)
  File "/home/piekuser/venv/lib/python3.7/site-packages/django/__init__.py", line 24, in setup
    apps.populate(settings.INSTALLED_APPS)
  File "/home/piekuser/venv/lib/python3.7/site-packages/django/apps/registry.py", line 114, in populate
    app_config.import_models()
  File "/home/piekuser/venv/lib/python3.7/site-packages/django/apps/config.py", line 211, in import_models
    self.models_module = import_module(models_module_name)
  File "/usr/lib/python3.7/importlib/__init__.py", line 127, in import_module
    return _bootstrap._gcd_import(name[level:], package, level)
  File "<frozen importlib._bootstrap>", line 1006, in _gcd_import
  File "<frozen importlib._bootstrap>", line 983, in _find_and_load
  File "<frozen importlib._bootstrap>", line 967, in _find_and_load_unlocked
  File "<frozen importlib._bootstrap>", line 677, in _load_unlocked
  File "<frozen importlib._bootstrap_external>", line 728, in exec_module
  File "<frozen importlib._bootstrap>", line 219, in _call_with_frames_removed
  File "/home/piekuser/piek/mainapp/models.py", line 3, in <module>
    from tinymce import HTMLField
ImportError: cannot import name 'HTMLField' from 'tinymce' (/home/piekuser/venv/lib/python3.7/site-packages/tinymce/__init__.py)
[2020-08-18 12:29:40 +0000] [15570] [INFO] Worker exiting (pid: 15570)
[2020-08-18 12:29:40 +0000] [15571] [ERROR] Exception in worker process
Traceback (most recent call last):
  File "/home/piekuser/venv/lib/python3.7/site-packages/gunicorn/arbiter.py", line 583, in spawn_worker
    worker.init_process()
  File "/home/piekuser/venv/lib/python3.7/site-packages/gunicorn/workers/base.py", line 119, in init_process
    self.load_wsgi()
  File "/home/piekuser/venv/lib/python3.7/site-packages/gunicorn/workers/base.py", line 144, in load_wsgi
    self.wsgi = self.app.wsgi()
  File "/home/piekuser/venv/lib/python3.7/site-packages/gunicorn/app/base.py", line 67, in wsgi
    self.callable = self.load()
  File "/home/piekuser/venv/lib/python3.7/site-packages/gunicorn/app/wsgiapp.py", line 49, in load
    return self.load_wsgiapp()
  File "/home/piekuser/venv/lib/python3.7/site-packages/gunicorn/app/wsgiapp.py", line 39, in load_wsgiapp
    return util.import_app(self.app_uri)
  File "/home/piekuser/venv/lib/python3.7/site-packages/gunicorn/util.py", line 358, in import_app
    mod = importlib.import_module(module)
  File "/usr/lib/python3.7/importlib/__init__.py", line 127, in import_module
    return _bootstrap._gcd_import(name[level:], package, level)
  File "<frozen importlib._bootstrap>", line 1006, in _gcd_import
  File "<frozen importlib._bootstrap>", line 983, in _find_and_load
  File "<frozen importlib._bootstrap>", line 967, in _find_and_load_unlocked
  File "<frozen importlib._bootstrap>", line 677, in _load_unlocked
  File "<frozen importlib._bootstrap_external>", line 728, in exec_module
  File "<frozen importlib._bootstrap>", line 219, in _call_with_frames_removed
  File "/home/piekuser/piek/jrl/wsgi.py", line 16, in <module>
    application = get_wsgi_application()
  File "/home/piekuser/venv/lib/python3.7/site-packages/django/core/wsgi.py", line 12, in get_wsgi_application
    django.setup(set_prefix=False)
  File "/home/piekuser/venv/lib/python3.7/site-packages/django/__init__.py", line 24, in setup
    apps.populate(settings.INSTALLED_APPS)
  File "/home/piekuser/venv/lib/python3.7/site-packages/django/apps/registry.py", line 114, in populate
    app_config.import_models()
  File "/home/piekuser/venv/lib/python3.7/site-packages/django/apps/config.py", line 211, in import_models
    self.models_module = import_module(models_module_name)
  File "/usr/lib/python3.7/importlib/__init__.py", line 127, in import_module
    return _bootstrap._gcd_import(name[level:], package, level)
  File "<frozen importlib._bootstrap>", line 1006, in _gcd_import
  File "<frozen importlib._bootstrap>", line 983, in _find_and_load
  File "<frozen importlib._bootstrap>", line 967, in _find_and_load_unlocked
  File "<frozen importlib._bootstrap>", line 677, in _load_unlocked
  File "<frozen importlib._bootstrap_external>", line 728, in exec_module
  File "<frozen importlib._bootstrap>", line 219, in _call_with_frames_removed
  File "/home/piekuser/piek/mainapp/models.py", line 3, in <module>
    from tinymce import HTMLField
ImportError: cannot import name 'HTMLField' from 'tinymce' (/home/piekuser/venv/lib/python3.7/site-packages/tinymce/__init__.py)
[2020-08-18 12:29:40 +0000] [15571] [INFO] Worker exiting (pid: 15571)
[2020-08-18 15:29:40 +0300] [15567] [INFO] Shutting down: Master
[2020-08-18 15:29:40 +0300] [15567] [INFO] Reason: Worker failed to boot.
[2020-08-18 15:29:41 +0300] [15572] [INFO] Starting gunicorn 20.0.4
[2020-08-18 15:29:41 +0300] [15572] [INFO] Listening at: http://127.0.0.1:8000 (15572)
[2020-08-18 15:29:41 +0300] [15572] [INFO] Using worker: sync
[2020-08-18 15:29:41 +0300] [15575] [INFO] Booting worker with pid: 15575
[2020-08-18 15:29:41 +0300] [15576] [INFO] Booting worker with pid: 15576
[2020-08-18 12:29:42 +0000] [15575] [ERROR] Exception in worker process
Traceback (most recent call last):
  File "/home/piekuser/venv/lib/python3.7/site-packages/gunicorn/arbiter.py", line 583, in spawn_worker
    worker.init_process()
  File "/home/piekuser/venv/lib/python3.7/site-packages/gunicorn/workers/base.py", line 119, in init_process
    self.load_wsgi()
  File "/home/piekuser/venv/lib/python3.7/site-packages/gunicorn/workers/base.py", line 144, in load_wsgi
    self.wsgi = self.app.wsgi()
  File "/home/piekuser/venv/lib/python3.7/site-packages/gunicorn/app/base.py", line 67, in wsgi
    self.callable = self.load()
  File "/home/piekuser/venv/lib/python3.7/site-packages/gunicorn/app/wsgiapp.py", line 49, in load
    return self.load_wsgiapp()
  File "/home/piekuser/venv/lib/python3.7/site-packages/gunicorn/app/wsgiapp.py", line 39, in load_wsgiapp
    return util.import_app(self.app_uri)
  File "/home/piekuser/venv/lib/python3.7/site-packages/gunicorn/util.py", line 358, in import_app
    mod = importlib.import_module(module)
  File "/usr/lib/python3.7/importlib/__init__.py", line 127, in import_module
    return _bootstrap._gcd_import(name[level:], package, level)
  File "<frozen importlib._bootstrap>", line 1006, in _gcd_import
  File "<frozen importlib._bootstrap>", line 983, in _find_and_load
  File "<frozen importlib._bootstrap>", line 967, in _find_and_load_unlocked
  File "<frozen importlib._bootstrap>", line 677, in _load_unlocked
  File "<frozen importlib._bootstrap_external>", line 728, in exec_module
  File "<frozen importlib._bootstrap>", line 219, in _call_with_frames_removed
  File "/home/piekuser/piek/jrl/wsgi.py", line 16, in <module>
    application = get_wsgi_application()
  File "/home/piekuser/venv/lib/python3.7/site-packages/django/core/wsgi.py", line 12, in get_wsgi_application
    django.setup(set_prefix=False)
  File "/home/piekuser/venv/lib/python3.7/site-packages/django/__init__.py", line 24, in setup
    apps.populate(settings.INSTALLED_APPS)
  File "/home/piekuser/venv/lib/python3.7/site-packages/django/apps/registry.py", line 114, in populate
    app_config.import_models()
  File "/home/piekuser/venv/lib/python3.7/site-packages/django/apps/config.py", line 211, in import_models
    self.models_module = import_module(models_module_name)
  File "/usr/lib/python3.7/importlib/__init__.py", line 127, in import_module
    return _bootstrap._gcd_import(name[level:], package, level)
  File "<frozen importlib._bootstrap>", line 1006, in _gcd_import
  File "<frozen importlib._bootstrap>", line 983, in _find_and_load
  File "<frozen importlib._bootstrap>", line 967, in _find_and_load_unlocked
  File "<frozen importlib._bootstrap>", line 677, in _load_unlocked
  File "<frozen importlib._bootstrap_external>", line 728, in exec_module
  File "<frozen importlib._bootstrap>", line 219, in _call_with_frames_removed
  File "/home/piekuser/piek/mainapp/models.py", line 3, in <module>
    from tinymce import HTMLField
ImportError: cannot import name 'HTMLField' from 'tinymce' (/home/piekuser/venv/lib/python3.7/site-packages/tinymce/__init__.py)
[2020-08-18 12:29:42 +0000] [15575] [INFO] Worker exiting (pid: 15575)
[2020-08-18 12:29:42 +0000] [15576] [ERROR] Exception in worker process
Traceback (most recent call last):
  File "/home/piekuser/venv/lib/python3.7/site-packages/gunicorn/arbiter.py", line 583, in spawn_worker
    worker.init_process()
  File "/home/piekuser/venv/lib/python3.7/site-packages/gunicorn/workers/base.py", line 119, in init_process
    self.load_wsgi()
  File "/home/piekuser/venv/lib/python3.7/site-packages/gunicorn/workers/base.py", line 144, in load_wsgi
    self.wsgi = self.app.wsgi()
  File "/home/piekuser/venv/lib/python3.7/site-packages/gunicorn/app/base.py", line 67, in wsgi
    self.callable = self.load()
  File "/home/piekuser/venv/lib/python3.7/site-packages/gunicorn/app/wsgiapp.py", line 49, in load
    return self.load_wsgiapp()
  File "/home/piekuser/venv/lib/python3.7/site-packages/gunicorn/app/wsgiapp.py", line 39, in load_wsgiapp
    return util.import_app(self.app_uri)
  File "/home/piekuser/venv/lib/python3.7/site-packages/gunicorn/util.py", line 358, in import_app
    mod = importlib.import_module(module)
  File "/usr/lib/python3.7/importlib/__init__.py", line 127, in import_module
    return _bootstrap._gcd_import(name[level:], package, level)
  File "<frozen importlib._bootstrap>", line 1006, in _gcd_import
  File "<frozen importlib._bootstrap>", line 983, in _find_and_load
  File "<frozen importlib._bootstrap>", line 967, in _find_and_load_unlocked
  File "<frozen importlib._bootstrap>", line 677, in _load_unlocked
  File "<frozen importlib._bootstrap_external>", line 728, in exec_module
  File "<frozen importlib._bootstrap>", line 219, in _call_with_frames_removed
  File "/home/piekuser/piek/jrl/wsgi.py", line 16, in <module>
    application = get_wsgi_application()
  File "/home/piekuser/venv/lib/python3.7/site-packages/django/core/wsgi.py", line 12, in get_wsgi_application
    django.setup(set_prefix=False)
  File "/home/piekuser/venv/lib/python3.7/site-packages/django/__init__.py", line 24, in setup
    apps.populate(settings.INSTALLED_APPS)
  File "/home/piekuser/venv/lib/python3.7/site-packages/django/apps/registry.py", line 114, in populate
    app_config.import_models()
  File "/home/piekuser/venv/lib/python3.7/site-packages/django/apps/config.py", line 211, in import_models
    self.models_module = import_module(models_module_name)
  File "/usr/lib/python3.7/importlib/__init__.py", line 127, in import_module
    return _bootstrap._gcd_import(name[level:], package, level)
  File "<frozen importlib._bootstrap>", line 1006, in _gcd_import
  File "<frozen importlib._bootstrap>", line 983, in _find_and_load
  File "<frozen importlib._bootstrap>", line 967, in _find_and_load_unlocked
  File "<frozen importlib._bootstrap>", line 677, in _load_unlocked
  File "<frozen importlib._bootstrap_external>", line 728, in exec_module
  File "<frozen importlib._bootstrap>", line 219, in _call_with_frames_removed
  File "/home/piekuser/piek/mainapp/models.py", line 3, in <module>
    from tinymce import HTMLField
ImportError: cannot import name 'HTMLField' from 'tinymce' (/home/piekuser/venv/lib/python3.7/site-packages/tinymce/__init__.py)
[2020-08-18 12:29:42 +0000] [15576] [INFO] Worker exiting (pid: 15576)
Traceback (most recent call last):
  File "/home/piekuser/venv/lib/python3.7/site-packages/gunicorn/arbiter.py", line 209, in run
    self.sleep()
  File "/home/piekuser/venv/lib/python3.7/site-packages/gunicorn/arbiter.py", line 357, in sleep
    ready = select.select([self.PIPE[0]], [], [], 1.0)
  File "/home/piekuser/venv/lib/python3.7/site-packages/gunicorn/arbiter.py", line 242, in handle_chld
    self.reap_workers()
  File "/home/piekuser/venv/lib/python3.7/site-packages/gunicorn/arbiter.py", line 525, in reap_workers
    raise HaltServer(reason, self.WORKER_BOOT_ERROR)
gunicorn.errors.HaltServer: <HaltServer 'Worker failed to boot.' 3>

During handling of the above exception, another exception occurred:

Traceback (most recent call last):
  File "/home/piekuser/venv/bin/gunicorn", line 10, in <module>
    sys.exit(run())
  File "/home/piekuser/venv/lib/python3.7/site-packages/gunicorn/app/wsgiapp.py", line 58, in run
    WSGIApplication("%(prog)s [OPTIONS] [APP_MODULE]").run()
  File "/home/piekuser/venv/lib/python3.7/site-packages/gunicorn/app/base.py", line 228, in run
    super().run()
  File "/home/piekuser/venv/lib/python3.7/site-packages/gunicorn/app/base.py", line 72, in run
    Arbiter(self).run()
  File "/home/piekuser/venv/lib/python3.7/site-packages/gunicorn/arbiter.py", line 229, in run
    self.halt(reason=inst.reason, exit_status=inst.exit_status)
  File "/home/piekuser/venv/lib/python3.7/site-packages/gunicorn/arbiter.py", line 342, in halt
    self.stop()
  File "/home/piekuser/venv/lib/python3.7/site-packages/gunicorn/arbiter.py", line 393, in stop
    time.sleep(0.1)
  File "/home/piekuser/venv/lib/python3.7/site-packages/gunicorn/arbiter.py", line 242, in handle_chld
    self.reap_workers()
  File "/home/piekuser/venv/lib/python3.7/site-packages/gunicorn/arbiter.py", line 525, in reap_workers
    raise HaltServer(reason, self.WORKER_BOOT_ERROR)
gunicorn.errors.HaltServer: <HaltServer 'Worker failed to boot.' 3>
[2020-08-18 15:29:44 +0300] [15577] [INFO] Starting gunicorn 20.0.4
[2020-08-18 15:29:44 +0300] [15577] [INFO] Listening at: http://127.0.0.1:8000 (15577)
[2020-08-18 15:29:44 +0300] [15577] [INFO] Using worker: sync
[2020-08-18 15:29:44 +0300] [15580] [INFO] Booting worker with pid: 15580
[2020-08-18 15:29:44 +0300] [15581] [INFO] Booting worker with pid: 15581
[2020-08-18 12:29:44 +0000] [15580] [ERROR] Exception in worker process
Traceback (most recent call last):
  File "/home/piekuser/venv/lib/python3.7/site-packages/gunicorn/arbiter.py", line 583, in spawn_worker
    worker.init_process()
  File "/home/piekuser/venv/lib/python3.7/site-packages/gunicorn/workers/base.py", line 119, in init_process
    self.load_wsgi()
  File "/home/piekuser/venv/lib/python3.7/site-packages/gunicorn/workers/base.py", line 144, in load_wsgi
    self.wsgi = self.app.wsgi()
  File "/home/piekuser/venv/lib/python3.7/site-packages/gunicorn/app/base.py", line 67, in wsgi
    self.callable = self.load()
  File "/home/piekuser/venv/lib/python3.7/site-packages/gunicorn/app/wsgiapp.py", line 49, in load
    return self.load_wsgiapp()
  File "/home/piekuser/venv/lib/python3.7/site-packages/gunicorn/app/wsgiapp.py", line 39, in load_wsgiapp
    return util.import_app(self.app_uri)
  File "/home/piekuser/venv/lib/python3.7/site-packages/gunicorn/util.py", line 358, in import_app
    mod = importlib.import_module(module)
  File "/usr/lib/python3.7/importlib/__init__.py", line 127, in import_module
    return _bootstrap._gcd_import(name[level:], package, level)
  File "<frozen importlib._bootstrap>", line 1006, in _gcd_import
  File "<frozen importlib._bootstrap>", line 983, in _find_and_load
  File "<frozen importlib._bootstrap>", line 967, in _find_and_load_unlocked
  File "<frozen importlib._bootstrap>", line 677, in _load_unlocked
  File "<frozen importlib._bootstrap_external>", line 728, in exec_module
  File "<frozen importlib._bootstrap>", line 219, in _call_with_frames_removed
  File "/home/piekuser/piek/jrl/wsgi.py", line 16, in <module>
    application = get_wsgi_application()
  File "/home/piekuser/venv/lib/python3.7/site-packages/django/core/wsgi.py", line 12, in get_wsgi_application
    django.setup(set_prefix=False)
  File "/home/piekuser/venv/lib/python3.7/site-packages/django/__init__.py", line 24, in setup
    apps.populate(settings.INSTALLED_APPS)
  File "/home/piekuser/venv/lib/python3.7/site-packages/django/apps/registry.py", line 114, in populate
    app_config.import_models()
  File "/home/piekuser/venv/lib/python3.7/site-packages/django/apps/config.py", line 211, in import_models
    self.models_module = import_module(models_module_name)
  File "/usr/lib/python3.7/importlib/__init__.py", line 127, in import_module
    return _bootstrap._gcd_import(name[level:], package, level)
  File "<frozen importlib._bootstrap>", line 1006, in _gcd_import
  File "<frozen importlib._bootstrap>", line 983, in _find_and_load
  File "<frozen importlib._bootstrap>", line 967, in _find_and_load_unlocked
  File "<frozen importlib._bootstrap>", line 677, in _load_unlocked
  File "<frozen importlib._bootstrap_external>", line 728, in exec_module
  File "<frozen importlib._bootstrap>", line 219, in _call_with_frames_removed
  File "/home/piekuser/piek/mainapp/models.py", line 3, in <module>
    from tinymce import HTMLField
ImportError: cannot import name 'HTMLField' from 'tinymce' (/home/piekuser/venv/lib/python3.7/site-packages/tinymce/__init__.py)
[2020-08-18 12:29:44 +0000] [15580] [INFO] Worker exiting (pid: 15580)
[2020-08-18 12:29:45 +0000] [15581] [ERROR] Exception in worker process
Traceback (most recent call last):
  File "/home/piekuser/venv/lib/python3.7/site-packages/gunicorn/arbiter.py", line 583, in spawn_worker
    worker.init_process()
  File "/home/piekuser/venv/lib/python3.7/site-packages/gunicorn/workers/base.py", line 119, in init_process
    self.load_wsgi()
  File "/home/piekuser/venv/lib/python3.7/site-packages/gunicorn/workers/base.py", line 144, in load_wsgi
    self.wsgi = self.app.wsgi()
  File "/home/piekuser/venv/lib/python3.7/site-packages/gunicorn/app/base.py", line 67, in wsgi
    self.callable = self.load()
  File "/home/piekuser/venv/lib/python3.7/site-packages/gunicorn/app/wsgiapp.py", line 49, in load
    return self.load_wsgiapp()
  File "/home/piekuser/venv/lib/python3.7/site-packages/gunicorn/app/wsgiapp.py", line 39, in load_wsgiapp
    return util.import_app(self.app_uri)
  File "/home/piekuser/venv/lib/python3.7/site-packages/gunicorn/util.py", line 358, in import_app
    mod = importlib.import_module(module)
  File "/usr/lib/python3.7/importlib/__init__.py", line 127, in import_module
    return _bootstrap._gcd_import(name[level:], package, level)
  File "<frozen importlib._bootstrap>", line 1006, in _gcd_import
  File "<frozen importlib._bootstrap>", line 983, in _find_and_load
  File "<frozen importlib._bootstrap>", line 967, in _find_and_load_unlocked
  File "<frozen importlib._bootstrap>", line 677, in _load_unlocked
  File "<frozen importlib._bootstrap_external>", line 728, in exec_module
  File "<frozen importlib._bootstrap>", line 219, in _call_with_frames_removed
  File "/home/piekuser/piek/jrl/wsgi.py", line 16, in <module>
    application = get_wsgi_application()
  File "/home/piekuser/venv/lib/python3.7/site-packages/django/core/wsgi.py", line 12, in get_wsgi_application
    django.setup(set_prefix=False)
  File "/home/piekuser/venv/lib/python3.7/site-packages/django/__init__.py", line 24, in setup
    apps.populate(settings.INSTALLED_APPS)
  File "/home/piekuser/venv/lib/python3.7/site-packages/django/apps/registry.py", line 114, in populate
    app_config.import_models()
  File "/home/piekuser/venv/lib/python3.7/site-packages/django/apps/config.py", line 211, in import_models
    self.models_module = import_module(models_module_name)
  File "/usr/lib/python3.7/importlib/__init__.py", line 127, in import_module
    return _bootstrap._gcd_import(name[level:], package, level)
  File "<frozen importlib._bootstrap>", line 1006, in _gcd_import
  File "<frozen importlib._bootstrap>", line 983, in _find_and_load
  File "<frozen importlib._bootstrap>", line 967, in _find_and_load_unlocked
  File "<frozen importlib._bootstrap>", line 677, in _load_unlocked
  File "<frozen importlib._bootstrap_external>", line 728, in exec_module
  File "<frozen importlib._bootstrap>", line 219, in _call_with_frames_removed
  File "/home/piekuser/piek/mainapp/models.py", line 3, in <module>
    from tinymce import HTMLField
ImportError: cannot import name 'HTMLField' from 'tinymce' (/home/piekuser/venv/lib/python3.7/site-packages/tinymce/__init__.py)
[2020-08-18 12:29:45 +0000] [15581] [INFO] Worker exiting (pid: 15581)
Traceback (most recent call last):
  File "/home/piekuser/venv/lib/python3.7/site-packages/gunicorn/arbiter.py", line 209, in run
    self.sleep()
  File "/home/piekuser/venv/lib/python3.7/site-packages/gunicorn/arbiter.py", line 357, in sleep
    ready = select.select([self.PIPE[0]], [], [], 1.0)
  File "/home/piekuser/venv/lib/python3.7/site-packages/gunicorn/arbiter.py", line 242, in handle_chld
    self.reap_workers()
  File "/home/piekuser/venv/lib/python3.7/site-packages/gunicorn/arbiter.py", line 525, in reap_workers
    raise HaltServer(reason, self.WORKER_BOOT_ERROR)
gunicorn.errors.HaltServer: <HaltServer 'Worker failed to boot.' 3>

During handling of the above exception, another exception occurred:

Traceback (most recent call last):
  File "/home/piekuser/venv/bin/gunicorn", line 10, in <module>
    sys.exit(run())
  File "/home/piekuser/venv/lib/python3.7/site-packages/gunicorn/app/wsgiapp.py", line 58, in run
    WSGIApplication("%(prog)s [OPTIONS] [APP_MODULE]").run()
  File "/home/piekuser/venv/lib/python3.7/site-packages/gunicorn/app/base.py", line 228, in run
    super().run()
  File "/home/piekuser/venv/lib/python3.7/site-packages/gunicorn/app/base.py", line 72, in run
    Arbiter(self).run()
  File "/home/piekuser/venv/lib/python3.7/site-packages/gunicorn/arbiter.py", line 229, in run
    self.halt(reason=inst.reason, exit_status=inst.exit_status)
  File "/home/piekuser/venv/lib/python3.7/site-packages/gunicorn/arbiter.py", line 342, in halt
    self.stop()
  File "/home/piekuser/venv/lib/python3.7/site-packages/gunicorn/arbiter.py", line 393, in stop
    time.sleep(0.1)
  File "/home/piekuser/venv/lib/python3.7/site-packages/gunicorn/arbiter.py", line 242, in handle_chld
    self.reap_workers()
  File "/home/piekuser/venv/lib/python3.7/site-packages/gunicorn/arbiter.py", line 525, in reap_workers
    raise HaltServer(reason, self.WORKER_BOOT_ERROR)
gunicorn.errors.HaltServer: <HaltServer 'Worker failed to boot.' 3>
[2020-08-18 15:29:48 +0300] [15584] [INFO] Starting gunicorn 20.0.4
[2020-08-18 15:29:48 +0300] [15584] [INFO] Listening at: http://127.0.0.1:8000 (15584)
[2020-08-18 15:29:48 +0300] [15584] [INFO] Using worker: sync
[2020-08-18 15:29:48 +0300] [15587] [INFO] Booting worker with pid: 15587
[2020-08-18 15:29:48 +0300] [15588] [INFO] Booting worker with pid: 15588
[2020-08-18 12:29:49 +0000] [15587] [ERROR] Exception in worker process
Traceback (most recent call last):
  File "/home/piekuser/venv/lib/python3.7/site-packages/gunicorn/arbiter.py", line 583, in spawn_worker
    worker.init_process()
  File "/home/piekuser/venv/lib/python3.7/site-packages/gunicorn/workers/base.py", line 119, in init_process
    self.load_wsgi()
  File "/home/piekuser/venv/lib/python3.7/site-packages/gunicorn/workers/base.py", line 144, in load_wsgi
    self.wsgi = self.app.wsgi()
  File "/home/piekuser/venv/lib/python3.7/site-packages/gunicorn/app/base.py", line 67, in wsgi
    self.callable = self.load()
  File "/home/piekuser/venv/lib/python3.7/site-packages/gunicorn/app/wsgiapp.py", line 49, in load
    return self.load_wsgiapp()
  File "/home/piekuser/venv/lib/python3.7/site-packages/gunicorn/app/wsgiapp.py", line 39, in load_wsgiapp
    return util.import_app(self.app_uri)
  File "/home/piekuser/venv/lib/python3.7/site-packages/gunicorn/util.py", line 358, in import_app
    mod = importlib.import_module(module)
  File "/usr/lib/python3.7/importlib/__init__.py", line 127, in import_module
    return _bootstrap._gcd_import(name[level:], package, level)
  File "<frozen importlib._bootstrap>", line 1006, in _gcd_import
  File "<frozen importlib._bootstrap>", line 983, in _find_and_load
  File "<frozen importlib._bootstrap>", line 967, in _find_and_load_unlocked
  File "<frozen importlib._bootstrap>", line 677, in _load_unlocked
  File "<frozen importlib._bootstrap_external>", line 728, in exec_module
  File "<frozen importlib._bootstrap>", line 219, in _call_with_frames_removed
  File "/home/piekuser/piek/jrl/wsgi.py", line 16, in <module>
    application = get_wsgi_application()
  File "/home/piekuser/venv/lib/python3.7/site-packages/django/core/wsgi.py", line 12, in get_wsgi_application
    django.setup(set_prefix=False)
  File "/home/piekuser/venv/lib/python3.7/site-packages/django/__init__.py", line 24, in setup
    apps.populate(settings.INSTALLED_APPS)
  File "/home/piekuser/venv/lib/python3.7/site-packages/django/apps/registry.py", line 114, in populate
    app_config.import_models()
  File "/home/piekuser/venv/lib/python3.7/site-packages/django/apps/config.py", line 211, in import_models
    self.models_module = import_module(models_module_name)
  File "/usr/lib/python3.7/importlib/__init__.py", line 127, in import_module
    return _bootstrap._gcd_import(name[level:], package, level)
  File "<frozen importlib._bootstrap>", line 1006, in _gcd_import
  File "<frozen importlib._bootstrap>", line 983, in _find_and_load
  File "<frozen importlib._bootstrap>", line 967, in _find_and_load_unlocked
  File "<frozen importlib._bootstrap>", line 677, in _load_unlocked
  File "<frozen importlib._bootstrap_external>", line 728, in exec_module
  File "<frozen importlib._bootstrap>", line 219, in _call_with_frames_removed
  File "/home/piekuser/piek/mainapp/models.py", line 3, in <module>
    from tinymce import HTMLField
ImportError: cannot import name 'HTMLField' from 'tinymce' (/home/piekuser/venv/lib/python3.7/site-packages/tinymce/__init__.py)
[2020-08-18 12:29:49 +0000] [15587] [INFO] Worker exiting (pid: 15587)
[2020-08-18 12:29:49 +0000] [15588] [ERROR] Exception in worker process
Traceback (most recent call last):
  File "/home/piekuser/venv/lib/python3.7/site-packages/gunicorn/arbiter.py", line 583, in spawn_worker
    worker.init_process()
  File "/home/piekuser/venv/lib/python3.7/site-packages/gunicorn/workers/base.py", line 119, in init_process
    self.load_wsgi()
  File "/home/piekuser/venv/lib/python3.7/site-packages/gunicorn/workers/base.py", line 144, in load_wsgi
    self.wsgi = self.app.wsgi()
  File "/home/piekuser/venv/lib/python3.7/site-packages/gunicorn/app/base.py", line 67, in wsgi
    self.callable = self.load()
  File "/home/piekuser/venv/lib/python3.7/site-packages/gunicorn/app/wsgiapp.py", line 49, in load
    return self.load_wsgiapp()
  File "/home/piekuser/venv/lib/python3.7/site-packages/gunicorn/app/wsgiapp.py", line 39, in load_wsgiapp
    return util.import_app(self.app_uri)
  File "/home/piekuser/venv/lib/python3.7/site-packages/gunicorn/util.py", line 358, in import_app
    mod = importlib.import_module(module)
  File "/usr/lib/python3.7/importlib/__init__.py", line 127, in import_module
    return _bootstrap._gcd_import(name[level:], package, level)
  File "<frozen importlib._bootstrap>", line 1006, in _gcd_import
  File "<frozen importlib._bootstrap>", line 983, in _find_and_load
  File "<frozen importlib._bootstrap>", line 967, in _find_and_load_unlocked
  File "<frozen importlib._bootstrap>", line 677, in _load_unlocked
  File "<frozen importlib._bootstrap_external>", line 728, in exec_module
  File "<frozen importlib._bootstrap>", line 219, in _call_with_frames_removed
  File "/home/piekuser/piek/jrl/wsgi.py", line 16, in <module>
    application = get_wsgi_application()
  File "/home/piekuser/venv/lib/python3.7/site-packages/django/core/wsgi.py", line 12, in get_wsgi_application
    django.setup(set_prefix=False)
  File "/home/piekuser/venv/lib/python3.7/site-packages/django/__init__.py", line 24, in setup
    apps.populate(settings.INSTALLED_APPS)
  File "/home/piekuser/venv/lib/python3.7/site-packages/django/apps/registry.py", line 114, in populate
    app_config.import_models()
  File "/home/piekuser/venv/lib/python3.7/site-packages/django/apps/config.py", line 211, in import_models
    self.models_module = import_module(models_module_name)
  File "/usr/lib/python3.7/importlib/__init__.py", line 127, in import_module
    return _bootstrap._gcd_import(name[level:], package, level)
  File "<frozen importlib._bootstrap>", line 1006, in _gcd_import
  File "<frozen importlib._bootstrap>", line 983, in _find_and_load
  File "<frozen importlib._bootstrap>", line 967, in _find_and_load_unlocked
  File "<frozen importlib._bootstrap>", line 677, in _load_unlocked
  File "<frozen importlib._bootstrap_external>", line 728, in exec_module
  File "<frozen importlib._bootstrap>", line 219, in _call_with_frames_removed
  File "/home/piekuser/piek/mainapp/models.py", line 3, in <module>
    from tinymce import HTMLField
ImportError: cannot import name 'HTMLField' from 'tinymce' (/home/piekuser/venv/lib/python3.7/site-packages/tinymce/__init__.py)
[2020-08-18 12:29:49 +0000] [15588] [INFO] Worker exiting (pid: 15588)
[2020-08-18 15:29:49 +0300] [15584] [INFO] Shutting down: Master
[2020-08-18 15:29:49 +0300] [15584] [INFO] Reason: Worker failed to boot.
[2020-08-18 15:32:01 +0300] [15719] [INFO] Starting gunicorn 20.0.4
[2020-08-18 15:32:01 +0300] [15719] [INFO] Listening at: http://127.0.0.1:8000 (15719)
[2020-08-18 15:32:01 +0300] [15719] [INFO] Using worker: sync
[2020-08-18 15:32:01 +0300] [15722] [INFO] Booting worker with pid: 15722
[2020-08-18 15:32:01 +0300] [15723] [INFO] Booting worker with pid: 15723
[2020-08-18 12:32:01 +0000] [15722] [ERROR] Exception in worker process
Traceback (most recent call last):
  File "/home/piekuser/venv/lib/python3.7/site-packages/gunicorn/arbiter.py", line 583, in spawn_worker
    worker.init_process()
  File "/home/piekuser/venv/lib/python3.7/site-packages/gunicorn/workers/base.py", line 119, in init_process
    self.load_wsgi()
  File "/home/piekuser/venv/lib/python3.7/site-packages/gunicorn/workers/base.py", line 144, in load_wsgi
    self.wsgi = self.app.wsgi()
  File "/home/piekuser/venv/lib/python3.7/site-packages/gunicorn/app/base.py", line 67, in wsgi
    self.callable = self.load()
  File "/home/piekuser/venv/lib/python3.7/site-packages/gunicorn/app/wsgiapp.py", line 49, in load
    return self.load_wsgiapp()
  File "/home/piekuser/venv/lib/python3.7/site-packages/gunicorn/app/wsgiapp.py", line 39, in load_wsgiapp
    return util.import_app(self.app_uri)
  File "/home/piekuser/venv/lib/python3.7/site-packages/gunicorn/util.py", line 358, in import_app
    mod = importlib.import_module(module)
  File "/usr/lib/python3.7/importlib/__init__.py", line 127, in import_module
    return _bootstrap._gcd_import(name[level:], package, level)
  File "<frozen importlib._bootstrap>", line 1006, in _gcd_import
  File "<frozen importlib._bootstrap>", line 983, in _find_and_load
  File "<frozen importlib._bootstrap>", line 967, in _find_and_load_unlocked
  File "<frozen importlib._bootstrap>", line 677, in _load_unlocked
  File "<frozen importlib._bootstrap_external>", line 728, in exec_module
  File "<frozen importlib._bootstrap>", line 219, in _call_with_frames_removed
  File "/home/piekuser/piek/jrl/wsgi.py", line 16, in <module>
    application = get_wsgi_application()
  File "/home/piekuser/venv/lib/python3.7/site-packages/django/core/wsgi.py", line 12, in get_wsgi_application
    django.setup(set_prefix=False)
  File "/home/piekuser/venv/lib/python3.7/site-packages/django/__init__.py", line 24, in setup
    apps.populate(settings.INSTALLED_APPS)
  File "/home/piekuser/venv/lib/python3.7/site-packages/django/apps/registry.py", line 114, in populate
    app_config.import_models()
  File "/home/piekuser/venv/lib/python3.7/site-packages/django/apps/config.py", line 211, in import_models
    self.models_module = import_module(models_module_name)
  File "/usr/lib/python3.7/importlib/__init__.py", line 127, in import_module
    return _bootstrap._gcd_import(name[level:], package, level)
  File "<frozen importlib._bootstrap>", line 1006, in _gcd_import
  File "<frozen importlib._bootstrap>", line 983, in _find_and_load
  File "<frozen importlib._bootstrap>", line 967, in _find_and_load_unlocked
  File "<frozen importlib._bootstrap>", line 677, in _load_unlocked
  File "<frozen importlib._bootstrap_external>", line 728, in exec_module
  File "<frozen importlib._bootstrap>", line 219, in _call_with_frames_removed
  File "/home/piekuser/piek/mainapp/models.py", line 3, in <module>
    from tinymce import HTMLField
ImportError: cannot import name 'HTMLField' from 'tinymce' (/home/piekuser/venv/lib/python3.7/site-packages/tinymce/__init__.py)
[2020-08-18 12:32:01 +0000] [15722] [INFO] Worker exiting (pid: 15722)
[2020-08-18 12:32:01 +0000] [15723] [ERROR] Exception in worker process
Traceback (most recent call last):
  File "/home/piekuser/venv/lib/python3.7/site-packages/gunicorn/arbiter.py", line 583, in spawn_worker
    worker.init_process()
  File "/home/piekuser/venv/lib/python3.7/site-packages/gunicorn/workers/base.py", line 119, in init_process
    self.load_wsgi()
  File "/home/piekuser/venv/lib/python3.7/site-packages/gunicorn/workers/base.py", line 144, in load_wsgi
    self.wsgi = self.app.wsgi()
  File "/home/piekuser/venv/lib/python3.7/site-packages/gunicorn/app/base.py", line 67, in wsgi
    self.callable = self.load()
  File "/home/piekuser/venv/lib/python3.7/site-packages/gunicorn/app/wsgiapp.py", line 49, in load
    return self.load_wsgiapp()
  File "/home/piekuser/venv/lib/python3.7/site-packages/gunicorn/app/wsgiapp.py", line 39, in load_wsgiapp
    return util.import_app(self.app_uri)
  File "/home/piekuser/venv/lib/python3.7/site-packages/gunicorn/util.py", line 358, in import_app
    mod = importlib.import_module(module)
  File "/usr/lib/python3.7/importlib/__init__.py", line 127, in import_module
    return _bootstrap._gcd_import(name[level:], package, level)
  File "<frozen importlib._bootstrap>", line 1006, in _gcd_import
  File "<frozen importlib._bootstrap>", line 983, in _find_and_load
  File "<frozen importlib._bootstrap>", line 967, in _find_and_load_unlocked
  File "<frozen importlib._bootstrap>", line 677, in _load_unlocked
  File "<frozen importlib._bootstrap_external>", line 728, in exec_module
  File "<frozen importlib._bootstrap>", line 219, in _call_with_frames_removed
  File "/home/piekuser/piek/jrl/wsgi.py", line 16, in <module>
    application = get_wsgi_application()
  File "/home/piekuser/venv/lib/python3.7/site-packages/django/core/wsgi.py", line 12, in get_wsgi_application
    django.setup(set_prefix=False)
  File "/home/piekuser/venv/lib/python3.7/site-packages/django/__init__.py", line 24, in setup
    apps.populate(settings.INSTALLED_APPS)
  File "/home/piekuser/venv/lib/python3.7/site-packages/django/apps/registry.py", line 114, in populate
    app_config.import_models()
  File "/home/piekuser/venv/lib/python3.7/site-packages/django/apps/config.py", line 211, in import_models
    self.models_module = import_module(models_module_name)
  File "/usr/lib/python3.7/importlib/__init__.py", line 127, in import_module
    return _bootstrap._gcd_import(name[level:], package, level)
  File "<frozen importlib._bootstrap>", line 1006, in _gcd_import
  File "<frozen importlib._bootstrap>", line 983, in _find_and_load
  File "<frozen importlib._bootstrap>", line 967, in _find_and_load_unlocked
  File "<frozen importlib._bootstrap>", line 677, in _load_unlocked
  File "<frozen importlib._bootstrap_external>", line 728, in exec_module
  File "<frozen importlib._bootstrap>", line 219, in _call_with_frames_removed
  File "/home/piekuser/piek/mainapp/models.py", line 3, in <module>
    from tinymce import HTMLField
ImportError: cannot import name 'HTMLField' from 'tinymce' (/home/piekuser/venv/lib/python3.7/site-packages/tinymce/__init__.py)
[2020-08-18 12:32:01 +0000] [15723] [INFO] Worker exiting (pid: 15723)
Traceback (most recent call last):
  File "/home/piekuser/venv/lib/python3.7/site-packages/gunicorn/arbiter.py", line 209, in run
    self.sleep()
  File "/home/piekuser/venv/lib/python3.7/site-packages/gunicorn/arbiter.py", line 357, in sleep
    ready = select.select([self.PIPE[0]], [], [], 1.0)
  File "/home/piekuser/venv/lib/python3.7/site-packages/gunicorn/arbiter.py", line 242, in handle_chld
    self.reap_workers()
  File "/home/piekuser/venv/lib/python3.7/site-packages/gunicorn/arbiter.py", line 525, in reap_workers
    raise HaltServer(reason, self.WORKER_BOOT_ERROR)
gunicorn.errors.HaltServer: <HaltServer 'Worker failed to boot.' 3>

During handling of the above exception, another exception occurred:

Traceback (most recent call last):
  File "/home/piekuser/venv/bin/gunicorn", line 10, in <module>
    sys.exit(run())
  File "/home/piekuser/venv/lib/python3.7/site-packages/gunicorn/app/wsgiapp.py", line 58, in run
    WSGIApplication("%(prog)s [OPTIONS] [APP_MODULE]").run()
  File "/home/piekuser/venv/lib/python3.7/site-packages/gunicorn/app/base.py", line 228, in run
    super().run()
  File "/home/piekuser/venv/lib/python3.7/site-packages/gunicorn/app/base.py", line 72, in run
    Arbiter(self).run()
  File "/home/piekuser/venv/lib/python3.7/site-packages/gunicorn/arbiter.py", line 229, in run
    self.halt(reason=inst.reason, exit_status=inst.exit_status)
  File "/home/piekuser/venv/lib/python3.7/site-packages/gunicorn/arbiter.py", line 342, in halt
    self.stop()
  File "/home/piekuser/venv/lib/python3.7/site-packages/gunicorn/arbiter.py", line 393, in stop
    time.sleep(0.1)
  File "/home/piekuser/venv/lib/python3.7/site-packages/gunicorn/arbiter.py", line 242, in handle_chld
    self.reap_workers()
  File "/home/piekuser/venv/lib/python3.7/site-packages/gunicorn/arbiter.py", line 525, in reap_workers
    raise HaltServer(reason, self.WORKER_BOOT_ERROR)
gunicorn.errors.HaltServer: <HaltServer 'Worker failed to boot.' 3>
[2020-08-18 15:32:02 +0300] [15724] [INFO] Starting gunicorn 20.0.4
[2020-08-18 15:32:02 +0300] [15724] [INFO] Listening at: http://127.0.0.1:8000 (15724)
[2020-08-18 15:32:02 +0300] [15724] [INFO] Using worker: sync
[2020-08-18 15:32:02 +0300] [15727] [INFO] Booting worker with pid: 15727
[2020-08-18 15:32:02 +0300] [15728] [INFO] Booting worker with pid: 15728
[2020-08-18 12:32:03 +0000] [15727] [ERROR] Exception in worker process
Traceback (most recent call last):
  File "/home/piekuser/venv/lib/python3.7/site-packages/gunicorn/arbiter.py", line 583, in spawn_worker
    worker.init_process()
  File "/home/piekuser/venv/lib/python3.7/site-packages/gunicorn/workers/base.py", line 119, in init_process
    self.load_wsgi()
  File "/home/piekuser/venv/lib/python3.7/site-packages/gunicorn/workers/base.py", line 144, in load_wsgi
    self.wsgi = self.app.wsgi()
  File "/home/piekuser/venv/lib/python3.7/site-packages/gunicorn/app/base.py", line 67, in wsgi
    self.callable = self.load()
  File "/home/piekuser/venv/lib/python3.7/site-packages/gunicorn/app/wsgiapp.py", line 49, in load
    return self.load_wsgiapp()
  File "/home/piekuser/venv/lib/python3.7/site-packages/gunicorn/app/wsgiapp.py", line 39, in load_wsgiapp
    return util.import_app(self.app_uri)
  File "/home/piekuser/venv/lib/python3.7/site-packages/gunicorn/util.py", line 358, in import_app
    mod = importlib.import_module(module)
  File "/usr/lib/python3.7/importlib/__init__.py", line 127, in import_module
    return _bootstrap._gcd_import(name[level:], package, level)
  File "<frozen importlib._bootstrap>", line 1006, in _gcd_import
  File "<frozen importlib._bootstrap>", line 983, in _find_and_load
  File "<frozen importlib._bootstrap>", line 967, in _find_and_load_unlocked
  File "<frozen importlib._bootstrap>", line 677, in _load_unlocked
  File "<frozen importlib._bootstrap_external>", line 728, in exec_module
  File "<frozen importlib._bootstrap>", line 219, in _call_with_frames_removed
  File "/home/piekuser/piek/jrl/wsgi.py", line 16, in <module>
    application = get_wsgi_application()
  File "/home/piekuser/venv/lib/python3.7/site-packages/django/core/wsgi.py", line 12, in get_wsgi_application
    django.setup(set_prefix=False)
  File "/home/piekuser/venv/lib/python3.7/site-packages/django/__init__.py", line 24, in setup
    apps.populate(settings.INSTALLED_APPS)
  File "/home/piekuser/venv/lib/python3.7/site-packages/django/apps/registry.py", line 114, in populate
    app_config.import_models()
  File "/home/piekuser/venv/lib/python3.7/site-packages/django/apps/config.py", line 211, in import_models
    self.models_module = import_module(models_module_name)
  File "/usr/lib/python3.7/importlib/__init__.py", line 127, in import_module
    return _bootstrap._gcd_import(name[level:], package, level)
  File "<frozen importlib._bootstrap>", line 1006, in _gcd_import
  File "<frozen importlib._bootstrap>", line 983, in _find_and_load
  File "<frozen importlib._bootstrap>", line 967, in _find_and_load_unlocked
  File "<frozen importlib._bootstrap>", line 677, in _load_unlocked
  File "<frozen importlib._bootstrap_external>", line 728, in exec_module
  File "<frozen importlib._bootstrap>", line 219, in _call_with_frames_removed
  File "/home/piekuser/piek/mainapp/models.py", line 3, in <module>
    from tinymce import HTMLField
ImportError: cannot import name 'HTMLField' from 'tinymce' (/home/piekuser/venv/lib/python3.7/site-packages/tinymce/__init__.py)
[2020-08-18 12:32:03 +0000] [15727] [INFO] Worker exiting (pid: 15727)
[2020-08-18 12:32:03 +0000] [15728] [ERROR] Exception in worker process
Traceback (most recent call last):
  File "/home/piekuser/venv/lib/python3.7/site-packages/gunicorn/arbiter.py", line 583, in spawn_worker
    worker.init_process()
  File "/home/piekuser/venv/lib/python3.7/site-packages/gunicorn/workers/base.py", line 119, in init_process
    self.load_wsgi()
  File "/home/piekuser/venv/lib/python3.7/site-packages/gunicorn/workers/base.py", line 144, in load_wsgi
    self.wsgi = self.app.wsgi()
  File "/home/piekuser/venv/lib/python3.7/site-packages/gunicorn/app/base.py", line 67, in wsgi
    self.callable = self.load()
  File "/home/piekuser/venv/lib/python3.7/site-packages/gunicorn/app/wsgiapp.py", line 49, in load
    return self.load_wsgiapp()
  File "/home/piekuser/venv/lib/python3.7/site-packages/gunicorn/app/wsgiapp.py", line 39, in load_wsgiapp
    return util.import_app(self.app_uri)
  File "/home/piekuser/venv/lib/python3.7/site-packages/gunicorn/util.py", line 358, in import_app
    mod = importlib.import_module(module)
  File "/usr/lib/python3.7/importlib/__init__.py", line 127, in import_module
    return _bootstrap._gcd_import(name[level:], package, level)
  File "<frozen importlib._bootstrap>", line 1006, in _gcd_import
  File "<frozen importlib._bootstrap>", line 983, in _find_and_load
  File "<frozen importlib._bootstrap>", line 967, in _find_and_load_unlocked
  File "<frozen importlib._bootstrap>", line 677, in _load_unlocked
  File "<frozen importlib._bootstrap_external>", line 728, in exec_module
  File "<frozen importlib._bootstrap>", line 219, in _call_with_frames_removed
  File "/home/piekuser/piek/jrl/wsgi.py", line 16, in <module>
    application = get_wsgi_application()
  File "/home/piekuser/venv/lib/python3.7/site-packages/django/core/wsgi.py", line 12, in get_wsgi_application
    django.setup(set_prefix=False)
  File "/home/piekuser/venv/lib/python3.7/site-packages/django/__init__.py", line 24, in setup
    apps.populate(settings.INSTALLED_APPS)
  File "/home/piekuser/venv/lib/python3.7/site-packages/django/apps/registry.py", line 114, in populate
    app_config.import_models()
  File "/home/piekuser/venv/lib/python3.7/site-packages/django/apps/config.py", line 211, in import_models
    self.models_module = import_module(models_module_name)
  File "/usr/lib/python3.7/importlib/__init__.py", line 127, in import_module
    return _bootstrap._gcd_import(name[level:], package, level)
  File "<frozen importlib._bootstrap>", line 1006, in _gcd_import
  File "<frozen importlib._bootstrap>", line 983, in _find_and_load
  File "<frozen importlib._bootstrap>", line 967, in _find_and_load_unlocked
  File "<frozen importlib._bootstrap>", line 677, in _load_unlocked
  File "<frozen importlib._bootstrap_external>", line 728, in exec_module
  File "<frozen importlib._bootstrap>", line 219, in _call_with_frames_removed
  File "/home/piekuser/piek/mainapp/models.py", line 3, in <module>
    from tinymce import HTMLField
ImportError: cannot import name 'HTMLField' from 'tinymce' (/home/piekuser/venv/lib/python3.7/site-packages/tinymce/__init__.py)
[2020-08-18 12:32:03 +0000] [15728] [INFO] Worker exiting (pid: 15728)
Traceback (most recent call last):
  File "/home/piekuser/venv/lib/python3.7/site-packages/gunicorn/arbiter.py", line 209, in run
    self.sleep()
  File "/home/piekuser/venv/lib/python3.7/site-packages/gunicorn/arbiter.py", line 357, in sleep
    ready = select.select([self.PIPE[0]], [], [], 1.0)
  File "/home/piekuser/venv/lib/python3.7/site-packages/gunicorn/arbiter.py", line 242, in handle_chld
    self.reap_workers()
  File "/home/piekuser/venv/lib/python3.7/site-packages/gunicorn/arbiter.py", line 525, in reap_workers
    raise HaltServer(reason, self.WORKER_BOOT_ERROR)
gunicorn.errors.HaltServer: <HaltServer 'Worker failed to boot.' 3>

During handling of the above exception, another exception occurred:

Traceback (most recent call last):
  File "/home/piekuser/venv/bin/gunicorn", line 10, in <module>
    sys.exit(run())
  File "/home/piekuser/venv/lib/python3.7/site-packages/gunicorn/app/wsgiapp.py", line 58, in run
    WSGIApplication("%(prog)s [OPTIONS] [APP_MODULE]").run()
  File "/home/piekuser/venv/lib/python3.7/site-packages/gunicorn/app/base.py", line 228, in run
    super().run()
  File "/home/piekuser/venv/lib/python3.7/site-packages/gunicorn/app/base.py", line 72, in run
    Arbiter(self).run()
  File "/home/piekuser/venv/lib/python3.7/site-packages/gunicorn/arbiter.py", line 229, in run
    self.halt(reason=inst.reason, exit_status=inst.exit_status)
  File "/home/piekuser/venv/lib/python3.7/site-packages/gunicorn/arbiter.py", line 342, in halt
    self.stop()
  File "/home/piekuser/venv/lib/python3.7/site-packages/gunicorn/arbiter.py", line 393, in stop
    time.sleep(0.1)
  File "/home/piekuser/venv/lib/python3.7/site-packages/gunicorn/arbiter.py", line 242, in handle_chld
    self.reap_workers()
  File "/home/piekuser/venv/lib/python3.7/site-packages/gunicorn/arbiter.py", line 525, in reap_workers
    raise HaltServer(reason, self.WORKER_BOOT_ERROR)
gunicorn.errors.HaltServer: <HaltServer 'Worker failed to boot.' 3>
[2020-08-18 15:32:05 +0300] [15729] [INFO] Starting gunicorn 20.0.4
[2020-08-18 15:32:05 +0300] [15729] [INFO] Listening at: http://127.0.0.1:8000 (15729)
[2020-08-18 15:32:05 +0300] [15729] [INFO] Using worker: sync
[2020-08-18 15:32:05 +0300] [15732] [INFO] Booting worker with pid: 15732
[2020-08-18 15:32:05 +0300] [15733] [INFO] Booting worker with pid: 15733
[2020-08-18 12:32:05 +0000] [15732] [ERROR] Exception in worker process
Traceback (most recent call last):
  File "/home/piekuser/venv/lib/python3.7/site-packages/gunicorn/arbiter.py", line 583, in spawn_worker
    worker.init_process()
  File "/home/piekuser/venv/lib/python3.7/site-packages/gunicorn/workers/base.py", line 119, in init_process
    self.load_wsgi()
  File "/home/piekuser/venv/lib/python3.7/site-packages/gunicorn/workers/base.py", line 144, in load_wsgi
    self.wsgi = self.app.wsgi()
  File "/home/piekuser/venv/lib/python3.7/site-packages/gunicorn/app/base.py", line 67, in wsgi
    self.callable = self.load()
  File "/home/piekuser/venv/lib/python3.7/site-packages/gunicorn/app/wsgiapp.py", line 49, in load
    return self.load_wsgiapp()
  File "/home/piekuser/venv/lib/python3.7/site-packages/gunicorn/app/wsgiapp.py", line 39, in load_wsgiapp
    return util.import_app(self.app_uri)
  File "/home/piekuser/venv/lib/python3.7/site-packages/gunicorn/util.py", line 358, in import_app
    mod = importlib.import_module(module)
  File "/usr/lib/python3.7/importlib/__init__.py", line 127, in import_module
    return _bootstrap._gcd_import(name[level:], package, level)
  File "<frozen importlib._bootstrap>", line 1006, in _gcd_import
  File "<frozen importlib._bootstrap>", line 983, in _find_and_load
  File "<frozen importlib._bootstrap>", line 967, in _find_and_load_unlocked
  File "<frozen importlib._bootstrap>", line 677, in _load_unlocked
  File "<frozen importlib._bootstrap_external>", line 728, in exec_module
  File "<frozen importlib._bootstrap>", line 219, in _call_with_frames_removed
  File "/home/piekuser/piek/jrl/wsgi.py", line 16, in <module>
    application = get_wsgi_application()
  File "/home/piekuser/venv/lib/python3.7/site-packages/django/core/wsgi.py", line 12, in get_wsgi_application
    django.setup(set_prefix=False)
  File "/home/piekuser/venv/lib/python3.7/site-packages/django/__init__.py", line 24, in setup
    apps.populate(settings.INSTALLED_APPS)
  File "/home/piekuser/venv/lib/python3.7/site-packages/django/apps/registry.py", line 114, in populate
    app_config.import_models()
  File "/home/piekuser/venv/lib/python3.7/site-packages/django/apps/config.py", line 211, in import_models
    self.models_module = import_module(models_module_name)
  File "/usr/lib/python3.7/importlib/__init__.py", line 127, in import_module
    return _bootstrap._gcd_import(name[level:], package, level)
  File "<frozen importlib._bootstrap>", line 1006, in _gcd_import
  File "<frozen importlib._bootstrap>", line 983, in _find_and_load
  File "<frozen importlib._bootstrap>", line 967, in _find_and_load_unlocked
  File "<frozen importlib._bootstrap>", line 677, in _load_unlocked
  File "<frozen importlib._bootstrap_external>", line 728, in exec_module
  File "<frozen importlib._bootstrap>", line 219, in _call_with_frames_removed
  File "/home/piekuser/piek/mainapp/models.py", line 3, in <module>
    from tinymce import HTMLField
ImportError: cannot import name 'HTMLField' from 'tinymce' (/home/piekuser/venv/lib/python3.7/site-packages/tinymce/__init__.py)
[2020-08-18 12:32:05 +0000] [15732] [INFO] Worker exiting (pid: 15732)
[2020-08-18 12:32:05 +0000] [15733] [ERROR] Exception in worker process
Traceback (most recent call last):
  File "/home/piekuser/venv/lib/python3.7/site-packages/gunicorn/arbiter.py", line 583, in spawn_worker
    worker.init_process()
  File "/home/piekuser/venv/lib/python3.7/site-packages/gunicorn/workers/base.py", line 119, in init_process
    self.load_wsgi()
  File "/home/piekuser/venv/lib/python3.7/site-packages/gunicorn/workers/base.py", line 144, in load_wsgi
    self.wsgi = self.app.wsgi()
  File "/home/piekuser/venv/lib/python3.7/site-packages/gunicorn/app/base.py", line 67, in wsgi
    self.callable = self.load()
  File "/home/piekuser/venv/lib/python3.7/site-packages/gunicorn/app/wsgiapp.py", line 49, in load
    return self.load_wsgiapp()
  File "/home/piekuser/venv/lib/python3.7/site-packages/gunicorn/app/wsgiapp.py", line 39, in load_wsgiapp
    return util.import_app(self.app_uri)
  File "/home/piekuser/venv/lib/python3.7/site-packages/gunicorn/util.py", line 358, in import_app
    mod = importlib.import_module(module)
  File "/usr/lib/python3.7/importlib/__init__.py", line 127, in import_module
    return _bootstrap._gcd_import(name[level:], package, level)
  File "<frozen importlib._bootstrap>", line 1006, in _gcd_import
  File "<frozen importlib._bootstrap>", line 983, in _find_and_load
  File "<frozen importlib._bootstrap>", line 967, in _find_and_load_unlocked
  File "<frozen importlib._bootstrap>", line 677, in _load_unlocked
  File "<frozen importlib._bootstrap_external>", line 728, in exec_module
  File "<frozen importlib._bootstrap>", line 219, in _call_with_frames_removed
  File "/home/piekuser/piek/jrl/wsgi.py", line 16, in <module>
    application = get_wsgi_application()
  File "/home/piekuser/venv/lib/python3.7/site-packages/django/core/wsgi.py", line 12, in get_wsgi_application
    django.setup(set_prefix=False)
  File "/home/piekuser/venv/lib/python3.7/site-packages/django/__init__.py", line 24, in setup
    apps.populate(settings.INSTALLED_APPS)
  File "/home/piekuser/venv/lib/python3.7/site-packages/django/apps/registry.py", line 114, in populate
    app_config.import_models()
  File "/home/piekuser/venv/lib/python3.7/site-packages/django/apps/config.py", line 211, in import_models
    self.models_module = import_module(models_module_name)
  File "/usr/lib/python3.7/importlib/__init__.py", line 127, in import_module
    return _bootstrap._gcd_import(name[level:], package, level)
  File "<frozen importlib._bootstrap>", line 1006, in _gcd_import
  File "<frozen importlib._bootstrap>", line 983, in _find_and_load
  File "<frozen importlib._bootstrap>", line 967, in _find_and_load_unlocked
  File "<frozen importlib._bootstrap>", line 677, in _load_unlocked
  File "<frozen importlib._bootstrap_external>", line 728, in exec_module
  File "<frozen importlib._bootstrap>", line 219, in _call_with_frames_removed
  File "/home/piekuser/piek/mainapp/models.py", line 3, in <module>
    from tinymce import HTMLField
ImportError: cannot import name 'HTMLField' from 'tinymce' (/home/piekuser/venv/lib/python3.7/site-packages/tinymce/__init__.py)
[2020-08-18 12:32:05 +0000] [15733] [INFO] Worker exiting (pid: 15733)
[2020-08-18 15:32:06 +0300] [15729] [INFO] Shutting down: Master
[2020-08-18 15:32:06 +0300] [15729] [INFO] Reason: Worker failed to boot.
[2020-08-18 15:32:09 +0300] [15734] [INFO] Starting gunicorn 20.0.4
[2020-08-18 15:32:09 +0300] [15734] [INFO] Listening at: http://127.0.0.1:8000 (15734)
[2020-08-18 15:32:09 +0300] [15734] [INFO] Using worker: sync
[2020-08-18 15:32:09 +0300] [15737] [INFO] Booting worker with pid: 15737
[2020-08-18 15:32:09 +0300] [15738] [INFO] Booting worker with pid: 15738
[2020-08-18 12:32:09 +0000] [15737] [ERROR] Exception in worker process
Traceback (most recent call last):
  File "/home/piekuser/venv/lib/python3.7/site-packages/gunicorn/arbiter.py", line 583, in spawn_worker
    worker.init_process()
  File "/home/piekuser/venv/lib/python3.7/site-packages/gunicorn/workers/base.py", line 119, in init_process
    self.load_wsgi()
  File "/home/piekuser/venv/lib/python3.7/site-packages/gunicorn/workers/base.py", line 144, in load_wsgi
    self.wsgi = self.app.wsgi()
  File "/home/piekuser/venv/lib/python3.7/site-packages/gunicorn/app/base.py", line 67, in wsgi
    self.callable = self.load()
  File "/home/piekuser/venv/lib/python3.7/site-packages/gunicorn/app/wsgiapp.py", line 49, in load
    return self.load_wsgiapp()
  File "/home/piekuser/venv/lib/python3.7/site-packages/gunicorn/app/wsgiapp.py", line 39, in load_wsgiapp
    return util.import_app(self.app_uri)
  File "/home/piekuser/venv/lib/python3.7/site-packages/gunicorn/util.py", line 358, in import_app
    mod = importlib.import_module(module)
  File "/usr/lib/python3.7/importlib/__init__.py", line 127, in import_module
    return _bootstrap._gcd_import(name[level:], package, level)
  File "<frozen importlib._bootstrap>", line 1006, in _gcd_import
  File "<frozen importlib._bootstrap>", line 983, in _find_and_load
  File "<frozen importlib._bootstrap>", line 967, in _find_and_load_unlocked
  File "<frozen importlib._bootstrap>", line 677, in _load_unlocked
  File "<frozen importlib._bootstrap_external>", line 728, in exec_module
  File "<frozen importlib._bootstrap>", line 219, in _call_with_frames_removed
  File "/home/piekuser/piek/jrl/wsgi.py", line 16, in <module>
    application = get_wsgi_application()
  File "/home/piekuser/venv/lib/python3.7/site-packages/django/core/wsgi.py", line 12, in get_wsgi_application
    django.setup(set_prefix=False)
  File "/home/piekuser/venv/lib/python3.7/site-packages/django/__init__.py", line 24, in setup
    apps.populate(settings.INSTALLED_APPS)
  File "/home/piekuser/venv/lib/python3.7/site-packages/django/apps/registry.py", line 114, in populate
    app_config.import_models()
  File "/home/piekuser/venv/lib/python3.7/site-packages/django/apps/config.py", line 211, in import_models
    self.models_module = import_module(models_module_name)
  File "/usr/lib/python3.7/importlib/__init__.py", line 127, in import_module
    return _bootstrap._gcd_import(name[level:], package, level)
  File "<frozen importlib._bootstrap>", line 1006, in _gcd_import
  File "<frozen importlib._bootstrap>", line 983, in _find_and_load
  File "<frozen importlib._bootstrap>", line 967, in _find_and_load_unlocked
  File "<frozen importlib._bootstrap>", line 677, in _load_unlocked
  File "<frozen importlib._bootstrap_external>", line 728, in exec_module
  File "<frozen importlib._bootstrap>", line 219, in _call_with_frames_removed
  File "/home/piekuser/piek/mainapp/models.py", line 3, in <module>
    from tinymce import HTMLField
ImportError: cannot import name 'HTMLField' from 'tinymce' (/home/piekuser/venv/lib/python3.7/site-packages/tinymce/__init__.py)
[2020-08-18 12:32:09 +0000] [15737] [INFO] Worker exiting (pid: 15737)
[2020-08-18 12:32:09 +0000] [15738] [ERROR] Exception in worker process
Traceback (most recent call last):
  File "/home/piekuser/venv/lib/python3.7/site-packages/gunicorn/arbiter.py", line 583, in spawn_worker
    worker.init_process()
  File "/home/piekuser/venv/lib/python3.7/site-packages/gunicorn/workers/base.py", line 119, in init_process
    self.load_wsgi()
  File "/home/piekuser/venv/lib/python3.7/site-packages/gunicorn/workers/base.py", line 144, in load_wsgi
    self.wsgi = self.app.wsgi()
  File "/home/piekuser/venv/lib/python3.7/site-packages/gunicorn/app/base.py", line 67, in wsgi
    self.callable = self.load()
  File "/home/piekuser/venv/lib/python3.7/site-packages/gunicorn/app/wsgiapp.py", line 49, in load
    return self.load_wsgiapp()
  File "/home/piekuser/venv/lib/python3.7/site-packages/gunicorn/app/wsgiapp.py", line 39, in load_wsgiapp
    return util.import_app(self.app_uri)
  File "/home/piekuser/venv/lib/python3.7/site-packages/gunicorn/util.py", line 358, in import_app
    mod = importlib.import_module(module)
  File "/usr/lib/python3.7/importlib/__init__.py", line 127, in import_module
    return _bootstrap._gcd_import(name[level:], package, level)
  File "<frozen importlib._bootstrap>", line 1006, in _gcd_import
  File "<frozen importlib._bootstrap>", line 983, in _find_and_load
  File "<frozen importlib._bootstrap>", line 967, in _find_and_load_unlocked
  File "<frozen importlib._bootstrap>", line 677, in _load_unlocked
  File "<frozen importlib._bootstrap_external>", line 728, in exec_module
  File "<frozen importlib._bootstrap>", line 219, in _call_with_frames_removed
  File "/home/piekuser/piek/jrl/wsgi.py", line 16, in <module>
    application = get_wsgi_application()
  File "/home/piekuser/venv/lib/python3.7/site-packages/django/core/wsgi.py", line 12, in get_wsgi_application
    django.setup(set_prefix=False)
  File "/home/piekuser/venv/lib/python3.7/site-packages/django/__init__.py", line 24, in setup
    apps.populate(settings.INSTALLED_APPS)
  File "/home/piekuser/venv/lib/python3.7/site-packages/django/apps/registry.py", line 114, in populate
    app_config.import_models()
  File "/home/piekuser/venv/lib/python3.7/site-packages/django/apps/config.py", line 211, in import_models
    self.models_module = import_module(models_module_name)
  File "/usr/lib/python3.7/importlib/__init__.py", line 127, in import_module
    return _bootstrap._gcd_import(name[level:], package, level)
  File "<frozen importlib._bootstrap>", line 1006, in _gcd_import
  File "<frozen importlib._bootstrap>", line 983, in _find_and_load
  File "<frozen importlib._bootstrap>", line 967, in _find_and_load_unlocked
  File "<frozen importlib._bootstrap>", line 677, in _load_unlocked
  File "<frozen importlib._bootstrap_external>", line 728, in exec_module
  File "<frozen importlib._bootstrap>", line 219, in _call_with_frames_removed
  File "/home/piekuser/piek/mainapp/models.py", line 3, in <module>
    from tinymce import HTMLField
ImportError: cannot import name 'HTMLField' from 'tinymce' (/home/piekuser/venv/lib/python3.7/site-packages/tinymce/__init__.py)
[2020-08-18 12:32:09 +0000] [15738] [INFO] Worker exiting (pid: 15738)
Traceback (most recent call last):
  File "/home/piekuser/venv/lib/python3.7/site-packages/gunicorn/arbiter.py", line 209, in run
    self.sleep()
  File "/home/piekuser/venv/lib/python3.7/site-packages/gunicorn/arbiter.py", line 357, in sleep
    ready = select.select([self.PIPE[0]], [], [], 1.0)
  File "/home/piekuser/venv/lib/python3.7/site-packages/gunicorn/arbiter.py", line 242, in handle_chld
    self.reap_workers()
  File "/home/piekuser/venv/lib/python3.7/site-packages/gunicorn/arbiter.py", line 525, in reap_workers
    raise HaltServer(reason, self.WORKER_BOOT_ERROR)
gunicorn.errors.HaltServer: <HaltServer 'Worker failed to boot.' 3>

During handling of the above exception, another exception occurred:

Traceback (most recent call last):
  File "/home/piekuser/venv/bin/gunicorn", line 10, in <module>
    sys.exit(run())
  File "/home/piekuser/venv/lib/python3.7/site-packages/gunicorn/app/wsgiapp.py", line 58, in run
    WSGIApplication("%(prog)s [OPTIONS] [APP_MODULE]").run()
  File "/home/piekuser/venv/lib/python3.7/site-packages/gunicorn/app/base.py", line 228, in run
    super().run()
  File "/home/piekuser/venv/lib/python3.7/site-packages/gunicorn/app/base.py", line 72, in run
    Arbiter(self).run()
  File "/home/piekuser/venv/lib/python3.7/site-packages/gunicorn/arbiter.py", line 229, in run
    self.halt(reason=inst.reason, exit_status=inst.exit_status)
  File "/home/piekuser/venv/lib/python3.7/site-packages/gunicorn/arbiter.py", line 342, in halt
    self.stop()
  File "/home/piekuser/venv/lib/python3.7/site-packages/gunicorn/arbiter.py", line 393, in stop
    time.sleep(0.1)
  File "/home/piekuser/venv/lib/python3.7/site-packages/gunicorn/arbiter.py", line 242, in handle_chld
    self.reap_workers()
  File "/home/piekuser/venv/lib/python3.7/site-packages/gunicorn/arbiter.py", line 525, in reap_workers
    raise HaltServer(reason, self.WORKER_BOOT_ERROR)
gunicorn.errors.HaltServer: <HaltServer 'Worker failed to boot.' 3>
[2020-08-18 15:50:33 +0300] [16064] [INFO] Starting gunicorn 20.0.4
[2020-08-18 15:50:33 +0300] [16064] [INFO] Listening at: http://127.0.0.1:8000 (16064)
[2020-08-18 15:50:33 +0300] [16064] [INFO] Using worker: sync
[2020-08-18 15:50:33 +0300] [16067] [INFO] Booting worker with pid: 16067
[2020-08-18 15:50:33 +0300] [16068] [INFO] Booting worker with pid: 16068
Connected to database engine "sqlite:////home/piekuser/piek/db.sqlite3"
[2020-08-18 12:50:34,038] db: INFO - Connected to database engine "sqlite:////home/piekuser/piek/db.sqlite3"
WARNING - 2020-08-18 12:50:34: Table "empoyess" does not have primary key and will be ignored
Connected to database engine "sqlite:////home/piekuser/piek/db.sqlite3"
[2020-08-18 12:50:34,243] db: WARNING - Table "empoyess" does not have primary key and will be ignored
WARNING - 2020-08-18 12:50:34: Table "sqlite_sequence" does not have primary key and will be ignored
[2020-08-18 12:50:34,251] db: WARNING - Table "sqlite_sequence" does not have primary key and will be ignored
[2020-08-18 12:50:34,251] db: INFO - Connected to database engine "sqlite:////home/piekuser/piek/db.sqlite3"
WARNING - 2020-08-18 12:50:34: Table "empoyess" does not have primary key and will be ignored
[2020-08-18 12:50:34,368] db: WARNING - Table "empoyess" does not have primary key and will be ignored
WARNING - 2020-08-18 12:50:34: Table "sqlite_sequence" does not have primary key and will be ignored
[2020-08-18 12:50:34,369] db: WARNING - Table "sqlite_sequence" does not have primary key and will be ignored
Internal Server Error: /catalog/elektroprivody-vzryvozashishennye/meof/
Traceback (most recent call last):
  File "/home/piekuser/venv/lib/python3.7/site-packages/django/template/base.py", line 829, in _resolve_lookup
    current = current[bit]
TypeError: 'ImageFieldFile' object is not subscriptable

During handling of the above exception, another exception occurred:

Traceback (most recent call last):
  File "/home/piekuser/venv/lib/python3.7/site-packages/django/core/handlers/exception.py", line 47, in inner
    response = get_response(request)
  File "/home/piekuser/venv/lib/python3.7/site-packages/django/core/handlers/base.py", line 179, in _get_response
    response = wrapped_callback(request, *callback_args, **callback_kwargs)
  File "/home/piekuser/piek/mainapp/views.py", line 23, in SubgroupDetailView
    'product_list'  : product_list,
  File "/home/piekuser/venv/lib/python3.7/site-packages/django/shortcuts.py", line 19, in render
    content = loader.render_to_string(template_name, context, request, using=using)
  File "/home/piekuser/venv/lib/python3.7/site-packages/django/template/loader.py", line 62, in render_to_string
    return template.render(context, request)
  File "/home/piekuser/venv/lib/python3.7/site-packages/django/template/backends/django.py", line 61, in render
    return self.template.render(context)
  File "/home/piekuser/venv/lib/python3.7/site-packages/django/template/base.py", line 170, in render
    return self._render(context)
  File "/home/piekuser/venv/lib/python3.7/site-packages/django/template/base.py", line 162, in _render
    return self.nodelist.render(context)
  File "/home/piekuser/venv/lib/python3.7/site-packages/django/template/base.py", line 938, in render
    bit = node.render_annotated(context)
  File "/home/piekuser/venv/lib/python3.7/site-packages/django/template/base.py", line 905, in render_annotated
    return self.render(context)
  File "/home/piekuser/venv/lib/python3.7/site-packages/django/template/defaulttags.py", line 211, in render
    nodelist.append(node.render_annotated(context))
  File "/home/piekuser/venv/lib/python3.7/site-packages/django/template/base.py", line 905, in render_annotated
    return self.render(context)
  File "/home/piekuser/venv/lib/python3.7/site-packages/django/template/base.py", line 988, in render
    output = self.filter_expression.resolve(context)
  File "/home/piekuser/venv/lib/python3.7/site-packages/django/template/base.py", line 671, in resolve
    obj = self.var.resolve(context)
  File "/home/piekuser/venv/lib/python3.7/site-packages/django/template/base.py", line 796, in resolve
    value = self._resolve_lookup(context)
  File "/home/piekuser/venv/lib/python3.7/site-packages/django/template/base.py", line 837, in _resolve_lookup
    current = getattr(current, bit)
  File "/home/piekuser/venv/lib/python3.7/site-packages/django/db/models/fields/files.py", line 61, in url
    self._require_file()
  File "/home/piekuser/venv/lib/python3.7/site-packages/django/db/models/fields/files.py", line 38, in _require_file
    raise ValueError("The '%s' attribute has no file associated with it." % self.field.name)
ValueError: The 'img' attribute has no file associated with it.
[2020-08-18 12:51:25,576] log: ERROR - Internal Server Error: /catalog/elektroprivody-vzryvozashishennye/meof/
Traceback (most recent call last):
  File "/home/piekuser/venv/lib/python3.7/site-packages/django/template/base.py", line 829, in _resolve_lookup
    current = current[bit]
TypeError: 'ImageFieldFile' object is not subscriptable

During handling of the above exception, another exception occurred:

Traceback (most recent call last):
  File "/home/piekuser/venv/lib/python3.7/site-packages/django/core/handlers/exception.py", line 47, in inner
    response = get_response(request)
  File "/home/piekuser/venv/lib/python3.7/site-packages/django/core/handlers/base.py", line 179, in _get_response
    response = wrapped_callback(request, *callback_args, **callback_kwargs)
  File "/home/piekuser/piek/mainapp/views.py", line 23, in SubgroupDetailView
    'product_list'  : product_list,
  File "/home/piekuser/venv/lib/python3.7/site-packages/django/shortcuts.py", line 19, in render
    content = loader.render_to_string(template_name, context, request, using=using)
  File "/home/piekuser/venv/lib/python3.7/site-packages/django/template/loader.py", line 62, in render_to_string
    return template.render(context, request)
  File "/home/piekuser/venv/lib/python3.7/site-packages/django/template/backends/django.py", line 61, in render
    return self.template.render(context)
  File "/home/piekuser/venv/lib/python3.7/site-packages/django/template/base.py", line 170, in render
    return self._render(context)
  File "/home/piekuser/venv/lib/python3.7/site-packages/django/template/base.py", line 162, in _render
    return self.nodelist.render(context)
  File "/home/piekuser/venv/lib/python3.7/site-packages/django/template/base.py", line 938, in render
    bit = node.render_annotated(context)
  File "/home/piekuser/venv/lib/python3.7/site-packages/django/template/base.py", line 905, in render_annotated
    return self.render(context)
  File "/home/piekuser/venv/lib/python3.7/site-packages/django/template/defaulttags.py", line 211, in render
    nodelist.append(node.render_annotated(context))
  File "/home/piekuser/venv/lib/python3.7/site-packages/django/template/base.py", line 905, in render_annotated
    return self.render(context)
  File "/home/piekuser/venv/lib/python3.7/site-packages/django/template/base.py", line 988, in render
    output = self.filter_expression.resolve(context)
  File "/home/piekuser/venv/lib/python3.7/site-packages/django/template/base.py", line 671, in resolve
    obj = self.var.resolve(context)
  File "/home/piekuser/venv/lib/python3.7/site-packages/django/template/base.py", line 796, in resolve
    value = self._resolve_lookup(context)
  File "/home/piekuser/venv/lib/python3.7/site-packages/django/template/base.py", line 837, in _resolve_lookup
    current = getattr(current, bit)
  File "/home/piekuser/venv/lib/python3.7/site-packages/django/db/models/fields/files.py", line 61, in url
    self._require_file()
  File "/home/piekuser/venv/lib/python3.7/site-packages/django/db/models/fields/files.py", line 38, in _require_file
    raise ValueError("The '%s' attribute has no file associated with it." % self.field.name)
ValueError: The 'img' attribute has no file associated with it.
[2020-08-18 15:53:37 +0300] [16064] [INFO] Handling signal: term
[2020-08-18 12:53:37 +0000] [16067] [INFO] Worker exiting (pid: 16067)
[2020-08-18 12:53:37 +0000] [16068] [INFO] Worker exiting (pid: 16068)
[2020-08-18 15:53:38 +0300] [16064] [INFO] Shutting down: Master
[2020-08-18 15:53:38 +0300] [16140] [INFO] Starting gunicorn 20.0.4
[2020-08-18 15:53:38 +0300] [16140] [INFO] Listening at: http://127.0.0.1:8000 (16140)
[2020-08-18 15:53:38 +0300] [16140] [INFO] Using worker: sync
[2020-08-18 15:53:38 +0300] [16143] [INFO] Booting worker with pid: 16143
[2020-08-18 15:53:38 +0300] [16144] [INFO] Booting worker with pid: 16144
Connected to database engine "sqlite:////home/piekuser/piek/db.sqlite3"
[2020-08-18 12:53:39,296] db: INFO - Connected to database engine "sqlite:////home/piekuser/piek/db.sqlite3"
Connected to database engine "sqlite:////home/piekuser/piek/db.sqlite3"
[2020-08-18 12:53:39,341] db: INFO - Connected to database engine "sqlite:////home/piekuser/piek/db.sqlite3"
WARNING - 2020-08-18 12:53:39: Table "empoyess" does not have primary key and will be ignored
[2020-08-18 12:53:39,520] db: WARNING - Table "empoyess" does not have primary key and will be ignored
WARNING - 2020-08-18 12:53:39: Table "sqlite_sequence" does not have primary key and will be ignored
[2020-08-18 12:53:39,526] db: WARNING - Table "sqlite_sequence" does not have primary key and will be ignored
WARNING - 2020-08-18 12:53:39: Table "empoyess" does not have primary key and will be ignored
[2020-08-18 12:53:39,546] db: WARNING - Table "empoyess" does not have primary key and will be ignored
WARNING - 2020-08-18 12:53:39: Table "sqlite_sequence" does not have primary key and will be ignored
[2020-08-18 12:53:39,546] db: WARNING - Table "sqlite_sequence" does not have primary key and will be ignored
[2020-08-18 12:53:46,839] log: ERROR - Internal Server Error: /catalog/elektroprivody-vzryvozashishennye/meof/
Traceback (most recent call last):
  File "/home/piekuser/venv/lib/python3.7/site-packages/django/template/base.py", line 829, in _resolve_lookup
    current = current[bit]
TypeError: 'ImageFieldFile' object is not subscriptable

During handling of the above exception, another exception occurred:

Traceback (most recent call last):
  File "/home/piekuser/venv/lib/python3.7/site-packages/django/core/handlers/exception.py", line 47, in inner
    response = get_response(request)
  File "/home/piekuser/venv/lib/python3.7/site-packages/django/core/handlers/base.py", line 179, in _get_response
    response = wrapped_callback(request, *callback_args, **callback_kwargs)
  File "/home/piekuser/piek/mainapp/views.py", line 23, in SubgroupDetailView
    'product_list'  : product_list,
  File "/home/piekuser/venv/lib/python3.7/site-packages/django/shortcuts.py", line 19, in render
    content = loader.render_to_string(template_name, context, request, using=using)
  File "/home/piekuser/venv/lib/python3.7/site-packages/django/template/loader.py", line 62, in render_to_string
    return template.render(context, request)
  File "/home/piekuser/venv/lib/python3.7/site-packages/django/template/backends/django.py", line 61, in render
    return self.template.render(context)
  File "/home/piekuser/venv/lib/python3.7/site-packages/django/template/base.py", line 170, in render
    return self._render(context)
  File "/home/piekuser/venv/lib/python3.7/site-packages/django/template/base.py", line 162, in _render
    return self.nodelist.render(context)
  File "/home/piekuser/venv/lib/python3.7/site-packages/django/template/base.py", line 938, in render
    bit = node.render_annotated(context)
  File "/home/piekuser/venv/lib/python3.7/site-packages/django/template/base.py", line 905, in render_annotated
    return self.render(context)
  File "/home/piekuser/venv/lib/python3.7/site-packages/django/template/defaulttags.py", line 211, in render
    nodelist.append(node.render_annotated(context))
  File "/home/piekuser/venv/lib/python3.7/site-packages/django/template/base.py", line 905, in render_annotated
    return self.render(context)
  File "/home/piekuser/venv/lib/python3.7/site-packages/django/template/base.py", line 988, in render
    output = self.filter_expression.resolve(context)
  File "/home/piekuser/venv/lib/python3.7/site-packages/django/template/base.py", line 671, in resolve
    obj = self.var.resolve(context)
  File "/home/piekuser/venv/lib/python3.7/site-packages/django/template/base.py", line 796, in resolve
    value = self._resolve_lookup(context)
  File "/home/piekuser/venv/lib/python3.7/site-packages/django/template/base.py", line 837, in _resolve_lookup
    current = getattr(current, bit)
  File "/home/piekuser/venv/lib/python3.7/site-packages/django/db/models/fields/files.py", line 61, in url
    self._require_file()
  File "/home/piekuser/venv/lib/python3.7/site-packages/django/db/models/fields/files.py", line 38, in _require_file
    raise ValueError("The '%s' attribute has no file associated with it." % self.field.name)
ValueError: The 'img' attribute has no file associated with it.
[2020-08-18 15:54:08 +0300] [16140] [INFO] Handling signal: term
[2020-08-18 12:54:08 +0000] [16143] [INFO] Worker exiting (pid: 16143)
[2020-08-18 12:54:08 +0000] [16144] [INFO] Worker exiting (pid: 16144)
[2020-08-18 15:54:08 +0300] [16140] [INFO] Shutting down: Master
[2020-08-18 16:07:26 +0300] [16406] [INFO] Starting gunicorn 20.0.4
[2020-08-18 16:07:26 +0300] [16406] [INFO] Listening at: http://127.0.0.1:8000 (16406)
[2020-08-18 16:07:26 +0300] [16406] [INFO] Using worker: sync
[2020-08-18 16:07:26 +0300] [16409] [INFO] Booting worker with pid: 16409
[2020-08-18 16:07:26 +0300] [16410] [INFO] Booting worker with pid: 16410
Connected to database engine "sqlite:////home/piekuser/piek/db.sqlite3"
[2020-08-18 13:07:27,550] db: INFO - Connected to database engine "sqlite:////home/piekuser/piek/db.sqlite3"
WARNING - 2020-08-18 13:07:27: Table "empoyess" does not have primary key and will be ignored
[2020-08-18 13:07:27,758] db: WARNING - Table "empoyess" does not have primary key and will be ignored
WARNING - 2020-08-18 13:07:27: Table "sqlite_sequence" does not have primary key and will be ignored
[2020-08-18 13:07:27,759] db: WARNING - Table "sqlite_sequence" does not have primary key and will be ignored
Connected to database engine "sqlite:////home/piekuser/piek/db.sqlite3"
[2020-08-18 13:07:27,790] db: INFO - Connected to database engine "sqlite:////home/piekuser/piek/db.sqlite3"
WARNING - 2020-08-18 13:07:27: Table "empoyess" does not have primary key and will be ignored
[2020-08-18 13:07:27,890] db: WARNING - Table "empoyess" does not have primary key and will be ignored
WARNING - 2020-08-18 13:07:27: Table "sqlite_sequence" does not have primary key and will be ignored
[2020-08-18 13:07:27,891] db: WARNING - Table "sqlite_sequence" does not have primary key and will be ignored
[2020-08-18 13:32:37,683] log: WARNING - Not Found: /robots.txt
[2020-08-18 13:53:01,181] log: ERROR - Internal Server Error: /catalog/elektroprivody-vzryvozashishennye/meof/
Traceback (most recent call last):
  File "/home/piekuser/venv/lib/python3.7/site-packages/django/template/base.py", line 829, in _resolve_lookup
    current = current[bit]
TypeError: 'ImageFieldFile' object is not subscriptable

During handling of the above exception, another exception occurred:

Traceback (most recent call last):
  File "/home/piekuser/venv/lib/python3.7/site-packages/django/core/handlers/exception.py", line 47, in inner
    response = get_response(request)
  File "/home/piekuser/venv/lib/python3.7/site-packages/django/core/handlers/base.py", line 179, in _get_response
    response = wrapped_callback(request, *callback_args, **callback_kwargs)
  File "/home/piekuser/piek/mainapp/views.py", line 23, in SubgroupDetailView
    'product_list'  : product_list,
  File "/home/piekuser/venv/lib/python3.7/site-packages/django/shortcuts.py", line 19, in render
    content = loader.render_to_string(template_name, context, request, using=using)
  File "/home/piekuser/venv/lib/python3.7/site-packages/django/template/loader.py", line 62, in render_to_string
    return template.render(context, request)
  File "/home/piekuser/venv/lib/python3.7/site-packages/django/template/backends/django.py", line 61, in render
    return self.template.render(context)
  File "/home/piekuser/venv/lib/python3.7/site-packages/django/template/base.py", line 170, in render
    return self._render(context)
  File "/home/piekuser/venv/lib/python3.7/site-packages/django/template/base.py", line 162, in _render
    return self.nodelist.render(context)
  File "/home/piekuser/venv/lib/python3.7/site-packages/django/template/base.py", line 938, in render
    bit = node.render_annotated(context)
  File "/home/piekuser/venv/lib/python3.7/site-packages/django/template/base.py", line 905, in render_annotated
    return self.render(context)
  File "/home/piekuser/venv/lib/python3.7/site-packages/django/template/defaulttags.py", line 211, in render
    nodelist.append(node.render_annotated(context))
  File "/home/piekuser/venv/lib/python3.7/site-packages/django/template/base.py", line 905, in render_annotated
    return self.render(context)
  File "/home/piekuser/venv/lib/python3.7/site-packages/django/template/base.py", line 988, in render
    output = self.filter_expression.resolve(context)
  File "/home/piekuser/venv/lib/python3.7/site-packages/django/template/base.py", line 671, in resolve
    obj = self.var.resolve(context)
  File "/home/piekuser/venv/lib/python3.7/site-packages/django/template/base.py", line 796, in resolve
    value = self._resolve_lookup(context)
  File "/home/piekuser/venv/lib/python3.7/site-packages/django/template/base.py", line 837, in _resolve_lookup
    current = getattr(current, bit)
  File "/home/piekuser/venv/lib/python3.7/site-packages/django/db/models/fields/files.py", line 61, in url
    self._require_file()
  File "/home/piekuser/venv/lib/python3.7/site-packages/django/db/models/fields/files.py", line 38, in _require_file
    raise ValueError("The '%s' attribute has no file associated with it." % self.field.name)
ValueError: The 'img' attribute has no file associated with it.
[2020-08-18 15:41:36,712] log: WARNING - Not Found: /favicon.ico
[2020-08-18 15:41:55,101] log: WARNING - Not Found: /favicon.ico
[2020-08-18 16:47:10,629] log: WARNING - Not Found: /robots.txt
[2020-08-18 16:47:19,633] log: WARNING - Not Found: /favicon.ico
[2020-08-18 19:39:03,038] log: WARNING - Not Found: /caке
[2020-08-18 19:54:01,931] log: WARNING - Not Found: /favicon.ico
[2020-08-18 23:12:01 +0300] [16406] [INFO] Handling signal: term
[2020-08-18 20:12:01 +0000] [16409] [INFO] Worker exiting (pid: 16409)
[2020-08-18 20:12:01 +0000] [16410] [INFO] Worker exiting (pid: 16410)
1
[2020-08-18 23:12:02 +0300] [16406] [INFO] Shutting down: Master
[2020-08-18 23:12:02 +0300] [20175] [INFO] Starting gunicorn 20.0.4
[2020-08-18 23:12:02 +0300] [20175] [INFO] Listening at: http://127.0.0.1:8000 (20175)
[2020-08-18 23:12:02 +0300] [20175] [INFO] Using worker: sync
[2020-08-18 23:12:02 +0300] [20178] [INFO] Booting worker with pid: 20178
[2020-08-18 23:12:02 +0300] [20179] [INFO] Booting worker with pid: 20179
Connected to database engine "sqlite:////home/piekuser/piek/db.sqlite3"
[2020-08-18 20:12:03,108] db: INFO - Connected to database engine "sqlite:////home/piekuser/piek/db.sqlite3"
Connected to database engine "sqlite:////home/piekuser/piek/db.sqlite3"
[2020-08-18 20:12:03,227] db: INFO - Connected to database engine "sqlite:////home/piekuser/piek/db.sqlite3"
WARNING - 2020-08-18 20:12:03: Table "empoyess" does not have primary key and will be ignored
[2020-08-18 20:12:03,336] db: WARNING - Table "empoyess" does not have primary key and will be ignored
WARNING - 2020-08-18 20:12:03: Table "sqlite_sequence" does not have primary key and will be ignored
[2020-08-18 20:12:03,337] db: WARNING - Table "sqlite_sequence" does not have primary key and will be ignored
WARNING - 2020-08-18 20:12:03: Table "empoyess" does not have primary key and will be ignored
[2020-08-18 20:12:03,395] db: WARNING - Table "empoyess" does not have primary key and will be ignored
WARNING - 2020-08-18 20:12:03: Table "sqlite_sequence" does not have primary key and will be ignored
[2020-08-18 20:12:03,395] db: WARNING - Table "sqlite_sequence" does not have primary key and will be ignored
[2020-08-18 20:16:13,930] log: WARNING - Not Found: /favicon.ico
[2020-08-18 20:17:12,622] log: WARNING - Not Found: /favicon.ico
[2020-08-18 20:18:04,295] log: WARNING - Not Found: /favicon.ico
[2020-08-18 20:18:57,723] log: WARNING - Not Found: /favicon.ico
[2020-08-18 20:42:07,100] log: WARNING - Not Found: /favicon.ico
[2020-08-18 20:43:40,910] log: WARNING - Not Found: /favicon.ico
[2020-08-18 20:43:42,131] log: WARNING - Not Found: /favicon.ico
[2020-08-18 20:44:08,078] log: WARNING - Not Found: /favicon.ico
[2020-08-18 20:44:09,494] log: WARNING - Not Found: /favicon.ico
Connected to database engine "sqlite:////home/piekuser/piek/db.sqlite3"
[2020-08-18 21:22:34,296] db: INFO - Connected to database engine "sqlite:////home/piekuser/piek/db.sqlite3"
WARNING - 2020-08-18 21:22:34: Table "empoyess" does not have primary key and will be ignored
[2020-08-18 21:22:34,388] db: WARNING - Table "empoyess" does not have primary key and will be ignored
WARNING - 2020-08-18 21:22:34: Table "sqlite_sequence" does not have primary key and will be ignored
[2020-08-18 21:22:34,388] db: WARNING - Table "sqlite_sequence" does not have primary key and will be ignored
[2020-08-18 21:49:08,809] log: WARNING - Not Found: /caке
[2020-08-18 21:49:12,108] log: WARNING - Not Found: /caке
[2020-08-18 22:08:15,231] log: WARNING - Not Found: /favicon.ico
[2020-08-18 22:11:30,464] log: WARNING - Not Found: /favicon.ico
[2020-08-18 22:11:39,743] log: WARNING - Not Found: /favicon.ico
[2020-08-18 22:15:05,958] log: WARNING - Not Found: /favicon.ico
[2020-08-18 22:17:32,620] log: WARNING - Not Found: /favicon.ico
[2020-08-18 22:19:15,070] log: WARNING - Not Found: /favicon.ico
[2020-08-18 22:19:18,573] log: WARNING - Not Found: /favicon.ico
